Workbook

Sheet HDSD
A1: ID_TaiLieu | B1: Tên tài liệu | C1: File đính kèm
A2: HDSD | B2: Tài liệu hướng dẫn sử dụng | C2: HDSD_Files_/HDSD.File đính kèm.134741.pdf

Sheet BANG_TONG_HOP
A1: ID_TongHop | B1: Ten_Bao_Cao | C1: Ngay_Cap_Nhat
A2: 1 | B2: BÁO CÁO TIẾN ĐỘ HỒ SƠ ĐỀ XUẤT CẤP ĐỘ TOÀN TỈNH

Sheet 0.Trang_Chu
A1: ID | B1: Danh_Muc_Cap_1 | C1: Link_Value | D1: Ten_View_Dich | E1: Ghi_Chu | F1: Từ khoá
A2: 1 | B2: QUẢN LÝ ĐƠN VỊ ( Trụ sở, Nhân sự) | C2: https://cdn-icons-png.flaticon.com/128/11813/11813336.png | D2: TH_Don_Vi_View | E2: Quản lý thông tin liên quan Trụ sở, Nhân sự | F2: Company
A3: 2 | B3: HỆ THỐNG THÔNG TIN | C3: https://cdn-icons-png.flaticon.com/128/3598/3598191.png | D3: Menu_HTTT | E3: Quản lý hạ tầng và thiết bị công nghệ thông tin | F3: Network
A4: 3 | B4: ĐÁNH GIÁ HỒ SƠ ĐXCĐ | C4: https://cdn-icons-png.flaticon.com/128/12882/12882480.png | D4: ĐÁNH GIÁ HSĐXCĐ | E4: Đánh giá, theo dõi tiến độ hồ sơ | F4: audit
A5: 4 | B5: HỆ THỐNG CAMERA GIÁM SÁT | C5: https://cdn-icons-png.flaticon.com/128/828/828036.png | D5: 1.CAMERA_TH | E5: QL các thông tin liên quan đến hệ thống camera | F5: cctv
A6: 5 | B6: HỆ THỐNG HỘI NGHỊ TRỰC TUYẾN | C6: https://cdn-icons-png.flaticon.com/128/12794/12794093.png | D6: TH_Hội nghị trực tuyến | E6: QL các thông tin liên quan đến HNTT | F6: Online Meeting
A7: 6 | B7: DỮ LIỆU CÁ NHÂN | C7: https://cdn-icons-png.flaticon.com/128/4436/4436450.png | D7: TH_Dữ liệu cá nhân | E7: QL các thông tin liên quan đến DLCN | F7: privacy data
A8: 7 | B8: BẢN ĐỒ CÁC ĐƠN VỊ | C8: https://cdn-icons-png.flaticon.com/128/3222/3222642.png | D8: Bản đồ | E8: Xem map vị trí trụ sở của các đơn vị | F8: map company
A9: 8 | B9: DANH BẠ | C9: https://cdn-icons-png.flaticon.com/128/3120/3120030.png | D9: Danh bạ | E9: Liên hệ công tác | F9: contact manager
A10: 9 | B10: XEM DASHBOARD | C10: https://cdn-icons-png.flaticon.com/128/9912/9912366.png | D10: DASHBOARD | E10: Tổng hợp các dashboard | F10: dashboard
A11: 10 | B11: XEM BÁO CÁO | C11: https://cdn-icons-png.flaticon.com/128/3286/3286169.png | D11: Báo cáo | E11: Tổng hợp các báo cáo | F11: report

Sheet 0.Trang_Chu_HTTT
A1: ID | B1: Danh_Muc_Cap_1 | C1: Link_Value | D1: Ten_View_Dich | E1: Ghi_Chu | F1: Từ khoá
A2: 1 | B2: Hệ thống thông tin (Tổng hợp) | C2: https://cdn-icons-png.flaticon.com/128/3598/3598191.png | D2: 10.HTTT_TongHop | E2: Quản lý tất cả các hạng mục (Phòng máy chủ, máy chủ, hệ thống mạng, thiết bị lưu trữ...) | F2: Network
A3: 2 | B3: Phòng máy chủ | C3: https://cdn-icons-png.flaticon.com/128/9937/9937224.png | D3: TH_ Phòng máy chủ | E3: Quản lý thông tin liên quan đến Phòng máy chủ | F3: Server room
A4: 3 | B4: Máy chủ | C4: https://cdn-icons-png.flaticon.com/128/622/622397.png | D4: TH_Máy chủ | E4: Quản lý thông tin liên quan đến Máy chủ | F4: Server
A5: 4 | B5: Thiết bị lưu trữ | C5: https://cdn-icons-png.flaticon.com/128/9542/9542653.png | D5: TH_Lưu trữ | E5: Quản lý thông tin liên quan đến Thiết bị lưu trữ | F5: Data
A6: 5 | B6: Phần mềm ứng dụng | C6: https://cdn-icons-png.flaticon.com/128/16949/16949386.png | D6: TH_Phần mềm ứng dụng | E6: Quản lý thông tin liên quan đến Phần mềm ứng dụng | F6: software
A7: 6 | B7: Hệ thống mạng | C7: https://cdn-icons-png.flaticon.com/128/9326/9326946.png | D7: TH_Mạng | E7: Quản lý thông tin liên quan đến Hệ thống mạng | F7: Network
A8: 7 | B8: Thiết bị mạng và thiết bị bảo mật | C8: https://cdn-icons-png.flaticon.com/128/2082/2082732.png | D8: TH_Thiết bị mạng & Bảo mật | E8: Quản lý thông tin liên quan đến Thiết bị mạng và thiết bị bảo mật | F8: Network device
A9: 8 | B9: Máy trạm | C9: https://cdn-icons-png.flaticon.com/128/2004/2004580.png | D9: TH_Máy trạm | E9: Quản lý thông tin liên quan đến Máy trạm | F9: Computer

Sheet 0.DASHBOARD
A1: ID | B1: Danh_Muc_Dashboard | C1: Link_Value | D1: Ten_View_Dich | E1: Ghi_Chu
A2: 1 | B2: Dashboard 1 | C2: https://cdn-icons-png.flaticon.com/128/14177/14177338.png
A3: 2 | B3: Dashboard 2 | C3: https://cdn-icons-png.flaticon.com/128/610/610106.png
A4: 3 | B4: Dashboard 3 | C4: https://cdn-icons-png.flaticon.com/128/8901/8901603.png
A5: 4 | B5: Dashboard 4 | C5: https://cdn-icons-png.flaticon.com/128/16139/16139726.png
A6: 5 | B6: Dashboard 5 | C6: https://cdn-icons-png.flaticon.com/128/610/610106.png

Sheet 0.Bao_Cao
A1: ID | B1: Danh_Muc_Bao_Cao | C1: Link_Value | D1: Ten_View_Dich | E1: Ghi_Chu
A2: 1 | B2: Báo cáo 1 | C2: https://cdn-icons-png.flaticon.com/128/11921/11921646.png
A3: 2 | B3: Báo cáo 2 | C3: https://cdn-icons-png.flaticon.com/128/19012/19012479.png
A4: 3 | B4: Báo cáo 3 | C4: https://cdn-icons-png.flaticon.com/128/8276/8276278.png

Sheet 1. log
A1: ID_Log | B1: Thoi_Gian | C1: Nguoi_Thao_Tac | D1: Hanh_Dong | E1: Ten_Bang | F1: Chi_Tiet_Ban_Ghi
A2: Log_DanhGia45370633 | B2: 46137.847 | C2: nghiencuuphdl05@gmail.com | D2: Cập nhật kết quả | E2: CHI_TIET_DANH_GIA | F2: Đội nghiencuuphdl05@gmail.com vừa cập nhật kết quả cho Tiêu chuẩn: TCVN-MANG-11 thuộc HS: HSĐXCĐ_-ae2b071a
A3: Log_DanhGia38c72a0c | B3: 46139.432 | C3: nghiencuuphdl05@gmail.com | D3: Cập nhật kết quả | E3: CHI_TIET_DANH_GIA | F3: Đội nghiencuuphdl05@gmail.com vừa cập nhật kết quả cho Tiêu chuẩn: TCVN-MANG-09 thuộc HS: HSĐXCĐ_-47a64f0e
A4: Log_DanhGiad6a33c42 | B4: 46139.432 | C4: nghiencuuphdl05@gmail.com | D4: Cập nhật kết quả | E4: CHI_TIET_DANH_GIA | F4: Đội nghiencuuphdl05@gmail.com vừa cập nhật kết quả cho Tiêu chuẩn: TCVN-MANG-10 thuộc HS: HSĐXCĐ_-47a64f0e
A5: Log_DanhGia668807f0 | B5: 46139.432 | C5: nghiencuuphdl05@gmail.com | D5: Cập nhật kết quả | E5: CHI_TIET_DANH_GIA | F5: Đội nghiencuuphdl05@gmail.com vừa cập nhật kết quả cho Tiêu chuẩn: TCVN-MANG-11 thuộc HS: HSĐXCĐ_-47a64f0e
A6: Log_DanhGiac1c55f11 | B6: 46139.433 | C6: nghiencuuphdl05@gmail.com | D6: Cập nhật kết quả | E6: CHI_TIET_DANH_GIA | F6: Đội nghiencuuphdl05@gmail.com vừa cập nhật kết quả cho Tiêu chuẩn: TCVN-MANG-12 thuộc HS: HSĐXCĐ_-47a64f0e
A7: Log_DanhGia0144bc62 | B7: 46139.433 | C7: nghiencuuphdl05@gmail.com | D7: Cập nhật kết quả | E7: CHI_TIET_DANH_GIA | F7: Đội nghiencuuphdl05@gmail.com vừa cập nhật kết quả cho Tiêu chuẩn: TCVN-MANG-13 thuộc HS: HSĐXCĐ_-47a64f0e
A8: Log_DanhGia5eee75e1 | B8: 46139.433 | C8: nghiencuuphdl05@gmail.com | D8: Cập nhật kết quả | E8: CHI_TIET_DANH_GIA | F8: Đội nghiencuuphdl05@gmail.com vừa cập nhật kết quả cho Tiêu chuẩn: TCVN-MANG-14 thuộc HS: HSĐXCĐ_-47a64f0e
A9: Log_DanhGia6baef83e | B9: 46139.433 | C9: nghiencuuphdl05@gmail.com | D9: Cập nhật kết quả | E9: CHI_TIET_DANH_GIA | F9: Đội nghiencuuphdl05@gmail.com vừa cập nhật kết quả cho Tiêu chuẩn: TCVN-MANG-15 thuộc HS: HSĐXCĐ_-47a64f0e
A10: Log_DanhGiae7e8ab0d | B10: 46139.433 | C10: nghiencuuphdl05@gmail.com | D10: Cập nhật kết quả | E10: CHI_TIET_DANH_GIA | F10: Đội nghiencuuphdl05@gmail.com vừa cập nhật kết quả cho Tiêu chuẩn: TCVN-DULIEU-01 thuộc HS: HSĐXCĐ_-47a64f0e
A11: Log_DanhGia6fa776ee | B11: 46139.433 | C11: nghiencuuphdl05@gmail.com | D11: Cập nhật kết quả | E11: CHI_TIET_DANH_GIA | F11: Đội nghiencuuphdl05@gmail.com vừa cập nhật kết quả cho Tiêu chuẩn: TCVN-DULIEU-02 thuộc HS: HSĐXCĐ_-47a64f0e
A12: Log_DanhGia9a334937 | B12: 46139.785 | C12: nghiencuuphdl05@gmail.com | D12: Cập nhật kết quả | E12: CHI_TIET_DANH_GIA | F12: Đội nghiencuuphdl05@gmail.com vừa cập nhật kết quả cho Tiêu chuẩn: TCVN-MANG-03 thuộc HS: HSĐXCĐ_-8debaec1
A13: Log_DanhGiab2480ac6 | B13: 46139.785 | C13: nghiencuuphdl05@gmail.com | D13: Cập nhật kết quả | E13: CHI_TIET_DANH_GIA | F13: Đội nghiencuuphdl05@gmail.com vừa cập nhật kết quả cho Tiêu chuẩn: TCVN-MANG-01 thuộc HS: HSĐXCĐ_-8debaec1
... A84: Log_DanhGia8e502ab5 | B84: 46145.977 | C84: nghiencuuphdl05@gmail.com | D84: Cập nhật kết quả | E84: CHI_TIET_DANH_GIA | F84: Đội nghiencuuphdl05@gmail.com vừa cập nhật kết quả cho Tiêu chuẩn: TCVN-VanHanh-13 thuộc HS: HSĐXCĐ_dang_uy_xa_thuan_nam

Sheet 2. Users
A1: Email_Dang_Nhap | B1: Ho_Ten | C1: Vai_Tro | D1: Trang_Thai
A2: nghiencuuphdl05@gmail.com | B2: Doi_4 | C2: Admin | D2: Hoạt động
A3: nghiencuu.anm.01@gmail.com | B3: To_01 | C3: hien_truong | D3: Hoạt động
A4: nghiencuu.anm.02@gmail.com | B4: To_02 | C4: hien_truong | D4: Hoạt động
A5: nghiencuu.anm.03@gmail.com | B5: To_03 | C5: hien_truong | D5: Hoạt động
A6: nghiencuu.anm.04@gmail.com | B6: To_04 | C6: hien_truong | D6: Hoạt động
A7: nghiencuu.anm.05@gmail.com | B7: To_05 | C7: hien_truong | D7: Hoạt động
A8: nghiencuu.anm.06@gmail.com | B8: Van_Phong_1 | C8: van_phong | D8: Hoạt động
A9: nghiencuu.anm.07@gmail.com | B9: Khanh_PA05 | C9: Admin | D9: Hoạt động
A10: nghiencuu.anm.08@gmail.com | B10: Thom_PA05 | C10: Admin | D10: Hoạt động
A11: nghiencuu.anm.09@gmail.com | B11: Hoang_Anh | C11: Admin | D11: Hoạt động

Sheet 3. Nhom
A1: ID_Nhom | B1: Ten_Nhom | C1: Email_Nguoi_Nhap | D1: Icon
A2: Nhom_1 | B2: Cơ quan Đảng | C2: nghiencuuphdl05@gmail.com | D2: https://cdn-icons-png.flaticon.com/128/12061/12061752.png
A3: Nhom_2 | B3: Đảng uỷ Phường Xã | C3: nghiencuuphdl05@gmail.com | D3: https://cdn-icons-png.flaticon.com/128/12061/12061752.png
A4: Nhom_3 | B4: Sở Ban Ngành | C4: nghiencuuphdl05@gmail.com | D4: https://cdn-icons-png.flaticon.com/128/12061/12061752.png
A5: Nhom_4 | B5: UBND phường xã | C5: nghiencuuphdl05@gmail.com | D5: https://cdn-icons-png.flaticon.com/128/12061/12061752.png
A6: Nhom_5 | B6: Đơn vị sự nghiệp | C6: nghiencuuphdl05@gmail.com | D6: https://cdn-icons-png.flaticon.com/128/12061/12061752.png

Sheet Đơn vị
A1: ID_Nhom | B1: ID_Don_Vi | C1: Ten_Don_Vi | D1: Email_Nguoi_Nhap | E1: Icon_Don_Vi
A2: Nhom_1 | B2: ban_noi_chinh | C2: Ban Nội chính | D2: nghiencuuphdl05@gmail.com | E2: https://cdn-icons-png.flaticon.com/128/12061/12061752.png
A3: Nhom_1 | B3: ban_to_chuc | C3: Ban Tổ chức | D3: nghiencuuphdl05@gmail.com | E3: https://cdn-icons-png.flaticon.com/128/12061/12061752.png
A4: Nhom_1 | B4: ban_tuyen_giao_dan_van | C4: Ban Tuyên giáo & Dân vận | D4: nghiencuuphdl05@gmail.com | E4: https://cdn-icons-png.flaticon.com/128/12061/12061752.png
A5: Nhom_1 | B5: bao_va_phat_thanh_truyen_hinh_khanh_hoa | C5: Báo và phát thanh, truyền hình Khánh Hòa | D5: nghiencuuphdl05@gmail.com | E5: https://cdn-icons-png.flaticon.com/128/12061/12061752.png
A6: Nhom_1 | B6: dang_uy_cac_co_quan_dang_tinh | C6: Đảng ủy Các cơ quan Đảng tỉnh | D6: nghiencuuphdl05@gmail.com | E6: https://cdn-icons-png.flaticon.com/128/12061/12061752.png
A7: Nhom_1 | B7: dang_uy_ubnd_tinh | C7: Đảng ủy UBND tỉnh | D7: nghiencuuphdl05@gmail.com | E7: https://cdn-icons-png.flaticon.com/128/12061/12061752.png
A8: Nhom_1 | B8: uy_ban_kiem_tra | C8: Ủy ban Kiểm tra | D8: nghiencuuphdl05@gmail.com | E8: https://cdn-icons-png.flaticon.com/128/12061/12061752.png
A9: Nhom_2 | B9: dang_uy_phuong_ba_ngoi | C9: Đảng uỷ Phường Ba Ngòi | D9: nghiencuuphdl05@gmail.com | E9: https://cdn-icons-png.flaticon.com/128/12061/12061752.png
A10: Nhom_2 | B10: dang_uy_phuong_bao_an | C10: Đảng uỷ Phường Bảo An | D10: nghiencuuphdl05@gmail.com | E10: https://cdn-icons-png.flaticon.com/128/12061/12061752.png
A11: Nhom_2 | B11: dang_uy_phuong_bac_cam_ranh | C11: Đảng uỷ Phường Bắc Cam Ranh | D11: nghiencuuphdl05@gmail.com | E11: https://cdn-icons-png.flaticon.com/128/12061/12061752.png
A12: Nhom_2 | B12: dang_uy_phuong_bac_nha_trang | C12: Đảng uỷ Phường Bắc Nha Trang | D12: nghiencuuphdl05@gmail.com | E12: https://cdn-icons-png.flaticon.com/128/12061/12061752.png
... A160: Nhom_4 | B160: ubnd_xa_xuan_hai | C160: UBND Xã Xuân Hải | D160: nghiencuuphdl05@gmail.com | E160: https://cdn-icons-png.flaticon.com/128/12061/12061752.png

Sheet CHI_TIET_DANH_GIA
A1: ID_DanhGia | B1: ID_HSDXCD | C1: Chọn Nhóm Yêu Cầu | D1: Chọn Phân Nhóm tiêu chí | E1: ID_TieuChuan | F1: Email_Nguoi_Nhap | G1: Ket_Qua_Van_Phong | H1: Minh_Chung_Van_Phong_Text | I1: Minh_Chung_Van_Phong_Image | J1: Ghi_Chu_Van_Phong | K1: Ket_Qua_Hien_Truong | L1: Minh_Chung_Hien_Truong_Text | M1: Minh_Chung_Hien_Truong_Image | N1: Ghi_Chu_Hien_Truong | O1: Ket_Luan_PA05 | P1: Minh_Chung_PA05_Text | Q1: Minh_Chung_PA05_Image | R1: Ghi_Chu_PA05 | S1: Thời hạn khắc phục | T1: Cụ thể hướng khắc phục

Sheet 11. Phan_Mem_BM
A1: ID_HTTT | B1: ID_MayChu | C1: ID_MayTram | D1: ID_PhanMem | E1: Phiên bản phần mềm | F1: Hãng/Model | G1: Chức năng | H1: Phạm vi triển khai | I1: Hình thức bản quyền | J1: Thời hạn License | K1: Ngày cập nhật CSDL | L1: Hình thức quản lý | M1: Tình trạng hoạt động | N1: Ghi chú | O1: Email_Nguoi_Nhap

Sheet 5. Nhan_Su
A1: ID_NhanSu | B1: ID_Don_Vi | C1: Họ và tên | D1: Vai trò | E1: Số điện thoại | F1: Email | G1: Ghi chú | H1: Email_Nguoi_Nhap
A2: Ma_NhanSu_03b9a276 | B2: dang_uy_phuong_nha_trang | C2: Lữ Thanh Hải | D2: Thủ trưởng | E2: 0913495084 | F2: dangbonhatrang@khanhhoa.gov.vn | G2: Bí thư Đảng ủy phường Nha Trang | H2: nghiencuu.anm.09@gmail.com
A3: Ma_NhanSu_69463571 | B3: dang_uy_phuong_nha_trang | C3: Chu Minh Phương | D3: Lãnh đạo phụ trách CNTT/ATTT | E3: 0906443189 | F3: chuminhphuongnt@gmail.com | G3: Chánh Văn phòng Đảng ủy phường Nha Trang | H3: nghiencuu.anm.09@gmail.com
A4: Ma_NhanSu_bnt_1 | B4: dang_uy_phuong_nha_trang | C4: Nguyễn Hữu Khuyết | D4: Chuyên viên | E4: 0979931704 | G4: Chuyên viên Văn phòng Đảng ủy phường Nha Trang | H4: nghiencuu.anm.09@gmail.com
A5: Ma_NhanSu_3c53c628 | B5: bao_va_phat_thanh_truyen_hinh_khanh_hoa | C5: Thái Thị Lệ Hằng | D5: Thủ trưởng | E5: 0905171744 | H5: nghiencuuphdl05@gmail.com
A6: Ma_NhanSu_7df8d512 | B6: bao_va_phat_thanh_truyen_hinh_khanh_hoa | C6: Trần Đình Hồng Thanh | D6: Cán bộ chuyên trách | E6: 0909313367 | H6: nghiencuuphdl05@gmail.com
A7: Ma_NhanSu_c56340e5 | B7: bao_va_phat_thanh_truyen_hinh_khanh_hoa | C7: Nguyễn Đắc Chánh | D7: Cán bộ kỹ thuật | E7: 0905210999 | H7: nghiencuuphdl05@gmail.com
A8: Ma_NhanSu_0001 | B8: dang_uy_phuong_hoa_thang | C8: Lương Thị Hồng Thảo | D8: Công chức Văn phòng Đảng ủy phường Hoà Thắng | E8: 0374654318 | H8: nghiencuuphdl05@gmail.com
A9: Ma_NhanSu_0002 | B9: so_dan_toc_va_ton_giao_khanh_hoa | C9: Nguyễn Phương Nam | D9: Chuyên viên | E9: 0354332982 | H9: nghiencuuphdl05@gmail.com
A10: Ma_NhanSu_0003 | B10: dang_uy_xa_bac_ai | C10: Nguyễn Thế Anh | D10: Chuyên viên | E10: 0987123181 | H10: nghiencuuphdl05@gmail.com
A11: Ma_NhanSu_0004 | B11: ubnd_phuong_nam_nha_trang | C11: Bùi Tiến Toàn | D11: Giám đốc TTPVHCC | E11: 0908326758 | H11: nghiencuuphdl05@gmail.com
A12: Ma_NhanSu_0005 | B12: ubnd_phuong_nam_nha_trang | C12: Trần Khánh Duy | D12: Chuyên viên TTPVHCC | E12: 0942037538 | H12: nghiencuuphdl05@gmail.com
A13: Ma_NhanSu_0006 | B13: ubnd_phuong_nam_nha_trang | C13: Võ Công Hiếu | D13: Chánh VP HĐND và UBND | E13: 0905757080 | H13: nghiencuuphdl05@gmail.com
A14: Ma_NhanSu_0007 | B14: ubnd_phuong_nam_nha_trang | C14: Võ Đức Cường | D14: Chuyên viên VP HĐND và UBND | E14: 0799993983 | H14: nghiencuuphdl05@gmail.com
A15: Ma_NhanSu_0008 | B15: dang_uy_xa_nam_cam_ranh | C15: Nguyễn Văn Mỹ | D15: Chánh văn phòng đảng ủy (lãnh đạo bộ phận phụ trách công tác ATTT) | E15: 0977420030 | H15: nghiencuuphdl05@gmail.com
A16: Ma_NhanSu_0009 | B16: dang_uy_xa_nam_cam_ranh | C16: Lê Thị Thanh Hằng | D16: Chuyên viên Văn Phòng đảng ủy(đầu mối kỹ thuật CNTT) | E16: 0976493832 | H16: nghiencuuphdl05@gmail.com
A17: Ma_NhanSu_0010 | B17: dang_uy_xa_nam_cam_ranh | C17: Ngô Thị Hoài | D17: Chuyên viên văn phòng đảng ủy phụ trách hồ sơ cấp độ ATTT | H17: nghiencuuphdl05@gmail.com
A18: Ma_NhanSu_0011 | B18: ubnd_xa_hoa_tri | C18: Nguyễn Hữu Nam | D18: Chủ tịch UBND xã | E18: 0914151501 | H18: nghiencuuphdl05@gmail.com
A19: Ma_NhanSu_0012 | B19: ubnd_xa_hoa_tri | C19: Nguyễn Ngọc Thanh Uyên | D19: Phó Chánh Văn phòng HĐND và UBND | E19: 0772470449 | H19: nghiencuuphdl05@gmail.com
A20: Ma_NhanSu_0014 | B20: dang_uy_xa_ninh_hai | C20: Trần Thanh Quy | D20: Chuyên Viên VP Đảng | E20: 0334822528 | H20: nghiencuuphdl05@gmail.com
A21: Ma_NhanSu_0015 | B21: dang_uy_xa_ninh_hai | C21: Huỳnh Kim Hưng | D21: Chánh VP Đảng uỷ | E21: 085 4748798 | H21: nghiencuuphdl05@gmail.com
A22: Ma_NhanSu_0016 | B22: ban_quan_ly_du_an_dau_tu_xay_dung_cac_cong_trinh_nong_nghiep_va_giao_thong_tinh | C22: Trần Đức Thành | D22: Nhân viên | E22: 0378039494 | H22: nghiencuuphdl05@gmail.com
A23: Ma_NhanSu_0017 | B23: ban_quan_ly_du_an_dau_tu_xay_dung_cac_cong_trinh_nong_nghiep_va_giao_thong_tinh | C23: Nguyễn Công Tuấn | D23: Phó Chánh Văn phòng | E23: 0888150569 | H23: nghiencuuphdl05@gmail.com
A24: Ma_NhanSu_0018 | B24: dang_uy_xa_ninh_hai | C24: Khưu Cẩm Tú | D24: Phó chánh VP Đảng uỷ | E24: 083 4985937 | H24: nghiencuuphdl05@gmail.com
A25: Ma_NhanSu_0019 | B25: ubnd_xa_cam_lam | C25: Huỳnh Uy Viễn | D25: chủ tịch UBND xã | E25: 0917479039 | H25: nghiencuuphdl05@gmail.com
A26: Ma_NhanSu_0020 | B26: ubnd_xa_cam_lam | C26: Biện Hoàng Tâm | D26: Chuyên viên văn phòng HDdND và UBDN | E26: 0986799879 | H26: nghiencuuphdl05@gmail.com
A27: Ma_NhanSu_0021 | B27: ubnd_xa_cam_lam | C27: Phạm Thị Ngọc Bích | D27: Chuyên viên văn phòng HĐND và UBND | E27: 0908922981 | H27: nghiencuuphdl05@gmail.com
A28: Ma_NhanSu_0022 | B28: ubnd_xa_cam_lam | C28: Huỳnh Thị Phước | D28: Chuyên viên văn phòng HĐND và UBND | E28: 0976848595 | H28: nghiencuuphdl05@gmail.com
A29: Ma_NhanSu_0023 | B29: ubnd_xa_anh_dung | C29: Phan Kế Vũ | D29: Phó Chủ tịch UBND xã | E29: 0902620242 | H29: nghiencuuphdl05@gmail.com
... A187: Ma_NhanSu_0192 | B187: dang_uy_xa_cam_lam | C187: Trần Thị Diệu Thanh | D187: Chuyên viên | E187: 0935874477 | H187: nghiencuuphdl05@gmail.com
A188: Ma_NhanSu_0193 | B188: dang_uy_xa_bac_ai_dong | C188: Hồ Đức Hiệp | D188: Chuyên viên VP Đảng uỷ xã | H188: nghiencuuphdl05@gmail.com
A189: Ma_NhanSu_0194 | B189: dang_uy_xa_bac_ai_dong | C189: Nguyễn Ngọc Tuân | D189: Chánh VP Đảng uỷ | E189: 0386650119 | H189: nghiencuuphdl05@gmail.com
A190: Ma_NhanSu_0195 | B190: dang_uy_xa_khanh_son | C190: Trần quốc quyền | D190: Chuyên viên | E190: 0898379199 | H190: nghiencuuphdl05@gmail.com
A191: Ma_NhanSu_0196 | B191: ubnd_xa_khanh_son | C191: Trịnh Đình Ba | D191: Chánh Văn phòng HĐND&UBND xã | E191: 097 9289191 | H191: nghiencuuphdl05@gmail.com
A192: Ma_NhanSu_0197 | B192: ubnd_xa_khanh_son | C192: Cao Hà | D192: Chuyên viên Văn phòng HĐND&UBND xã | E192: 0988936003 | H192: nghiencuuphdl05@gmail.com
A193: Ma_NhanSu_0198 | B193: ubnd_xa_khanh_son | C193: Nguyễn Thị Sen | D193: Chuyên viên Phòng Văn hóa - xã hội | E193: 097 9710243 | H193: nghiencuuphdl05@gmail.com
A194: Ma_NhanSu_0199 | B194: dang_uy_phuong_nam_nha_trang | C194: Trần Xuân Cường | D194: Chuyên viên Văn phòng Đảng ủy | E194: 0935353304 | H194: nghiencuuphdl05@gmail.com
A195: Ma_NhanSu_0201 | B195: dang_uy_xa_bac_ai_tay | C195: Cadá Thị Hương Quỳnh | D195: Phó Chánh văn phòng | E195: 0394232487 | H195: nghiencuuphdl05@gmail.com
A196: Ma_NhanSu_0202 | B196: dang_uy_xa_bac_ai_tay | C196: võ Minh Tiến | D196: Chuyên viên | E196: 0902912889 | H196: nghiencuuphdl05@gmail.com
A197: Ma_NhanSu_0203 | B197: dang_uy_xa_vinh_hai | C197: Trần Minh Thái | D197: Bí thư Đảng ủy | E197: 0903672304 | H197: nghiencuuphdl05@gmail.com
...

Sheet TIEU_CHUAN_GOC
A1: ID_TieuChuan | B1: Nhóm yêu cầu | C1: Phân nhóm tiêu chí | D1: Đối chiếu với Mẫu Hướng dẫn Thuyết minh HSĐXCĐ | E1: Cấp độ tối thiểu | F1: Cấp độ tối đa | G1: Mã tham chiếu TCVN 11930 | H1: Bảng dữ liệu đối chiếu | I1: Cột dữ liệu đối chiếu | J1: Yêu cầu | K1: Phương án | L1: Hướng dẫn | M1: Điều kiện đạt chuyên sâu của đơn vị tư vấn | N1: Hướng dẫn chuyên sâu kỹ thuật của đơn vị tư vấn
A2: ND85-01 | B2: Yêu cầu quản lý | C2: Hồ sơ đề xuất cấp độ | D2: Khoản 3 Điều 13 NĐ 85: Thuyết minh đề xuất cấp độ | E2: 1 | F2: 2 | G2: Khoản 3 Điều 13 NĐ 85: Thuyết minh đề xuất cấp độ | H2: HSDX | I2: 3. Tài liệu Thuyết minh Hồ sơ đề xuất cấp độ | J2: Có bản thuyết minh ĐXCĐ | K2: Upload file lên phần mềm | L2: Bản scan (PDF) Thuyết minh đề xuất cấp độ theo đúng mẫu TT12, điền đủ thông tin và có dấu đỏ phê duyệt.
A3: ND85-02 | B3: Yêu cầu quản lý | C3: Hồ sơ đề xuất cấp độ | D3: Khoản 3 Điều 13 NĐ 85: Thuyết minh đề xuất cấp độ | E3: 1 | F3: 2 | G3: Khoản 3 Điều 13 NĐ 85: Thuyết minh đề xuất cấp độ | H3: HSDX | I3: 4. Quy chế An toàn thông tin | J3: Có Ban hành quy chế ATTT | K3: Upload file lên phần mềm | L3: Bản scan Quyết định ban hành Quy chế ATTT nội bộ của đơn vị có chữ ký Lãnh đạo và đóng dấu đỏ.
A4: TT12-01 | B4: Yêu cầu quản lý | C4: Hồ sơ đề xuất cấp độ | D4: Khoản 7 Điều 9 TT 12/2022: Quy định phê duyệt quy chế | E4: 1 | F4: 2 | G4: Khoản 7 Điều 9 TT 12/2022: Quy định phê duyệt quy chế | H4: HSDX | I4: 4. Quy chế An toàn thông tin | J4: Ban hành trước ngày duyệt HSĐXCĐ | K4: Kiểm tra và Upload file lên phần mềm | L4: Kiểm tra ngày ký của Quyết định ban hành Quy chế ATTT phải trước hoặc cùng ngày với Quyết định phê duyệt HSĐXCĐ.
A5: TCVN-ChinhSach-01 | B5: Yêu cầu quản lý | C5: 6.1.1. Thiết lập chính sách an toàn thông tin | D5: Mục 6.1.1.1. Xây dựng chính sách an toàn thông tin | E5: 1 | F5: 1 | G5: Mục 6.1.1.1. Xây dựng chính sách an toàn thông tin | H5: HSDX | I5: 4. Quy chế An toàn thông tin | J5: Xây dựng chính sách an toàn thông tin bao gồm: - Quản lý an toàn mạng; - Quản lý an toàn máy chủ và ứng dụng; - Quản lý an toàn dữ liệu; - Quản lý an toàn người sử dụng đầu cuối. | K5: Mục tiêu, nguyên tắc bảo đảm an toàn thông tin 1. Mục tiêu bảo đảm an toàn thông tin Bảo vệ thông tin, hệ thống thông tin trên mạng tránh bị truy nhập, sử dụng, tiết lộ, gián đoạn, sửa đổi hoặc phá hoại trái phép nhằm bảo đảm tính nguyên vẹn, tính bảo mật và tính khả dụng của Hệ thống … của Đơn vị vận hành. 2. Nguyên tắc a) Cơ quan, tổ chức thuộc đối tượng áp dụng Quy chế này có trách nhiệm bảo đảm an toàn thông tin và hệ thống thông tin trong phạm vi xử lý công việc của mình theo quy định của pháp luật, hướng dẫn của cơ quan, đơn vị có thẩm quyền và các quy định tại Quy chế này. b) Bảo đảm an toàn thông tin (ATTT) là yêu cầu bắt buộc, phải được thực hiện thường xuyên, liên tục trong quá trình: i. Thu thập, tạo lập, xử lý, truyền tải, lưu trữ và sử dụng thông tin, dữ liệu. ii. Thiết kế, thiết lập và vận hành, nâng cấp, hủy bỏ hệ thống thông tin. c) Việc bảo đảm an toàn thông tin cho Hệ thống … của Đơn vị vận hành được thực hiện một cách tổng thể, đồng bộ, tập trung trong việc đầu tư các giải pháp bảo vệ, có sự dùng chung, chia sẻ tài nguyên để tối ưu hiệu năng, tránh đầu tư thừa, trùng lặp. | L5: - Điều kiện "ĐẠT" khi Quy chế An toàn thông tin có nội dung trên (Quy định Điều 3 Quy chế mẫu). - Yêu cầu Trích dẫn nội dung minh chứng vào phần Minh Chứng văn bản text trong phần mềm. - Nếu đáp ứng một phần, chưa đáp ứng: Đơn vị vận hành cập nhật, bổ sung ban hành trong vòng 15 ngày, kể từ khi HSĐXCĐ được phê duyệt.
A6: TCVN-ChinhSach-02 | B6: Yêu cầu quản lý | C6: 6.1.1. Thiết lập chính sách an toàn thông tin | D6: Mục 6.1.1.1. Xây dựng chính sách an toàn thông tin | E6: 2 | F6: 2 | G6: Mục 6.1.1.1. Xây dựng chính sách an toàn thông tin | H6: HSDX | I6: 4. Quy chế An toàn thông tin | J6: Xây dựng chính sách an toàn thông tin bao gồm: - Quản lý an toàn mạng; - Quản lý an toàn máy chủ và ứng dụng; - Quản lý an toàn dữ liệu; - Quản lý an toàn người sử dụng đầu cuối. | K6: Mục tiêu, nguyên tắc bảo đảm an toàn thông tin 1. Mục tiêu bảo đảm an toàn thông tin Bảo vệ thông tin, hệ thống thông tin trên mạng tránh bị truy nhập, sử dụng, tiết lộ, gián đoạn, sửa đổi hoặc phá hoại trái phép nhằm bảo đảm tính nguyên vẹn, tính bảo mật và tính khả dụng của Hệ thống … của Đơn vị vận hành. 2. Nguyên tắc a) Cơ quan, tổ chức thuộc đối tượng áp dụng Quy chế này có trách nhiệm bảo đảm an toàn thông tin và hệ thống thông tin trong phạm vi xử lý công việc của mình theo quy định của pháp luật, hướng dẫn của cơ quan, đơn vị có thẩm quyền và các quy định tại Quy chế này. b) Bảo đảm an toàn thông tin (ATTT) là yêu cầu bắt buộc, phải được thực hiện thường xuyên, liên tục trong quá trình: i. Thu thập, tạo lập, xử lý, truyền tải, lưu trữ và sử dụng thông tin, dữ liệu. ii. Thiết kế, thiết lập và vận hành, nâng cấp, hủy bỏ hệ thống thông tin. c) Việc bảo đảm an toàn thông tin cho Hệ thống … của Đơn vị vận hành được thực hiện một cách tổng thể, đồng bộ, tập trung trong việc đầu tư các giải pháp bảo vệ, có sự dùng chung, chia sẻ tài nguyên để tối ưu hiệu năng, tránh đầu tư thừa, trùng lặp. | L6: - Điều kiện "ĐẠT" khi Quy chế An toàn thông tin có nội dung trên (Quy định Điều 3 Quy chế mẫu). - Yêu cầu Trích dẫn nội dung minh chứng vào phần Minh Chứng văn bản text trong phần mềm. - Nếu đáp ứng một phần, chưa đáp ứng: Đơn vị vận hành cập nhật, bổ sung ban hành trong vòng 15 ngày, kể từ khi HSĐXCĐ được phê duyệt.
A7: TCVN-ChinhSach-03 | B7: Yêu cầu quản lý | C7: 6.1.1. Thiết lập chính sách an toàn thông tin | D7: Mục 6.1.1.2. Chính sách được ủy quyền thông qua | E7: 1 | F7: 2 | G7: Mục 6.1.1.2. Chính sách và công bố | H7: HSDX | I7: 4. Quy chế An toàn thông tin | J7: Quy định về xây dựng và công bố Quy chế bảo đảm an toàn thông tin | K7: Xây dựng và công bố Quy chế này được tổ chức/bộ phận trình người đúng đầu đơn vị vận hành trước khi công bố áp dụng. | L7: - Điều kiện "ĐẠT" khi Quy chế An toàn thông tin có nội dung trên (Quy định Điều 20 Quy chế mẫu). - Yêu cầu Trích dẫn nội dung minh chứng vào phần Minh Chứng văn bản text trong phần mềm. - Nếu đáp ứng một phần, chưa đáp ứng: Đơn vị vận hành cập nhật, bổ sung ban hành trong vòng 15 ngày, kể từ khi HSĐXCĐ được phê duyệt.
A8: TCVN-ChinhSach-04 | B8: Yêu cầu quản lý | C8: 6.1.1. Thiết lập chính sách an toàn thông tin | D8: Mục 6.1.1.3. Rà soát, sửa đổi | E8: 1 | F8: 2 | G8: Mục 6.1.1.3. Rà soát, sửa đổi | H8: HSDX | I8: 4. Quy chế An toàn thông tin | J8: Có quy định về việc rà soát, sửa đổi Quy chế bảo đảm an toàn thông tin | K8: Rà soát, cập nhật, bổ sung Quy chế 1. Định kỳ 03 năm hoặc khi có thay đổi Quy chế bảo đảm an toàn thông tin kiểm tra lại tính phù hợp và thực hiện rà soát, cập nhật, bổ sung. 2. Có hồ sơ lưu lại thông tin phản hồi của đối tượng áp dụng chính sách trong quá trình triển khai, áp dụng chính sách an toàn thông tin. | L8: - Điều kiện "ĐẠT" khi Quy chế An toàn thông tin có nội dung trên (Quy định tại Điều 21 Quy chế mẫu). - Yêu cầu Trích dẫn nội dung minh chứng vào phần Minh Chứng văn bản text trong phần mềm. - Nếu đáp ứng một phần, chưa đáp ứng: Đơn vị vận hành cập nhật, bổ sung ban hành trong vòng 15 ngày, kể từ khi HSĐXCĐ được phê duyệt.
A9: TCVN-ToChuc-01 | B9: Yêu cầu quản lý | C9: 6.1.2. Tổ chức bảo đảm ATTT | D9: Mục 6.1.2.1. Có bộ phận/cán bộ bảo đảm ATTT | E9: 1 | F9: 1 | G9: Mục 6.1.2.1. Đơn vị chuyên trách về ATTT | H9: HSDX | I9: Nhân sự | J9: Có bộ phận có trách nhiệm bảo đảm an toàn thông tin cho tổ chức | K9: Thành lập hoặc chỉ định đơn vị/bộ phận chuyên trách về an toàn thông tin trong tổ chức | L9: - Điều kiện "ĐẠT" khi Quy chế An toàn thông tin có nội dung trên (Quy định tại Điều 18 Quy chế mẫu). - Yêu cầu Trích dẫn nội dung minh chứng vào phần Minh Chứng văn bản text trong phần mềm. - Nếu đáp ứng một phần, chưa đáp ứng: Đơn vị vận hành cập nhật, bổ sung ban hành trong vòng 15 ngày, kể từ khi HSĐXCĐ được phê duyệt.
A10: TCVN-ToChuc-02 | B10: Yêu cầu quản lý | C10: 6.1.2. Tổ chức bảo đảm ATTT | D10: Mục 6.1.2.1. Có bộ phận/cán bộ bảo đảm ATTT | E10: 2 | F10: 2 | G10: Mục 6.1.2.1. Đơn vị chuyên trách về ATTT | H10: HSDX | I10: Nhân sự | J10: Có bộ phận có trách nhiệm bảo đảm an toàn thông tin cho tổ chức | K10: Thành lập hoặc chỉ định đơn vị/bộ phận chuyên trách về an toàn thông tin trong tổ chức | L10: - Điều kiện "ĐẠT" khi Quy chế An toàn thông tin có nội dung trên (Quy định tại Điều 18 Quy chế mẫu). - Yêu cầu Trích dẫn nội dung minh chứng vào phần Minh Chứng văn bản text trong phần mềm. - Nếu đáp ứng một phần, chưa đáp ứng: Đơn vị vận hành cập nhật, bổ sung ban hành trong vòng 15 ngày, kể từ khi HSĐXCĐ được phê duyệt.
A11: TCVN-ToChuc-03 | B11: Yêu cầu quản lý | C11: 6.1.2. Tổ chức bảo đảm ATTT | D11: Mục 6.1.2.2. Phối hợp với cơ quan có thẩm quyền | E11: 1 | F11: 2 | G11: Mục 6.1.2.2.a Có đầu mối liên hệ, phối hợp với các cơ quan, tổ chức có thẩm quyền quản lý về an toàn thông tin | H11: HSDX | I11: 6. Tài liệu khác liên quan | J11: Có đầu mối liên hệ, phối hợp với các cơ quan, tổ chức có thẩm quyền quản lý về an toàn thông tin | K11: 1. Đầu mối liên hệ, phối hợp với các cơ quan, tổ chức có thẩm quyền quản lý về an toàn thông tin: Sở/Ngành/Xã… (Đơn vị vận hành hệ thống thông tin) giao Phòng A (tên bộ phận chuyên trách của Đơn vị vận hành) là đầu mối liên hệ, phối hợp các cơ quan, tổ chức có thẩm quyền quản lý về an toàn thông tin phục vụ việc bảo đảm an toàn, an ninh mạng cho Hệ thống… | L11: - Điều kiện "ĐẠT" khi Quy chế An toàn thông tin có nội dung trên (Quy định tại khoản 1, Điều 5 Quy chế mẫu). - Yêu cầu Trích dẫn nội dung minh chứng vào phần Minh Chứng văn bản text trong phần mềm. - Nếu đáp ứng một phần, chưa đáp ứng: Đơn vị vận hành cập nhật, bổ sung ban hành trong vòng 15 ngày, kể từ khi HSĐXCĐ được phê duyệt.
A12: TCVN-ToChuc-04 | B12: Yêu cầu quản lý | C12: 6.1.2. Tổ chức bảo đảm ATTT | D12: Mục 6.1.2.2. Phối hợp với cơ quan có thẩm quyền | E12: 1 | F12: 2 | G12: Mục 6.1.2.2.b Có đầu mối liên hệ, phối hợp với các cơ quan, tổ chức trong công tác hỗ trợ điều phối xử lý sự cố an toàn thông tin | H12: HSDX | I12: 6. Tài liệu khác liên quan | J12: Có đầu mối liên hệ, phối hợp với các cơ quan, tổ chức trong công tác hỗ trợ điều phối xử lý sự cố an toàn thông tin | K12: 2. Đầu mối liên hệ, phối hợp với các cơ quan, tổ chức trong công tác hỗ trợ điều phối xử lý sự cố an toàn thông tin: a) Đội Ứng cứu sự cố an toàn thông tin mạng tỉnh: - Số điện thoại hotline 24/7: - Số điện thoại trong giờ hành chính: - Thư điện tử: panm.cat@khanhhoa.gov.vn. b) Cục An ninh mạng và phòng, chống tội phạm sử dụng công nghệ cao/Trung tâm Ứng cứu khẩn cấp không gian mạng Việt Nam (VNCERT) - Người liên hệ/bộ phận: - Số điện thoại: - Email: - Báo cáo sự cố qua nền tảng điều phối, xử lý sự cố an toàn thông tin mạng quốc gia: - Báo cáo sự cố qua website của VNCERT: | L12: - Điều kiện "ĐẠT" khi Quy chế An toàn thông tin có nội dung trên (Quy định tại khoản 2, Điều 5 Quy chế mẫu). - Yêu cầu Trích dẫn nội dung minh chứng vào phần Minh Chứng văn bản text trong phần mềm. - Nếu đáp ứng một phần, chưa đáp ứng: Đơn vị vận hành cập nhật, bổ sung ban hành trong vòng 15 ngày, kể từ khi HSĐXCĐ được phê duyệt.
A13: TCVN-ToChuc-05 | B13: Yêu cầu quản lý | C13: 6.1.2. Tổ chức bảo đảm ATTT | D13: Mục 6.1.2.2. Phối hợp với cơ quan có thẩm quyền | E13: 2 | F13: 2 | G13: Mục 6.1.2.2.c Tham gia các hoạt động, công tác bảo đảm an toàn thông tin khi có yêu cầu của tổ chức có thẩm quyền | H13: HSDX | I13: 6. Tài liệu khác liên quan | J13: Tham gia các hoạt động, công tác bảo đảm an toàn thông tin khi có yêu cầu của tổ chức có thẩm quyền | K13: Phối hợp với những cơ quan/tổ chức có thẩm quyền Tham gia các hoạt động, công tác bảo đảm an toàn thông tin khi có yêu cầu của các cơ quan, tổ chức có thẩm quyền. | L13: - Điều kiện "ĐẠT" khi Quy chế An toàn thông tin có nội dung trên (Quy định tại khoản 3 Điều 5 Quy chế mẫu). - Yêu cầu Trích dẫn nội dung minh chứng vào phần Minh Chứng văn bản text trong phần mềm. - Nếu đáp ứng một phần, chưa đáp ứng: Đơn vị vận hành cập nhật, bổ sung ban hành trong vòng 15 ngày, kể từ khi HSĐXCĐ được phê duyệt.
... A38: TCVN-VanHanh-09 | B38: Yêu cầu quản lý | C38: 6.1.5. Quản lý vận hành hệ thống | D38: Mục 6.1.5.3. Quản lý an toàn dữ liệu | E38: 2 | F38: 2 | G38: Mục 6.1.5.3.b. Định kỳ hoặc khi có thay đổi cấu hình trên hệ thống thực hiện quy trình sao lưu dự phòng: tập tin cấu hình hệ thống, bản dự phòng hệ điều hành máy chủ, cơ sở dữ liệu; dữ liệu, thông tin nghiệp vụ | H38: HSDX | I38: 4. Quy chế An toàn thông tin | J38: Có quy định định kỳ hoặc khi có thay đổi cấu hình trên hệ thống thực hiện quy trình sao lưu dự phòng: tập tin cấu hình hệ thống, bản dự phòng hệ điều hành máy chủ, cơ sở dữ liệu; dữ liệu, thông tin nghiệp vụ | K38: 2. Định kỳ hàng tháng hoặc khi có thay đổi cấu hình trên hệ thống thực hiện quy trình sao lưu dự phòng: tập tin cấu hình hệ thống, bản dự phòng hệ điều hành máy chủ, cơ sở dữ liệu; dữ liệu, thông tin nghiệp vụ. 3. Bản sao lưu được lưu trữ trên thiết bị hoặc hệ thống độc lập. | L38: - Điều kiện "ĐẠT" khi Quy chế An toàn thông tin có nội dung trên (Quy định tại khoản 2, 3 Điều 12 Quy chế mẫu). - Yêu cầu Trích dẫn nội dung minh chứng vào phần Minh Chứng văn bản text trong phần mềm. - Nếu đáp ứng một phần, chưa đáp ứng: Đơn vị vận hành cập nhật, bổ sung ban hành trong vòng 15 ngày, kể từ khi HSĐXCĐ được phê duyệt.
A39: TCVN-VanHanh-10 | B39: Yêu cầu quản lý | C39: 6.1.5. Quản lý vận hành hệ thống | D39: Mục 6.1.5.4. Quản lý sự cố an toàn thông tin | E39: 2 | F39: 2 | G39: Mục 6.1.5.4. Quản lý sự cố an toàn thông tin | J39: Phương án quản lý sự cố an toàn thông tin mạng | K39: Quản lý sự cố an toàn thông tin 1. Thực hiện cô lập hệ thống, ngắt kết nối với các hệ thống liên quan khác. 2. Khi có sự cố an toàn thông tin xảy ra, bộ phận chuyên trách phải sao lưu, dự phòng toàn bộ hiện trạng hệ thống trước khi xử lý sự cố. 3. Liên hệ với đầu mối ứng cứu sự cố theo thông tin đưa ra dưới đây: a) Đội Ứng cứu sự cố an toàn thông tin mạng tỉnh Khánh Hòa: - Số điện thoại hotline 24/7: - Số điện thoại trong giờ hành chính:. - Thư điện tử: panm.cat@khanhhoa.gov.vn b) Cục An ninh mạng và phòng, chống tội phạm sử dụng công nghệ cao/Trung tâm Ứng cứu khẩn cấp không gian mạng Việt Nam (VNCERT) - Người liên hệ/bộ phận: - Số điện thoại: - Email: - Báo cáo sự cố qua nền tảng điều phối, xử lý sự cố an toàn thông tin mạng quốc gia: - Báo cáo sự cố qua website của VNCERT. | L39: - Điều kiện "ĐẠT" khi Quy chế An toàn thông tin có nội dung trên (Quy định tại Điều 13 Quy chế mẫu). - Yêu cầu Trích dẫn nội dung minh chứng vào phần Minh Chứng văn bản text trong phần mềm. - Nếu đáp ứng một phần, chưa đáp ứng: Đơn vị vận hành cập nhật, bổ sung ban hành trong vòng 15 ngày, kể từ khi HSĐXCĐ được phê duyệt.
A40: TCVN-VanHanh-11 | B40: Yêu cầu quản lý | C40: 6.1.5. Quản lý vận hành hệ thống | D40: Mục 6.1.5.5. Quản lý an toàn người sử dụng đầu cuối | E40: 2 | F40: 2 | G40: Mục 6.1.5.5. Quản lý an toàn người sử dụng đầu cuối | J40: Có quy định về quản lý truy cập, sử dụng tài nguyên nội bộ | K40: Quản lý an toàn người sử dụng đầu cuối 1. Khi kết nối thiết bị lưu trữ ngoài như ổ cứng di động, các loại thẻ nhớ, thiết bị lưu trữ USB, ... phải quét virus trước khi đọc hoặc sao chép dữ liệu. 2. Không sử dụng các máy tính thuộc sở hữu cá nhân (máy xách tay của cá nhân, PDA) hoặc những thiết bị lưu trữ di động cá nhân vào mạng quản trị hoặc nghiệp vụ. Hạn chế tối đa việc sử dụng các thiết bị lưu trữ ngoài để sao chép, di chuyển dữ liệu. 3. Thiết lập mạng công cộng cho các máy tính thuộc sở hữu cá nhân (máy xách tay của cá nhân, PDA) hoặc những thiết bị lưu trữ di động cá nhân và có quản lý truy cập vùng mạng này với các vùng mạng khác trong hệ thống. 4. Máy tính người sử dụng phải được thiết lập chế độ cập nhật bản vá tự động và phần mềm phòng chống mã độc. | L40: - Điều kiện "ĐẠT" khi Quy chế An toàn thông tin có nội dung trên (Quy định tại Điều 14 Quy chế mẫu). - Yêu cầu Trích dẫn nội dung minh chứng vào phần Minh Chứng văn bản text trong phần mềm. - Nếu đáp ứng một phần, chưa đáp ứng: Đơn vị vận hành cập nhật, bổ sung ban hành trong vòng 15 ngày, kể từ khi HSĐXCĐ được phê duyệt.
A41: TCVN-VanHanh-12 | B41: Yêu cầu quản lý | C41: 6.1.5. Quản lý vận hành hệ thống | D41: Mục 6.1.5.6. Phương án Quản lý rủi ro an toàn thông tin | E41: 1 | F41: 2 | G41: Mục 6.1.5.6. Phương án Quản lý rủi ro an toàn thông tin | J41: Có chính sách, quy trình quản lý quản lý rủi ro an toàn thông tin | K41: Kiểm tra, đánh giá và quản lý rủi ro an toàn thông tin 1. Danh mục tài sản thông tin, dữ liệu có trong hệ thống. 2. Đánh giá các rủi ro an toàn thông tin đối với mỗi loại tài sản. 3. Có phương án dự phòng và khôi phục sau sự cố đối với thông tin, dữ liệu và ứng dụng. | L41: - Điều kiện "ĐẠT" khi Quy chế An toàn thông tin có nội dung trên (Quy định tại Điều 15 Quy chế mẫu). - Yêu cầu Trích dẫn nội dung minh chứng vào phần Minh Chứng văn bản text trong phần mềm. - Nếu đáp ứng một phần, chưa đáp ứng: Đơn vị vận hành cập nhật, bổ sung ban hành trong vòng 15 ngày, kể từ khi HSĐXCĐ được phê duyệt.
A42: TCVN-VanHanh-13 | B42: Yêu cầu quản lý | C42: 6.1.5. Quản lý vận hành hệ thống | D42: Mục 6.1.5.7. Phương án Kết thúc vận hành, khai thác, thanh lý, hủy bỏ hệ thống thông tin | E42: 1 | F42: 2 | G42: Mục 6.1.5.7. Phương án Kết thúc vận hành, khai thác, thanh lý, hủy bỏ hệ thống thông tin | J42: Có quy định, quy trình về Kết thúc vận hành, khai thác, thanh lý, hủy bỏ | K42: Kết thúc vận hành, khai thác, thanh lý, huỷ bỏ 1. Thiết bị CNTT có chứa dữ liệu (máy tính, thiết bị lưu trữ, ...) khi bị hỏng phải được cán bộ vận hành kiểm tra, sửa chữa, khắc phục. Phải có biện pháp kiểm tra, giám sát đảm bảo không để lọt lộ thông tin hay lây nhiễm mã độc đối với máy tính mang ra bên ngoài sửa chữa, bảo hành. 2. Trước khi tiến hành thanh lý/loại bỏ thiết bị công nghệ thông tin cũ, phải áp dụng các biện pháp kỹ thuật xoá bỏ hoàn toàn dữ liệu người dùng đã tạo ra, đảm bảo không thể phục hồi. 3. Các phương tiện và thiết bị CNTT: Máy tính cá nhân (PC), máy tính xách tay, máy chủ, các thiết bị mạng, phương tiện lưu trữ như CD/DVD, thẻ nhớ, ổ cứng phải xóa sạch dữ liệu khi chuyển giao hoặc thay đổi mục đích sử dụng. | L42: - Điều kiện "ĐẠT" khi Quy chế An toàn thông tin có nội dung trên (Quy định tại Điều 16 Quy chế mẫu). - Yêu cầu Trích dẫn nội dung minh chứng vào phần Minh Chứng văn bản text trong phần mềm. - Nếu đáp ứng một phần, chưa đáp ứng: Đơn vị vận hành cập nhật, bổ sung ban hành trong vòng 15 ngày, kể từ khi HSĐXCĐ được phê duyệt.
A43: TCVN-MANG-01 | B43: Yêu cầu kỹ thuật | C43: 6.2.1. Bảo đảm an toàn mạng | D43: Mục Mục 6.2.1.1. Thiết kế hệ thống | E43: 1 | F43: 2 | G43: Mục 6.2.1.1.a Các vùng mạng trong hệ thống: | H43: 8. Mang | I43: Phân vùng mạng | J43: a) Các vùng mạng trong hệ thống: Có thiết kế và cấu hình các vùng mạng: - Vùng mạng nội bộ. - Vùng mạng biên. - Vùng DMZ. - Vùng máy chủ nội bộ. - Vùng mạng không dây | K43: - Vùng mạng nội bộ độc lập, được thiết lập để cung cấp kết nối mạng cho các máy trạm, các thiết bị đầu cuối và các thiết bị khác của người dùng cuối - Vùng mạng biên: được thiết lập để cung cấp các kết nối hệ thống với mạng Internet và mạng khác - Vùng DMZ: đặt máy chủ dịch vụ, cung cấp dịch vụ trực tiếp ra bên ngoài Internet - Vùng đặt máy chủ nội bộ như máy chủ cơ sở dữ liệu, máy chủ lưu trữ dữ liệu nội bộ, … để cung cấp các dịch vụ nội bộ. - Vùng mạng không dây: Được thiết lập cho các thiết bị kết nối không dây. | L43: - Điều kiện "ĐẠT" khi Quy chế An toàn thông tin có nội dung, đồng thời cấu hình kỹ thuật theo phương án. - Đơn vị kĩ thuật kiểm tra và cập nhập hình ảnh cấu hình vào phần mềm. - Nếu đáp ứng một phần, chưa đáp ứng: Đơn vị vận hành phải cập nhật, bổ sung ban hành trong vòng 30 ngày, kể từ khi HSĐXCĐ được phê duyệt.
A44: TCVN-MANG-02 | B44: Yêu cầu kỹ thuật | C44: 6.2.1. Bảo đảm an toàn mạng | D44: Mục 6.2.1.1. Thiết kế hệ thống | E44: 1 | F44: 2 | G44: Mục 6.2.1.1.b Phương án bảo đảm an toàn thông tin (1) | J44: 1) Phương án bảo đảm an toàn thông tin Có Phương án quản lý truy cập, quản trị hệ thống từ xa an toàn | K44: Thiết bị tường lửa tích hợp tính năng quản lý truy cập từ xa VPN. Trường hợp truy cập, quản trị hệ thống từ xa phải sử dụng tài khoản VPN để kết nối vào mạng nội bộ. | L44: - Điều kiện "ĐẠT" khi Quy chế An toàn thông tin có nội dung, đồng thời cấu hình kỹ thuật theo phương án. - Đơn vị kĩ thuật kiểm tra và cập nhập hình ảnh cấu hình vào phần mềm. - Nếu đáp ứng một phần, chưa đáp ứng: Đơn vị vận hành phải cập nhật, bổ sung ban hành trong vòng 30 ngày, kể từ khi HSĐXCĐ được phê duyệt.
A45: TCVN-MANG-03 | B45: Yêu cầu kỹ thuật | C45: 6.2.1. Bảo đảm an toàn mạng | D45: Mục 6.2.1.1. Thiết kế hệ thống | E45: 1 | F45: 2 | G45: Mục 6.2.1.1.b Phương án bảo đảm an toàn thông tin (2) | J45: 2) Phương án bảo đảm an toàn thông tin Có Phương án quản lý truy cập giữa các vùng mạng và phòng chống xâm nhập | K45: Thiết bị tường lửa tích hợp tính năng phòng chống xâm nhập (IPS) để kiểm soát truy cập và phòng chống xâm nhập giữa các vùng mạng của hệ thống. | L45: - Điều kiện "ĐẠT" khi Quy chế An toàn thông tin có nội dung, đồng thời cấu hình kỹ thuật theo phương án. - Đơn vị kĩ thuật kiểm tra và cập nhập hình ảnh cấu hình vào phần mềm. - Nếu đáp ứng một phần, chưa đáp ứng: Đơn vị vận hành phải cập nhật, bổ sung ban hành trong vòng 30 ngày, kể từ khi HSĐXCĐ được phê duyệt.
A46: TCVN-MANG-04 | B46: Yêu cầu kỹ thuật | C46: 6.2.1. Bảo đảm an toàn mạng | D46: Mục 6.2.1.1. Thiết kế hệ thống | E46: 1 | F46: 2 | G46: Mục 6.2.1.1.b Phương án bảo đảm an toàn thông tin (3) | J46: 3) Phương án bảo đảm an toàn thông tin Có Phương án dự phòng cho các thiết bị mạng chính | K46: Các thiết bị mạng chính được thiết kế và cấu hình hoạt động ở chế độ Active-Active. Cụ thể: - Firewall: FW01/ Chủng loại; FW02/ Chủng loại (Dự phòng nóng cho FW01) - Router: Router01/ Chủng loại; Router02/ Chủng loại (Dự phòng nóng cho Router01) - Switch: L3 SW01/ Chủng loại; L3 SW02/ Chủng loại (Dự phòng nóng 1-1 cho L3 SW01) - SAN Storage: SAN01/ Chủng loại; SAN02/ Chủng loại (Dự phòng nóng cho SAN01) | L46: - Điều kiện "ĐẠT" khi Quy chế An toàn thông tin có nội dung, đồng thời cấu hình kỹ thuật theo phương án. - Đơn vị kĩ thuật kiểm tra và cập nhập hình ảnh cấu hình vào phần mềm. - Nếu đáp ứng một phần, chưa đáp ứng: Đơn vị vận hành phải cập nhật, bổ sung ban hành trong vòng 30 ngày, kể từ khi HSĐXCĐ được phê duyệt.
A47: TCVN-MANG-05 | B47: Yêu cầu kỹ thuật | C47: 6.2.1. Bảo đảm an toàn mạng | D47: Mục 6.2.1.2. Kiểm soát truy cập từ bên ngoài mạng | E47: 1 | F47: 2 | G47: Mục 6.2.1.2. Kiểm soát truy cập từ bên ngoài mạng (1) | J47: 1. Có Thiết lập hệ thống chỉ cho phép sử dụng các kết nối mạng an toàn khi truy cập thông tin nội bộ hoặc quản trị hệ thống từ các mạng bên ngoài và mạng Internet | K47: Hệ thống được thiết lập trên thiết bị tường lửa chỉ cho phép kết nối vào mạng nội bộ để truy cập thông tin nội bộ hoặc quản trị hệ thống thông qua VPN. | L47: - Điều kiện "ĐẠT" khi Quy chế An toàn thông tin có nội dung, đồng thời cấu hình kỹ thuật theo phương án. - Đơn vị kĩ thuật kiểm tra và cập nhập hình ảnh cấu hình vào phần mềm. - Nếu đáp ứng một phần, chưa đáp ứng: Đơn vị vận hành phải cập nhật, bổ sung ban hành trong vòng 30 ngày, kể từ khi HSĐXCĐ được phê duyệt.
A48: TCVN-MANG-06 | B48: Yêu cầu kỹ thuật | C48: 6.2.1. Bảo đảm an toàn mạng | D48: Mục 6.2.1.2. Kiểm soát truy cập từ bên ngoài mạng | E48: 1 | F48: 2 | G48: Mục 6.2.1.2. Kiểm soát truy cập từ bên ngoài mạng (2) | J48: 2. Kiểm soát truy cập từ bên ngoài vào hệ thống theo từng dịch vụ, ứng dụng cụ thể; chặn tất cả truy cập tới các dịch vụ, ứng dụng mà hệ thống không cung cấp hoặc không cho phép truy cập từ bên ngoài | K48: Hệ thống được thiết lập trên thiết bị tường lửa chỉ cho phép kết nối vào các cổng dịch vụ trên các máy chủ thuộc vùng DMZ như 80, 443. | L48: - Điều kiện "ĐẠT" khi Quy chế An toàn thông tin có nội dung, đồng thời cấu hình kỹ thuật theo phương án. - Đơn vị kĩ thuật kiểm tra và cập nhập hình ảnh cấu hình vào phần mềm. - Nếu đáp ứng một phần, chưa đáp ứng: Đơn vị vận hành phải cập nhật, bổ sung ban hành trong vòng 30 ngày, kể từ khi HSĐXCĐ được phê duyệt.
A49: TCVN-MANG-07 | B49: Yêu cầu kỹ thuật | C49: 6.2.1. Bảo đảm an toàn mạng | D49: Mục 6.2.1.2. Kiểm soát truy cập từ bên ngoài mạng | E49: 1 | F49: 2 | G49: Mục 6.2.1.2. Kiểm soát truy cập từ bên ngoài mạng (3) | J49: 3. Thiết lập giới hạn thời gian chờ (timeout) để đóng phiên kết nối khi hệ thống không nhận được yêu cầu từ người dùng. | K49: Thiết bị tường lửa được thiết lập giới hạn thời gian chờ (Session Timeout) để đóng phiên kết nối khi hệ thống không nhận được yêu cầu từ người dùng. | L49: - Điều kiện "ĐẠT" khi Quy chế An toàn thông tin có nội dung, đồng thời cấu hình kỹ thuật theo phương án. - Đơn vị kĩ thuật kiểm tra và cập nhập hình ảnh cấu hình vào phần mềm. - Nếu đáp ứng một phần, chưa đáp ứng: Đơn vị vận hành phải cập nhật, bổ sung ban hành trong vòng 30 ngày, kể từ khi HSĐXCĐ được phê duyệt.
A50: TCVN-MANG-08 | B50: Yêu cầu kỹ thuật | C50: 6.2.1. Bảo đảm an toàn mạng | D50: Mục 6.2.1.3 Kiểm soát truy cập từ bên trong mạng | E50: 1 | F50: 2 | G50: Mục 6.2.1.3 Kiểm soát truy cập từ bên trong mạng | J50: Chỉ cho phép truy cập các ứng dụng, dịch vụ bên ngoài theo yêu cầu nghiệp vụ, chặn các dịch vụ khác không phục vụ hoạt động nghiệp vụ theo chính sách của tổ chức | K50: Thiết bị tường lửa tích hợp tính năng Application Control, cho phép kiểm soát truy cập từ các vùng mạng trong hệ thống đi ra các mạng bên ngoài và mạng Internet. Giới hạn các truy cập đến các địa chỉ độc hại. | L50: - Điều kiện "ĐẠT" khi Quy chế An toàn thông tin có nội dung, đồng thời cấu hình kỹ thuật theo phương án. - Đơn vị kĩ thuật kiểm tra và cập nhập hình ảnh cấu hình vào phần mềm. - Nếu đáp ứng một phần, chưa đáp ứng: Đơn vị vận hành phải cập nhật, bổ sung ban hành trong vòng 30 ngày, kể từ khi HSĐXCĐ được phê duyệt.
A51: TCVN-MANG-09 | B51: Yêu cầu kỹ thuật | C51: 6.2.1. Bảo đảm an toàn mạng | D51: Mục 6.2.1.4. Nhật ký hệ thống | E51: 1 | F51: 2 | G51: Mục 6.2.1.4. Nhật ký hệ thống (1) | J51: 1. Có Thiết lập chức năng ghi, lưu trữ nhật ký hệ thống trên các thiết bị hệ thống | K51: Có Thiết lập cấu hình bản ghi log trên từng thiết bị: Router, FW01, FW02, L3 SW01, L3 SW02, SAN01, SAN02. | L51: - Điều kiện "ĐẠT" khi Quy chế An toàn thông tin có nội dung, đồng thời cấu hình kỹ thuật theo phương án. - Đơn vị kĩ thuật kiểm tra và cập nhập hình ảnh cấu hình vào phần mềm. - Nếu đáp ứng một phần, chưa đáp ứng: Đơn vị vận hành phải cập nhật, bổ sung ban hành trong vòng 30 ngày, kể từ khi HSĐXCĐ được phê duyệt.
A52: TCVN-MANG-10 | B52: Yêu cầu kỹ thuật | C52: 6.2.1. Bảo đảm an toàn mạng | D52: Mục 6.2.1.4. Nhật ký hệ thống | E52: 1 | F52: 2 | G52: Mục 6.2.1.4. Nhật ký hệ thống (2) | J52: 2. Sử dụng máy chủ thời gian trong hệ thống để đồng bộ thời gian | K52: Có có thiết lập máy chủ thời gian (NTP) trên từng thiết bị: Router, FW01, FW02, L3 SW01, L3 SW02, SAN01, SAN02. | L52: - Điều kiện "ĐẠT" khi Quy chế An toàn thông tin có nội dung, đồng thời cấu hình kỹ thuật theo phương án. - Đơn vị kĩ thuật kiểm tra và cập nhập hình ảnh cấu hình vào phần mềm. - Nếu đáp ứng một phần, chưa đáp ứng: Đơn vị vận hành phải cập nhật, bổ sung ban hành trong vòng 30 ngày, kể từ khi HSĐXCĐ được phê duyệt.
A53: TCVN-MANG-11 | B53: Yêu cầu kỹ thuật | C53: 6.2.1. Bảo đảm an toàn mạng | D53: Mục 6.2.1.5. Phòng chống xâm nhập | E53: 1 | F53: 2 | G53: Mục 6.2.1.5. Phòng chống xâm nhập (1) | J53: 1. Có phương án phòng chống xâm nhập để bảo vệ vùng DMZ và vùng máy chủ nội bộ | K53: * Nội dung thuyết minh & cấu hình: - Hệ thống có trang bị giải pháp IPS hoặc Firewall có tính năng IPS - Thiết bị tường lửa tích hợp tính năng phòng chống xâm nhập (IPS) để kiểm soát truy cập và phòng chống xâm nhập giữa các vùng mạng của hệ thống. | L53: - Điều kiện "ĐẠT" khi Quy chế An toàn thông tin có nội dung, đồng thời cấu hình kỹ thuật theo phương án. - Đơn vị kĩ thuật kiểm tra và cập nhập hình ảnh cấu hình vào phần mềm. - Nếu đáp ứng một phần, chưa đáp ứng: Đơn vị vận hành phải cập nhật, bổ sung ban hành trong vòng 30 ngày, kể từ khi HSĐXCĐ được phê duyệt.
A54: TCVN-MANG-12 | B54: Yêu cầu kỹ thuật | C54: 6.2.1. Bảo đảm an toàn mạng | D54: Mục 6.2.1.5. Phòng chống xâm nhập | E54: 1 | F54: 2 | G54: Mục 6.2.1.5. Phòng chống xâm nhập (2) | J54: 2. Định kỳ cập nhật cơ sở dữ liệu dấu hiệu phát hiện tấn công mạng (Signatures) | K54: * Nội dung thuyết minh & cấu hình: - Chức năng tự động cập nhật cơ sở dữ liệu dấu hiệu phát hiện tấn công mạng đều được thiết lập trên thiết bị tường lửa (IPS hoặc Firewall sử dụng bộ signature mới nhất và có cấu hình tự động cập nhật signature). | L54: - Điều kiện "ĐẠT" khi Quy chế An toàn thông tin có nội dung, đồng thời cấu hình kỹ thuật theo phương án. - Đơn vị kĩ thuật kiểm tra và cập nhập hình ảnh cấu hình vào phần mềm. - Nếu đáp ứng một phần, chưa đáp ứng: Đơn vị vận hành phải cập nhật, bổ sung ban hành trong vòng 30 ngày, kể từ khi HSĐXCĐ được phê duyệt.
A55: TCVN-MANG-13 | B55: Yêu cầu kỹ thuật | C55: 6.2.1. Bảo đảm an toàn mạng | D55: Mục 6.2.1.6. Bảo vệ thiết bị hệ thống | E55: 1 | F55: 2 | G55: Mục 6.2.1.6. Bảo vệ thiết bị hệ thống (1) | J55: 1. Cấu hình chức năng xác thực trên các thiết bị | K55: * Nội dung thuyết minh & cấu hình: - Có Thiết lập cấu hình trên các thiết bị: Router, FW01, FW02, L3 SW01, L3 SW02, SAN01, SAN02. - Thiết bị được thiết lập yêu cầu xác thực khi kết nối quản trị | L55: - Điều kiện "ĐẠT" khi Quy chế An toàn thông tin có nội dung, đồng thời cấu hình kỹ thuật theo phương án. - Đơn vị kĩ thuật kiểm tra và cập nhập hình ảnh cấu hình vào phần mềm. - Nếu đáp ứng một phần, chưa đáp ứng: Đơn vị vận hành phải cập nhật, bổ sung ban hành trong vòng 30 ngày, kể từ khi HSĐXCĐ được phê duyệt.
... A57: TCVN-MANG-15 | B57: Yêu cầu kỹ thuật | C57: 6.2.1. Bảo đảm an toàn mạng | D57: Mục 6.2.1.6. Bảo vệ thiết bị hệ thống | E57: 1 | F57: 2 | G57: Mục 6.2.1.6. Bảo vệ thiết bị hệ thống (3) | J57: 3. Hạn chế các địa chỉ mạng có thể kết nối, quản trị thiết bị từ xa | K57: * Nội dung thuyết minh & cấu hình: - Có Thiết lập cấu hình trên các thiết bị: Router, FW01, FW02, L3 SW01, L3 SW02, SAN01, SAN02. - kết nối SSH đến thiết bị được giới hạn theo địa chỉ IP hoặc vùng mạng | L57: - Điều kiện "ĐẠT" khi Quy chế An toàn thông tin có nội dung, đồng thời cấu hình kỹ thuật theo phương án. - Đơn vị kĩ thuật kiểm tra và cập nhập hình ảnh cấu hình vào phần mềm. - Nếu đáp ứng một phần, chưa đáp ứng: Đơn vị vận hành phải cập nhật, bổ sung ban hành trong vòng 30 ngày, kể từ khi HSĐXCĐ được phê duyệt.
A58: TCVN-MAYCHU-01 | B58: Yêu cầu kỹ thuật | C58: 6.2.2. Bảo đảm an toàn máy chủ | D58: Mục 6.2.2.1. Xác thực máy chủ | E58: 1 | F58: 2 | G58: Mục 6.2.2.1. Xác thực máy chủ (1) | J58: 1. Thiết lập chính sách xác thực trên máy chủ | K58: Có thiết lập cấu hình trên các thiết bị: - Web Server (máy ảo)/Cài đặt Web-App/Vùng DMZ/ Window Server 2019. - Database Server (máy ảo)/ Cài đặt SQL server 2019/Vùng máy chủ nội bộ/ Window Server 2019. * Nội dung thuyết minh & cấu hình: - máy chủ được thiết lập yêu cầu xác thực khi kết nối quản trị | L58: - Điều kiện "ĐẠT" khi Quy chế An toàn thông tin có nội dung, đồng thời cấu hình kỹ thuật theo phương án. - Đơn vị kĩ thuật kiểm tra và cập nhập hình ảnh cấu hình vào phần mềm. - Nếu đáp ứng một phần, chưa đáp ứng: Đơn vị vận hành phải cập nhật, bổ sung ban hành trong vòng 30 ngày, kể từ khi HSĐXCĐ được phê duyệt. | M58: Bắt buộc xác thực đăng nhập Trên Windows Pass nếu tất cả các điều kiện sau đều đúng: - Không cho phép đăng nhập bằng tài khoản trống mật khẩu qua mạng: LimitBlankPasswordUse = 1 - Account lockout threshold: ≤ 5 invalid attempts - Account lockout duration: ≥ 10 minutes Trên Linux Pass khi tất cả các giá trị sau đều đúng: SSH không cho phép đăng nhập bằng mật khẩu trực tiếp hoặc bắt buộc key-based: PasswordAuthentication no hoặc PubkeyAuthentication yes SSH không cho phép đăng nhập root trực tiếp: PermitRootLogin no SSH không cho phép mật khẩu trống: PermitEmptyPasswords no Cơ chế khóa tài khoản sau đăng nhập sai được cấu hình: deny = 5, unlock_time = 900 trong pam_faillock | N58: Ảnh chụp màn hình yêu cầu nhập User/Password khi truy cập (Console/RDP/SSH) vào Máy chủ. HOẶC Trên Windows - Kiểm tra giới hạn tài khoản mật khẩu trống: `Get-ItemProperty -Path "HKLM:\SYSTEM\CurrentControlSet\Control\Lsa" | Select-Object LimitBlankPasswordUse` (Kết quả đạt: LimitBlankPasswordUse = 1) - Kiểm tra chính sách khóa tài khoản: `net accounts` Trên Linux Kiểm tra cấu hình xác thực SSH: `grep -E "PasswordAuthentication|PermitRootLogin|PermitEmptyPasswords|PubkeyAuthentication" /etc/ssh/sshd_config` Kiểm tra timeout phiên SSH: `grep -E "ClientAliveInterval|ClientAliveCountMax" /etc/ssh/sshd_config` Kiểm tra cấu hình khóa tài khoản (faillock): `grep -E "faillock|tally" /etc/pam.d/system-auth /etc/pam.d/common-auth 2>/dev/null`; `cat /etc/security/faillock.conf 2>/dev/null`
A59: TCVN-MAYCHU-02 | B59: Yêu cầu kỹ thuật | C59: 6.2.2. Bảo đảm an toàn máy chủ | D59: Mục 6.2.2.1. Xác thực máy chủ | E59: 1 | F59: 2 | G59: Mục 6.2.2.1. Xác thực máy chủ (2) | J59: 2. Thay đổi các tài khoản mặc định trên hệ thống hoặc vô hiệu hóa | K59: Có thiết lập cấu hình trên các thiết bị: - Web Server (máy ảo)/Cài đặt Web-App/Vùng DMZ/ Window Server 2019. - Database Server (máy ảo)/ Cài đặt SQL server 2019/Vùng máy chủ nội bộ/ Window Server 2019. * Nội dung thuyết minh & cấu hình: - Tài khoản mặc định trên máy chủ được vô hiệu hoá, tài khoản Administrator đối với máy chủ Windows và root đối với máy chủ Linux | L59: - Điều kiện "ĐẠT" khi Quy chế An toàn thông tin có nội dung, đồng thời cấu hình kỹ thuật theo phương án. - Đơn vị kĩ thuật kiểm tra và cập nhập hình ảnh cấu hình vào phần mềm. - Nếu đáp ứng một phần, chưa đáp ứng: Đơn vị vận hành phải cập nhật, bổ sung ban hành trong vòng 30 ngày, kể từ khi HSĐXCĐ được phê duyệt. | M59: Đổi/Khóa tài khoản mặc định Trên Windows Pass nếu tất cả các điều kiện sau đều đúng: Tài khoản Administrator mặc định đã được đổi tên (không còn tên "Administrator") hoặc Disabled Tài khoản Guest có trạng thái: Account active: No Không có tài khoản mặc định nào khác (ví dụ: DefaultAccount, WDAGUtilityAccount) đang ở trạng thái Enabled mà không có mục đích rõ ràng Tài khoản quản trị thực tế đang dùng có tên khác, không trùng với tên mặc định của hệ thống Trên Linux Pass nếu tất cả các điều kiện sau đều đúng: Tài khoản root bị khóa đăng nhập trực tiếp: trường mật khẩu trong /etc/shadow hiển thị ! hoặc * (không thể đăng nhập bằng mật khẩu) Các tài khoản dịch vụ mặc định (bin, daemon, nobody, sys, mail, v.v.) có shell là /sbin/nologin hoặc /bin/false Không có tài khoản mặc định nào có UID < 1000 đang được phép đăng nhập shell tương tác (trừ trường hợp có lý do kỹ thuật được ghi nhận) | N59: Ảnh chụp Local Users and Groups hoặc file /etc/passwd cho thấy tài khoản Administrator/root đã bị đổi tên hoặc vô hiệu hóa (Nếu không sử dụng), tạo tài khoản Admin mới. HOẶC Với windows: Sử dụng PowerShell: `Get-LocalUser | Select-Object Name, Enabled, Description, LastLogon | Format-Table -AutoSize` Hoặc qua GUI: lusrmgr.msc → Users → kiểm tra danh sách và trạng thái từng tài khoản secpol.msc → Local Policies → Security Options → "Accounts: Rename administrator account" "Accounts: Rename guest account" "Accounts: Guest account status" Với linux: Kiểm tra trạng thái khóa tài khoản root: `sudo grep "^root:" /etc/shadow | cut -d: -f2` (Kết quả đạt: bắt đầu bằng ! hoặc *) Kiểm tra toàn bộ tài khoản hệ thống có shell tương tác (UID < 1000): `awk -F: '($3 < 1000) && ($7 != "/sbin/nologin") && ($7 != "/bin/false") && ($7 != "") {print $1, $3, $7}' /etc/passwd` Kiểm tra các tài khoản có thể đăng nhập (không bị khóa): `sudo passwd -S -a 2>/dev/null | grep -v "L\|NP" | awk '{print $1, $2}'`
A60: TCVN-MAYCHU-03 | B60: Yêu cầu kỹ thuật | C60: 6.2.2. Bảo đảm an toàn máy chủ | D60: Mục 6.2.2.1. Xác thực máy chủ | E60: 1 | F60: 2 | G60: Mục 6.2.2.1. Xác thực máy chủ (3) | J60: 3. Thiết lập chính sách mật khẩu an toàn: Yêu cầu thay đổi mật khẩu mặc định; Thiết lập quy tắc đặt mật khẩu về số ký tự, loại ký tự; Thiết lập thời gian yêu cầu thay đổi mật khẩu; Thiết lập thời gian mật khẩu hợp lệ | K60: Có thiết lập cấu hình trên các thiết bị: - Web Server (máy ảo)/Cài đặt Web-App/Vùng DMZ/ Window Server 2019. - Database Server (máy ảo)/ Cài đặt SQL server 2019/Vùng máy chủ nội bộ/ Window Server 2019. * Nội dung thuyết minh & cấu hình: - máy chủ được thiết lập yêu cầu mật khẩu có độ dài tối thiểu, các loại ký tự phải có trong mật khẩu, … | L60: - Điều kiện "ĐẠT" khi Quy chế An toàn thông tin có nội dung, đồng thời cấu hình kỹ thuật theo phương án. - Đơn vị kĩ thuật kiểm tra và cập nhập hình ảnh cấu hình vào phần mềm. - Nếu đáp ứng một phần, chưa đáp ứng: Đơn vị vận hành phải cập nhật, bổ sung ban hành trong vòng 30 ngày, kể từ khi HSĐXCĐ được phê duyệt. | M60: Trên Windows Pass nếu tất cả tiêu chí Cấp độ 1 đạt, cộng thêm: Maximum password age: ≤ 90 days Minimum password age: ≥ 1 day Enforce password history: ≥ 10 passwords remembered Trên Linux Pass khi tất cả tiêu chí Cấp độ 1 đạt, cộng thêm: PASS_MAX_DAYS ≤ 90 trong /etc/login.defs PASS_MIN_DAYS ≥ 1 trong /etc/login.defs PASS_WARN_AGE ≥ 7 trong /etc/login.defs Kết quả chage -l <username> của từng tài khoản thực tế khớp với chính sách trên | N60: Trên Windows Kiểm tra toàn bộ chính sách mật khẩu bao gồm tuổi thọ và lịch sử: `net accounts` Kiểm tra chi tiết qua PowerShell: `secedit /export /cfg C:\secpolicy.cfg Get-Content C:\secpolicy.cfg | Select-String -Pattern "PasswordHistorySize|MaximumPasswordAge|MinimumPasswordAge|MinimumPasswordLength|PasswordComplexity"` Hoặc qua GUI: secpol.msc → Account Policies → Password Policy → Maximum password age → Minimum password age → Enforce password history Trên Linux Kiểm tra chính sách tuổi thọ mật khẩu toàn hệ thống: `grep -E "PASS_MAX_DAYS|PASS_MIN_DAYS|PASS_WARN_AGE" /etc/login.defs` Kiểm tra tuổi thọ mật khẩu thực tế của từng tài khoản: `chage -l <username>` Kiểm tra hàng loạt tất cả tài khoản thực tế (UID ≥ 1000): `sudo -s awk -F: '($3 >= 1000) && ($1 != "nobody") {print $1}' /etc/passwd | xargs -I{} chage -l {}`
A61: TCVN-MAYCHU-04 | B61: Yêu cầu kỹ thuật | C61: 6.2.2. Bảo đảm an toàn máy chủ | D61: Mục 6.2.2.2. Kiểm soát truy cập máy chủ | E61: 1 | F61: 2 | G61: Mục 6.2.2.2. Kiểm soát truy cập máy chủ (1) | J61: 1. Chỉ cho phép sử dụng các kết nối mạng an toàn khi truy cập, quản trị máy chủ từ xa | K61: Có thiết lập cấu hình trên các thiết bị: - Web Server (máy ảo)/Cài đặt Web-App/Vùng DMZ/ Window Server 2019 - Database Server (máy ảo)/ Cài đặt SQL server 2019/Vùng máy chủ nội bộ/ Window Server 2019 * Nội dung thuyết minh & cấu hình: - Máy chủ được thiết lập kết nối quản trị theo giao thức RDP có NLA đối với máy chủ Windows và SSH đối với máy chủ Linux). | L61: - Điều kiện "ĐẠT" khi Quy chế An toàn thông tin có nội dung, đồng thời cấu hình kỹ thuật theo phương án. - Đơn vị kĩ thuật kiểm tra và cập nhập hình ảnh cấu hình vào phần mềm. - Nếu đáp ứng một phần, chưa đáp ứng: Đơn vị vận hành phải cập nhật, bổ sung ban hành trong vòng 30 ngày, kể từ khi HSĐXCĐ được phê duyệt.
A62: TCVN-MAYCHU-05 | B62: Yêu cầu kỹ thuật | C62: 6.2.2. Bảo đảm an toàn máy chủ | D62: Mục 6.2.2.2. Kiểm soát truy cập máy chủ | E62: 1 | F62: 2 | G62: Mục 6.2.2.2. Kiểm soát truy cập máy chủ (2) | J62: 2. Thiết lập giới hạn thời gian chờ (timeout) | K62: Có thiết lập cấu hình trên các thiết bị: - Web Server (máy ảo)/Cài đặt Web-App/Vùng DMZ/ Window Server 2019 - Database Server (máy ảo)/ Cài đặt SQL server 2019/Vùng máy chủ nội bộ/ Window Server 2019. * Nội dung thuyết minh & cấu hình: Máy chủ được thiết lập session timeout cho kết nối RDP hoặc SSH). | L62: - Điều kiện "ĐẠT" khi Quy chế An toàn thông tin có nội dung, đồng thời cấu hình kỹ thuật theo phương án. - Đơn vị kĩ thuật kiểm tra và cập nhập hình ảnh cấu hình vào phần mềm. - Nếu đáp ứng một phần, chưa đáp ứng: Đơn vị vận hành phải cập nhật, bổ sung ban hành trong vòng 30 ngày, kể từ khi HSĐXCĐ được phê duyệt.
A63: TCVN-MAYCHU-06 | B63: Yêu cầu kỹ thuật | C63: 6.2.2. Bảo đảm an toàn máy chủ | D63: Mục 6.2.2.3. Nhật ký hệ thống máy chủ | E63: 1 | F63: 2 | G63: Mục 6.2.2.3. Nhật ký hệ thống máy chủ (1) | J63: 1. Thiết lập lập chức năng ghi nhật ký hệ thống trên các máy chủ | K63: Có thiết lập cấu hình trên các thiết bị: - Web Server (máy ảo)/Cài đặt Web-App/Vùng DMZ/ Window Server 2019 - Database Server (máy ảo)/ Cài đặt SQL server 2019/Vùng máy chủ nội bộ/ Window Server 2019 * Nội dung thuyết minh & cấu hình: - Ghi nhật ký hệ thống bao gồm những thông tin cơ bản sau: - Thông tin kết nối mạng tới máy chủ (Firewall log); - Thông tin đăng nhập vào máy chủ; - Lỗi phát sinh trong quá trình hoạt động; - Thông tin thay đổi cấu hình máy chủ; - Thông tin truy cập dữ liệu và dịch vụ quan trọng trên máy chủ (nếu có). | L63: - Điều kiện "ĐẠT" khi Quy chế An toàn thông tin có nội dung, đồng thời cấu hình kỹ thuật theo phương án. - Đơn vị kĩ thuật kiểm tra và cập nhập hình ảnh cấu hình vào phần mềm. - Nếu đáp ứng một phần, chưa đáp ứng: Đơn vị vận hành phải cập nhật, bổ sung ban hành trong vòng 30 ngày, kể từ khi HSĐXCĐ được phê duyệt.
