Workbook

Sheet Tổng hợp CP PM
A2: DỰ TOÁN CHI PHÍ PHẦN MỀM NỘI BỘ
D3: (Đơn vị tính: VNĐ)
A4: STT | B4: Khoản mục chi phí | C4: Cách tính | D4: Giá trị | E4: Ký hiệu
A5: 1 | B5: Chi phí trực tiếp xây dựng, phát triển, nâng cấp, mở rộng phần mềm nội bộ | C5: 1,4 x E x P x H | D5: ='PLVIII.GTPM (G)'!F15 -> 8.4333198e+08 | E5: G
A6: 2 | B6: Chi phí chung | C6: G x 65% | D6: =65%*D5 -> 5.4816579e+08 | E6: C
A7: 3 | B7: Thu nhập chịu thuế tính trước | C7: (G+C) x 6% | D7: =(D5+D6)*6% -> 83489866 | E7: TL
A8: 4 | B8: Chi phí xây dựng, phát triển, nâng cấp, mở rộng phần mềm nội bộ | C8: G + C + TL | D8: =SUM(D5:D7) -> 1.4749876e+09 | E8: GPM
B9: TỔNG CỘNG: | D9: =D8 -> 1.4749876e+09

Sheet PLVIII.GTPM (G)
A2: PHỤ LỤC VIII: BẢNG TÍNH TOÁN CHI PHÍ TRỰC TIẾP XÂY DỰNG, PHÁT TRIỂN, MỞ RỘNG PHẦN MỀM NỘI BỘ
A4: STT | B4: Hạng mục | C4: ĐVT | D4: Diễn giải | F4: Giá trị | G4: Ghi chú
A5: I | B5: Tính điểm trường hợp sử dụng (Use case)
A6: 1 | B6: Điểm Actor (TAW) | C6: Điểm | D6: Phụ lục IV | F6: =PLIV.TAW!F8 -> 9 | G6: Bảng PLIV
A7: 2 | B7: Điểm Use case (TBF) | C7: Điểm | D7: Phụ lục V | F7: =PLV.TBF!F17 -> 505 | G7: Bảng PLV
A8: 3 | B8: Tính điểm UUCP | C8: Điểm | D8: UUCP=TAW+TBF | F8: =F6+F7 -> 514
A9: 4 | B9: Hệ số phức tạp về KT-CN (TCF) | C9: Điểm | D9: TCF=0,6+(0,01*TFW) | F9: =PLVI.TFW!E18 -> 0.875 | G9: Bảng PLVI
A10: 5 | B10: Điểm hệ số phức tạp môi trường (EF) | C10: Điểm | D10: EF=1,4+(-0,03*EFW) | F10: =PLVII.EFW!E13 -> 0.62 | G10: Bảng PLVII
A11: 6 | B11: Tính điểm AUCP | C11: Điểm | D11: AUCP=UUCP*TCF*EF | F11: =F8*F9*F10 -> 278.845
A12: II | B12: Nội suy thời gian lao động (P) | D12: P = người/giờ/AUCP | F12: =PLVII.EFW!F15 -> 21.363636 | G12: Bảng PLVII
A13: III | B13: Giá trị nỗ lực thực tế (E) | D13: E = AUCP*10/6 | F13: =F11*10/6 -> 464.74167
A14: IV | B14: Mức lương lao đồng bình quân (H) | C14: VNĐ | D14: H = người/giờ | F14: ='Lương-H'!E7 -> 60671.362 | G14: Lương trung bình thành viên tham gia
A15: V | B15: Chi phí trực tiếp xây dựng, phát triển, mở rộng phần mềm nội bộ (G) | C15: VNĐ | D15: G=1,4*E*P*H | F15: =1.4*F13*F12*F14 -> 8.4333198e+08

Sheet PLI.Actors
A1: PHỤ LỤC I BẢNG DANH SÁCH CÁC TÁC NHÂN THAM GIA VÀO HỆ THỐNG (ACTORS)
A2: STT | B2: Tên tác nhân | C2: Mô tả tác nhân | D2: Loại tác nhân
A3: 1 | B3: Quản trị hệ thống | C3: Cấu hình, phân quyền, quản lý danh mục và nhân viên trên Website | D3: Phức tạp (complex actor)
A4: 2 | B4: Nhân viên văn phòng | C4: Phân tuyến, tạo phiếu, xác nhận, xuất hóa đơn, xem báo cáo trên Website | D4: Phức tạp (complex actor)
A5: 3 | B5: Lãnh đạo | C5: Xem báo cáo thống kê, theo dõi tình hình thu phí trên Website | D5: Phức tạp (complex actor)
A6: 4 | B6: Nhân viên thu phí | C6: Thu phí tại hiện trường qua App Mobile: lấy phiếu, thu tiền, in phiếu, đồng bộ dữ liệu | D6: Phức tạp (complex actor)

Sheet PLII.DS chức năng
A1: PHỤ LỤC II
A2: BẢNG DANH SÁCH CÁC YÊU CẦU CHỨC NĂNG CỦA PHẦN MỀM
A3: TT | B3: Mô tả trường hợp | C3: Phân loại | D3: Ghi chú
A4: I. Website thu phí môi trường
A5: I.1. Đơn vị hành chính
A6: 1 | B6: Quản lý TỈNH | C6: Quản trị hệ thống
A7: 2 | B7: Quản lý HUYỆN/THÀNH PHỐ | C7: Quản trị hệ thống
A8: 3 | B8: Quản lý PHƯỜNG/XÃ | C8: Quản trị hệ thống
A9: 4 | B9: Quản lý KHU VỰC | C9: Quản trị hệ thống
A10: 5 | B10: Quản lý TUYẾN ĐƯỜNG | C10: Quản trị hệ thống
A11: I.2. Hệ Thống
A12: 6 | B12: Quản lý Cấu Hình Mobile | C12: Quản trị hệ thống
A13: 7 | B13: Quản lý Cấu Hình Hệ Thống | C13: Quản trị hệ thống
A14: 8 | B14: Quản lý Nhóm Quyền | C14: Quản trị hệ thống
A15: 9 | B15: Quản lý Lỗi Hệ Thống | C15: Quản trị hệ thống
A16: 10 | B16: Quản lý Menu | C16: Quản trị hệ thống
A17: 11 | B17: Đăng nhập | C17: Quản trị hệ thống/ Cán bộ nghiệp vụ
A18: 12 | B18: Thay đổi mật khẩu | C18: Quản trị hệ thống/ Cán bộ nghiệp vụ
A19: 13 | B19: Thông báo trên thanh header | C19: Quản trị hệ thống/ Cán bộ nghiệp vụ
A20: I.3. Danh Mục
A21: 14 | B21: Quản lý Nhóm Khách Hàng | C21: Cán bộ nghiệp vụ
A22: 15 | B22: Quản lý Nhóm Nhân viên | C22: Quản trị hệ thống
A23: 16 | B23: Quản lý Mức Phí | C23: Cán bộ nghiệp vụ
A24: 17 | B24: Quản lý nhân viên | C24: Quản trị hệ thống
A25: 18 | B25: Quản lý Khách Hàng Chưa Xác Nhận | C25: Cán bộ nghiệp vụ
A26: 19 | B26: Quản lý Khách Hàng | C26: Cán bộ nghiệp vụ
A27: 20 | B27: Thêm mới khách hàng không sử dụng hợp đồng | C27: Cán bộ nghiệp vụ
A28: 21 | B28: Thêm mới khách hàng sử dụng hợp đồng | C28: Cán bộ nghiệp vụ
A29: 22 | B29: Import danh sách hộ dân | C29: Cán bộ nghiệp vụ
A30: 23 | B30: Import danh sách doanh nghiệp | C30: Cán bộ nghiệp vụ
A31: 24 | B31: Chỉnh sửa thông tin khách hàng | C31: Cán bộ nghiệp vụ
A32: 25 | B32: Cập nhật Giá khách hàng | C32: Cán bộ nghiệp vụ
... A36: 29 | B36: Ngưng hoạt động và Mở hoạt động khách hàng | C36: Cán bộ nghiệp vụ
A37: I.4. Nghiệp vụ
A38: 30 | B38: Phân tuyến thu phí | C38: Cán bộ nghiệp vụ
A39: 31 | B39: Tạo phiếu thu | C39: Cán bộ nghiệp vụ
A40: 32 | B40: Xóa phiếu thu theo điều kiện | C40: Cán bộ nghiệp vụ
A41: 33 | B41: Quản lý phiếu thu | C41: Cán bộ nghiệp vụ
A42: 34 | B42: Xác nhận phiếu thu | C42: Cán bộ nghiệp vụ
A43: 35 | B43: Dữ liệu xác nhận | C43: Cán bộ nghiệp vụ
...

Sheet PLIII.Chuyển đổi UC
A1: PHỤ LỤC III
A2: BẢNG CHUYỂN ĐỔI YÊU CẦU CHỨC NĂNG SANG TRƯỜNG HỢP SỬ DỤNG (USE CASE)
I3: =SUM(I6:I1836) -> 45 | J3: =SUM(J6:J1836) -> 25 | K3: =SUM(K6:K1836) -> 2
A4: TT | B4: Tên Use case | C4: Tên tác nhân | D4: Giao dịch (Transaction) | E4: Phân loại theo BMT | F4: Phân loại theo độ phức tạp | G4: Ghi chú | H4: Số transaction | I4: Đơn giản | J4: Trung bình | K4: Phức tạp
A5: I. Website thu phí môi trường
A6: I.1. Đơn vị hành chính
A7: 1 | B7: Quản lý PHƯỜNG/XÃ | C7: Quản trị hệ thống | D7: Usecase tổng quát | E7: B | F7: =IF(H7>7,"Phức tạp",IF(H7>3,"Trung bình","Đơn giản")) -> Trung bình | H7: =COUNTA(D8:D11) -> 4 | J7: 1
D8: Hiển thị danh sách Phường/Xã của Huyện/Thành Phố
D9: Thêm thông tin Phường/Xã (Huyện/TP, Tên)
D10: Chỉnh sửa thông tin
D11: Xóa thông tin
A12: 2 | B12: Quản lý KHU VỰC | C12: Quản trị hệ thống | D12: Usecase tổng quát | E12: B | F12: =IF(H12>7,"Phức tạp",IF(H12>3,"Trung bình","Đơn giản")) -> Trung bình | H12: =COUNTA(D13:D16) -> 4 | J12: 1
D13: Hiển thị danh sách Khu Vực của Huyện/Thành Phố
D14: Thêm thông tin Khu Vực (Huyện/TP, Phường, Tên)
D15: Chỉnh sửa thông tin
D16: Xóa thông tin
A17: 3 | B17: Quản lý TUYẾN ĐƯỜNG | C17: Quản trị hệ thống | D17: Usecase tổng quát | E17: B | F17: =IF(H17>7,"Phức tạp",IF(H17>3,"Trung bình","Đơn giản")) -> Trung bình | H17: =COUNTA(D18:D21) -> 4 | J17: 1
D18: Hiển thị danh sách Tuyến đường của Huyện/Thành Phố
D19: Thêm thông tin Tuyến Đường (Tuyến đường có thể thuộc 1 tuyến đường cha, có thể nằm ở nhiều Phường/Xã, Tên tuyến đường)
D20: Chỉnh sửa thông tin
D21: Xóa thông tin
A22: I.2. Hệ Thống
A23: 4 | B23: Quản lý Cấu Hình Hệ Thống | C23: Quản trị hệ thống | D23: Usecase tổng quát | E23: B | F23: =IF(H23>7,"Phức tạp",IF(H23>3,"Trung bình","Đơn giản")) -> Trung bình | H23: =COUNTA(D24:D27) -> 4 | J23: 1
D24: Hiển thị danh sách Cấu Hình Hệ Thống của chương trình
D25: Thêm thông tin (Key, Giá Trị)
D26: Chỉnh sửa thông tin (Giá Trị)
D27: Xóa thông tin
A28: 5 | B28: Quản lý Nhóm Quyền | C28: Quản trị hệ thống | D28: Usecase tổng quát | E28: B | F28: =IF(H28>7,"Phức tạp",IF(H28>3,"Trung bình","Đơn giản")) -> Trung bình | H28: =COUNTA(D29:D33) -> 5 | J28: 1
D29: Hiển thị danh sách Nhóm Quyền của chương trình
D30: Thêm thông tin (AppCode, Tên nhóm)
D31: Chỉnh sửa thông tin
D32: Xóa thông tin
D33: Chọn Chức Năng cho Nhóm Quyền
A34: 6 | B34: Đăng nhập | C34: Quản trị hệ thống/ Cán bộ nghiệp vụ | D34: Usecase tổng quát | E34: B | F34: =IF(H34>7,"Phức tạp",IF(H34>3,"Trung bình","Đơn giản")) -> Đơn giản | H34: =COUNTA(D35:D35) -> 1 | I34: 1
D35: Đăng nhập bằng tài khoản và mật khẩu
A36: 7 | B36: Thay đổi mật khẩu | C36: Quản trị hệ thống/ Cán bộ nghiệp vụ | D36: Usecase tổng quát | E36: B | F36: =IF(H36>7,"Phức tạp",IF(H36>3,"Trung bình","Đơn giản")) -> Đơn giản | H36: =COUNTA(D37:D37) -> 1 | I36: 1
D37: Thay đổi mật khẩu mới: mật khẩu cũ, mật khẩu mới, xác định mật khẩu mới
A38: 8 | B38: Thông báo trên thanh header | C38: Quản trị hệ thống/ Cán bộ nghiệp vụ | D38: Usecase tổng quát | E38: B | F38: =IF(H38>7,"Phức tạp",IF(H38>3,"Trung bình","Đơn giản")) -> Trung bình | H38: =COUNTA(D39:D42) -> 4 | J38: 1
D39: Hiển thị số lượng hóa đơn chờ
D40: Hiển thị số lượng thông báo của nhân viên thu phí gửi lên
...

Sheet PLIV.TAW
A2: PHU LỤC IV BẢNG TÍNH TOÁN ĐIỂM CÁC TÁC NHÂN (ACTORS) TƯƠNG TÁC, TRAO ĐỔI THÔNG TIN VỚI PHẦN MỀM
A4: TT | B4: Loại Actor | C4: Mô tả | D4: Trọng số | E4: Số tác nhân | F4: Điểm của từng loại tác nhân
A5: 1 | B5: Đơn giản (simple actor) | C5: Giao diện lập trình ứng dụng (API) | D5: 1 | E5: 0 | F5: =D5*E5 -> 0
A6: 2 | B6: Trung bình (average actor) | C6: Giao diện dòng lệnh (CLI) hoặc giao diện thông qua một giao thức nào đó nhưng không phải giao diện lập trình ứng dụng (API) | D6: 2 | E6: =COUNTIF($C$9:$C$9,B6) -> 0 | F6: =D6*E6 -> 0
A7: 3 | B7: Phức tạp (complex actor) | C7: Giao diện đồ họa người dùng (GUI) | D7: 3 | E7: 3 | F7: =D7*E7 -> 9
B8: Cộng (1+2+3) | C8: TAW | F8: =SUM(F5:F7) -> 9

Sheet PLV.TBF
A2: PHỤ LỤC V BẢNG TÍNH TOÁN ĐIỂM CÁC TRƯỜNG HỢP SỬ DỤNG (USE-CASE)
A4: TT | B4: Loại | C4: Trọng số | D4: Hệ số BMT | E4: Số trường hợp sử dụng | F4: Điểm của từng loại trường hợp sử dụng
A5: 1 | B5: B
B6: Đơn giản | C6: 5 | D6: 1 | E6: =COUNTIFS('PLIII.Chuyển đổi UC'!$E$7:$E$1836,"B",'PLIII.Chuyển đổi UC'!$F$7:$F$1836,"Đơn giản") -> 45 | F6: =D6*C6*E6 -> 225
B7: Trung bình | C7: 10 | D7: 1 | E7: =COUNTIFS('PLIII.Chuyển đổi UC'!$E$7:$E$1836,"B",'PLIII.Chuyển đổi UC'!$F$7:$F$1836,"Trung bình") -> 25 | F7: =D7*C7*E7 -> 250
B8: Phức tạp | C8: 15 | D8: 1 | E8: =COUNTIFS('PLIII.Chuyển đổi UC'!$E$7:$E$1836,"B",'PLIII.Chuyển đổi UC'!$F$7:$F$1836,"Phức tạp") -> 2 | F8: =D8*C8*E8 -> 30
A9: 2 | B9: M
B10: Đơn giản | C10: 5 | D10: 1.2 | E10: =COUNTIFS('PLIII.Chuyển đổi UC'!$E$7:$E$1836,"M",'PLIII.Chuyển đổi UC'!$F$7:$F$1836,"Đơn giản") -> 0 | F10: =C10*D10*E10 -> 0
B11: Trung bình | C11: 10 | D11: 1.2 | E11: =COUNTIFS('PLIII.Chuyển đổi UC'!$E$7:$E$1836,"M",'PLIII.Chuyển đổi UC'!$F$7:$F$1836,"Trung bình") -> 0 | F11: =D11*C11*E11 -> 0
B12: Phức tạp | C12: 15 | D12: 1.2 | E12: =COUNTIFS('PLIII.Chuyển đổi UC'!$E$7:$E$1836,"M",'PLIII.Chuyển đổi UC'!$F$7:$F$1836,"Phức tạp") -> 0 | F12: =D12*C12*E12 -> 0
A13: 3 | B13: T
B14: Đơn giản | C14: 5 | D14: 1.5 | E14: =COUNTIFS('PLIII.Chuyển đổi UC'!$E$7:$E$1836,"T",'PLIII.Chuyển đổi UC'!$F$7:$F$1836,"Đơn giản") -> 0 | F14: =D14*C14*E14 -> 0
B15: Trung bình | C15: 10 | D15: 1.5 | E15: =COUNTIFS('PLIII.Chuyển đổi UC'!$E$7:$E$1836,"T",'PLIII.Chuyển đổi UC'!$F$7:$F$1836,"Trung bình") -> 0 | F15: =D15*C15*E15 -> 0
B16: Phức tạp | C16: 15 | D16: 1.5 | E16: =COUNTIFS('PLIII.Chuyển đổi UC'!$E$7:$E$1836,"T",'PLIII.Chuyển đổi UC'!$F$7:$F$1836,"Phức tạp") -> 0 | F16: =D16*C16*E16 -> 0
B17: Cộng (1+2+3) | E17: TBF | F17: =SUM(F6:F16) -> 505

Sheet PLVI.TFW
A1: PHỤ LỤC VI BẢNG TÍNH TOÁN HỆ SỐ PHỨC TẠP KỸ THUẬT - CÔNG NGHỆ
A3: TT | B3: Các hệ số | C3: Trọng số | D3: Giá trị xếp hạng | E3: Kết quả | F3: Ghi chú
A4: I | B4: Hệ số KT - CN (TFW) | E4: =SUM(E5:E17) -> 27.5
B5: Xử lý phân tán | C5: 1 | D5: 0 | E5: =C5*D5 -> 0 | F5: Giá trị xếp hạng Yêu cầu cụ thể cho giá trị 0: Không yêu cầu xử lý phân tán. 1:Yêu cầu một lớp/thành phần của hệ thống tạo dữ liệu và truyền cho các lớp/thành phần khác của hệ thống để xử lý thủ công (có sự can thiệp của con người). 2: Yêu cầu một lớp/thành phần của hệ thống tạo dữ liệu và truyền cho các lớp/thành phần khác của hệ thống để xử lý tự động (không cần con người can thiệp vào việc xử lý). 3: Yêu cầu xử lý phân tán, dữ liệu được truyền theo một chiều (dữ liệu được xử lý tại một lớp/thành phần của hệ thống và được truyền qua lớp/thành phần khác của hệ thống xử lý tiếp). 4: Yêu cầu xử lý phân tán, dữ liệu được truyền theo hai chiều (dữ liệu được xử lý tại một lớp/thành phần của hệ thống và được truyền qua lớp/thành phần khác của hệ thống xử lý tiếp, sau khi xử lý xong, dữ liệu được truyền ngược lại cho lớp/thành phần ban đầu của hệ thống) 5: Yêu cầu hệ thống có thể tự động phân bổ tài nguyên (CPU, RAM, ...) một cách hợp lý cho các lớp/thành phần của hệ thống khi xử lý phân tán hoặc yêu cầu hệ thống tự động lựa chọn lớp/thành phần thích hợp nhất để xử lý.
A6: 2 | B6: Mức độ quan trọng của hiệu năng | C6: 1 | D6: 2 | E6: =C6*D6 -> 2 | F6: Xác định giá trị xếp hạng: 0: Không có yêu cầu về hiệu năng. 1: Có yêu cầu về hiệu năng nhưng không cụ thể. 2: Yêu cầu cụ thể về hiệu năng trong giờ cao điểm. Không có yêu cầu thiết kế riêng biệt về sử dụng tài nguyên hệ thống để đáp ứng yêu cầu hiệu năng trong giờ cao điểm. 3: Yêu cầu cụ thể hiệu năng trong toàn bộ thời gian tác nghiệp. Không có yêu cầu thiết kế riêng biệt về sử dụng tài nguyên hệ thống để đáp ứng yêu cầu hiệu năng, yêu cầu cụ thể về thời gian phản hồi đối với các giao dịch được xử lý với các hệ thống (tích hợp) khác. 4: Gồm các yêu cầu trong trường hợp “Giá trị xếp hạng” = 3 và có yêu cầu phân tích cụ thể, rõ ràng hiệu năng trong thiết kế trên cơ sở các yêu cầu về hiệu năng được nêu. 5: Gồm các yêu cầu trong trường hợp “Giá trị xếp hạng” = 4 và yêu cầu có công cụ phân tích hiệu năng để sử dụng trong các giai đoạn phát triển, triển khai nhằm chứng minh việc đáp ứng các yêu cầu về hiệu năng đã đặt ra.
A7: 3 | B7: Hiệu quả sử dụng cho người dùng | C7: 1 | D7: 2 | E7: =C7*D7 -> 2 | F7: Xác định giá trị xếp hạng: Một số tiêu chí đưa ra để đánh giá hiệu quả sử dụng như: - Trợ giúp điều hướng (ví dụ: các menu được tạo động và thêm bớt tùy nhu cầu người dùng, Hypermedia thích hợp,…).; - Di chuyển con trỏ tự động (khi một trường thông tin đã được nhập xong, ví dụ như chọn giá trị trong danh sách thì con trỏ được chuyển sang trường thông tin tiếp theo); - Các phím chức năng được cài đặt sẵn (các phím tắt được gán cho các phím hoặc tổ hợp phím cho phép thực hiện tác vụ nào đó, như tổ hợp phím Alt+phím, Ctrl+phím,…); - Các ràng buộc đơn giản (ví dụ: tính hợp lệ của trường dữ liệu nhập vào, như dữ liệu kiểu số, dữ liệu ngày tháng,…) được kiểm tra ngay trên màn hình chức năng mà người dùng tương tác; - Sử dụng nhiều màu sắc và hình ảnh nổi bật trong màn hình (hoặc việc sử dụng màu sắc, hình ảnh hoặc hình nền có tính chất tương phản cao để làm nổi bật nội dung); giao diện có nét tương đồng về mặt thiết kế so với các ứng dụng mà người dùng đang sử dụng (đưa ra cụ thể các yêu cầu về giao diện để chứng minh tính tương đồng với các ứng dụng đang sử dụng); - Tối thiểu hóa số lượng giao diện để đạt được các mục tiêu nghiệp vụ (yêu cầu cụ thể số lượng giao diện tối thiểu); - Hỗ trợ và tài liệu trực tuyến (từ hệ thống có thể gọi chức năng trợ giúp tương ứng với chức năng đang chọn hoặc gọi tới tài liệu như một phần trong hệ thống); - Hỗ trợ song ngữ, đa ngôn ngữ; - Các tiêu chí khác. Giá trị xếp hạng TFW3 theo các tiêu chí này được xác định như bảng dưới đây: 0 Không có yêu cầu nào về hiệu quả sử dụng theo các tiêu chí nêu trên. 1 Yêu cầu đáp ứng từ 1 đến 3 tiêu chí nêu trên. 2 Yêu cầu đáp ứng từ 4 đến 5 tiêu chí nêu trên. 3 Yêu cầu đáp ứng từ 6 tiêu chí nêu trên trở lên. 4 Yêu cầu đáp ứng từ 6 tiêu chí nêu trên trở lên và phần mềm được thiết kế phải có các phương án, giải pháp để giảm thiểu thao tác nhập liệu thủ công, tối đa hóa các giá trị mặc định, sử dụng các mẫu biểu sẵn có. 5 Yêu cầu đáp ứng từ 7 tiêu chí nêu trên trở lên và phần mềm được thiết kế phải có các phương án, giải pháp để giảm thiểu thao tác nhập liệu thủ công, tối đa hóa các giá trị mặc định, sử dụng các mẫu biểu sẵn có.
A8: 4 | B8: Độ phức tạp của xử lý bên trong | C8: 2 | D8: 2 | E8: =C8*D8 -> 4 | F8: Xác định giá trị xếp hạng: Một số tiêu chí để đánh giá độ phức tạp của xử lý bên trong như: - Yêu cầu kiểm soát dữ liệu và/hoặc xử lý bảo mật riêng; - Yêu cầu xử lý lô-gic mở rộng: là các yêu cầu bổ sung thêm làm các chức năng hoàn thiện hơn (ví dụ: các xử lý kiểm tra tính hợp lý của dữ liệu nhập vào,…); - Yêu cầu có sử dụng công thức toán học: Yêu cầu sử dụng các công thức tính toán theo tỷ lệ, theo công thức định nghĩa trước hoặc theo các điều kiện dữ liệu khác nhau,...; - Yêu cầu xử lý ngoại lệ cho những giao dịch không hoàn chỉnh phải được xử lý lại (ví dụ: các giao dịch máy rút tiền tự động chưa hoàn thành do bị ngắt kết nối hoặc lỗi dữ liệu); - Yêu cầu xử lý nhiều loại thông tin đầu vào hoặc thông tin đầu ra (ví dụ: yêu cầu xử lý các loại thông tin dạng tệp, âm thanh, hình ảnh; yêu cầu xử lý thông tin đầu vào nhận được từ thiết bị đa phương tiện, thiết bị ngoại vi độc lập, giọng nói, đọc mã vạch, quét võng mạc, phân tích hơi thở,...); - Các tiêu chí khác. Giá trị xết hạng TFW4 theo các tiêu chí này được xác định như bảng dưới đây: 0 Không có yêu cầu nào trong 5 loại tiêu chí nêu trên. 1 Có 1 yêu cầu trong các tiêu chí nêu trên. 2 Có 2 yêu cầu trong các tiêu chí nêu trên. 3 Có 3 yêu cầu trong các tiêu chí nêu trên. 4 Có 4 yêu cầu trong các tiêu chí nêu trên. 5 Có 5 yêu cầu trong các tiêu chí nêu trên.
A9: 5 | B9: Khả năng tái sử dụng mã nguồn | C9: 1 | D9: 3 | E9: =C9*D9 -> 3 | F9: Xác định giá trị xếp hạng: 0 Không có yêu cầu về việc tái sử dụng mã nguồn. 3 Yêu cầu ứng dụng phải được đóng gói riêng và/hoặc tài liệu hóa nhằm tạo điều kiện cho việc tái sử dụng lại. Có yêu cầu có thể tùy chỉnh ứng dụng để tái sử dụng bằng cách điều chỉnh mã nguồn. 5 Yêu cầu ứng dụng phải được đóng gói riêng và/hoặc tài liệu hóa nhằm tạo điều kiện cho việc tái sử dụng lại. Có yêu cầu có thể tùy chỉnh ứng dụng để tái sử dụng bằng cách thay đổi tham số mà không cần điều chỉnh mã nguồn.
A10: 6 | B10: Dễ cài đặt | C10: 0.5 | D10: 2 | E10: =C10*D10 -> 1 | F10: Xác định giá trị xếp hạng: 0 Không có yêu cầu cài đặt. 1 Yêu cầu cung cấp công cụ hỗ trợ cài đặt tự động trên một môi trường vận hành phần mềm (hệ điều hành máy chủ, máy tính, thiết bị di động,…) không có yêu cầu thiết lập thông số khi cài đặt. 2 Yêu cầu cung cấp công cụ hỗ trợ cài đặt tự động trên một môi trường vận hành phần mềm (hệ điều hành máy chủ, máy tính, thiết bị di động,…), có yêu cầu thiết lập thông số khi cài đặt. 3 Yêu cầu cung cấp công cụ hỗ trợ cài đặt tự động trên một môi trường vận hành phần mềm (hệ điều hành máy chủ, máy tính, thiết bị di động,…), có yêu cầu thiết lập thông số khi cài đặt và có yêu cầu phải xây dựng tài liệu hướng dẫn cài đặt. 4 Yêu cầu cung cấp công cụ hỗ trợ cài đặt tự động trên hai môi trường vận hành phần mềm (hệ điều hành máy chủ, máy tính, thiết bị di động,…), yêu cầu thiết lập thông số khi cài đặt trên hai môi trường và có yêu cầu phải xây dựng tài liệu hướng dẫn cài đặt. 5 Yêu cầu cung cấp công cụ hỗ trợ cài đặt tự động từ ba môi trường vận hành phần mềm (hệ điều hành máy chủ, máy tính, thiết bị di động,…) trở lên, yêu cầu thiết lập thông số khi cài đặt trên các môi trường và có yêu cầu phải xây dựng tài liệu hướng dẫn cài đặt.
A11: 7 | B11: Dễ vận hành | C11: 0.5 | D11: 3 | E11: =C11*D11 -> 1.5 | F11: Xác định giá trị xếp hạng: 0 Việc vận hành hệ thống thực hiện đơn giản, không yêu cầu lập quy trình vận hành hệ thống. 3 Việc vận hành hệ thống thực hiện theo quy trình, có yêu cầu phải lập quy trình vận hành hệ thống. 5 Việc vận hành hệ thống thực hiện tự động, có nghĩa là không cần sự can thiệp của con người để vận hành hệ thống ngay cả khi có lỗi xảy ra, trừ việc khởi động hoặc tắt hệ thống. Hệ thống có chức năng tự khôi phục khi có lỗi.
A12: 8 | B12: Khả năng chuyển đổi | C12: 1 | D12: 3 | E12: =C12*D12 -> 3 | F12: Xác định giá trị xếp hạng: Một số tiêu chí đưa ra để đánh giá khả năng chuyển đổi gồm: - Yêu cầu về môi trường vận hành phần mềm: hệ thống có thể chạy trên chỉ một môi trường (ví dụ: chỉ chạy trên Windows 10); hệ thống có thể chạy trên các môi trường tương tự (ví dụ: từ Windows XP trở lên); hệ thống có thể chạy trên các môi trường không đồng nhất (ví dụ: Windows, OSX, Unix, Android, iOS). - Yêu cầu về nền tảng phần cứng (loại thiết bị): (i) Hệ thống chỉ chạy trên một loại thiết bị (ví dụ: chỉ chạy trên máy tính cá nhân sử dụng bộ vi xử lý theo kiến trúc x86 ở một thế hệ nhất định, ví dụ thế hệ Intel 80486 (có kiến trúc 32 bit); hay chỉ chạy với bộ vi xử lý kiến trúc ARM ở một thế hệ nhất định,…); (ii) Hệ thống có thể chạy trên nhiều loại thiết bị tương tự (ví dụ: các máy tính cá nhân cùng sử dụng bộ vi xử lý có kiến trúc x86 từ hai thế hệ gần nhau trở lên: dòng vi xử lý Intel 64 bít (như Intel Pentium Dual-Core, Intel Core 2, Intel Core i3/i5/i7). Hay phần mềm được xây dựng cho một loại thiết bị phần cứng đặc thù và có thể chạy được với hơn một thế hệ (hoặc phiên bản) của dòng thiết bị đó (ví dụ: thiết bị Raspberry Pi); (iii) Hệ thống có thể chạy trên nhiều loại thiết bị không đồng nhất (ví dụ: máy tính cá nhân, máy tính bảng, điện thoại); - Các tiêu chí khác. Giá trị xếp hạng TFW8 theo các tiêu chí này được xác định như bảng dưới đây: 0 Chỉ yêu cầu hệ thống vận hành trên một môi trường phần mềm và phần cứng cụ thể. 3 Có yêu cầu hệ thống vận hành được trên môi trường phần mềm hoặc phần cứng tương tự nhau. 5 Có yêu cầu hệ thống vận hành được trên nhiều môi trường phần mềm hoặc phần cứng không đồng nhất.
A13: 9 | B13: Dễ dàng bảo trì | C13: 1 | D13: 3 | E13: =C13*D13 -> 3 | F13: Xác định giá trị xếp hạng: 0 Không có yêu cầu về việc chỉnh sửa hệ thống trong tương lai. 3 Có yêu cầu về việc chỉnh sửa hệ thống trong tương lai mà không cần lập trình lại từ đầu. 5 Có yêu cầu về việc chỉnh sửa hệ thống trong tương lai mà không cần lập trình lại, chỉ cần cấu hình lại hệ thống.
A14: 10 | B14: Xử lý đồng thời | C14: 1 | D14: 3 | E14: =C14*D14 -> 3 | F14: Xác định giá trị xếp hạng: 0 Không có yêu cầu truy cập dữ liệu đồng thời. 1 Yêu cầu truy cập dữ liệu đồng thời nhưng không thường xuyên. 2 Yêu cầu truy cập dữ liệu đồng thời theo định kỳ. 3 Yêu cầu truy cập dữ liệu đồng thời tại mọi thời điểm. 4 Gồm các yêu cầu trong trường hợp “Giá trị xếp hạng” = 3 và thiết kế phải đưa ra phương án, giải pháp đánh giá, xử lý các điểm tắc nghẽn khi truy cập dữ liệu đồng thời. 5 Gồm các yêu cầu trong trường hợp “Giá trị xếp hạng” = 4 và thiết kế phải đề xuất công cụ kiểm soát việc xử lý truy cập dữ liệu đồng thời.
A15: 11 | B15: Mức độ hỗ trợ bảo mật | C15: 2 | D15: 1 | E15: =C15*D15 -> 2 | F15: Xác định giá trị xếp hạng: Một số tiêu chí đưa ra để đánh giá mức độ hỗ trợ bảo mật như sau: tiêu chí mức 1, mức 2, mức 3, mức 4, mức 5 tương ứng với yêu cầu kỹ thuật của hệ thống thông tin cấp độ 1, cấp độ 2, cấp độ 3, cấp độ 4, cấp độ 5 trong yêu cầu an toàn cơ bản đối với phần mềm nội bộ quy định tại Thông tư số 12/2022/TT-BTTTT ngày 12/8/2022 của Bộ trưởng Bộ Thông tin và Truyền thông quy định chi tiết và hướng dẫn một số điều của Nghị định số 85/2016/NĐ-CP ngày 01 tháng 7 năm 2016 về bảo đảm an toàn hệ thống thông tin theo cấp độ và Quyết định số 742/QĐ-BTTTT ngày 22/4/2022 của Bộ trưởng Bộ Thông tin và Truyền thông ban hành yêu cầu an toàn cơ bản đối với phần mềm nội bộ. Giá trị xếp hạng TFW11 theo các tiêu chí này được xác định như bảng dưới đây: 0 Không có yêu cầu bảo mật. 1 Yêu cầu bảo mật mức 1. 2 Yêu cầu bảo mật mức 2. 3 Yêu cầu bảo mật mức 3. 4 Yêu cầu bảo mật mức 4. 5 Yêu cầu bảo mật mức 5.
A16: 12 | B16: Sự phụ thuộc vào mã lệnh của bên thứ ba | C16: 1 | D16: 2 | E16: =C16*D16 -> 2 | F16: Xác định giá trị xếp hạng: 0 Sử dụng mã lệnh sẵn có (không cần hiệu chỉnh) để phát triển toàn bộ ứng dụng. 1 Sử dụng mã lệnh sẵn có (không cần hiệu chỉnh) để phát triển một phần của ứng dụng. 2 Hiệu chỉnh mã lệnh sẵn có để phát triển toàn bộ ứng dụng. 3 Hiệu chỉnh mã lệnh sẵn có để phát triển một phần của ứng dụng. 4 Mã lệnh sẵn có được sử dụng để phát triển ứng dụng, nhưng cần phải sửa lỗi hoặc rất khó để sử dụng mã lệnh sẵn có. 5 Không sử dụng mã lệnh sẵn có để phát triển ứng dụng.
A17: 13 | B17: Mức độ hỗ trợ đào tạo người sử dụng | C17: 1 | D17: 1 | E17: =C17*D17 -> 1 | F17: Xác định giá trị xếp hạng: 0 Không có yêu cầu hỗ trợ của hệ thống về đào tạo người sử dụng. 1 Có yêu cầu hỗ trợ của hệ thống về đào tạo người sử dụng. 2 Có yêu cầu hỗ trợ của hệ thống về đào tạo người sử dụng, hệ thống có một số tiện ích để hỗ trợ đào tạo. 3 Hệ thống có một số tiện ích để hỗ trợ đào tạo người sử dụng ở nhiều cấp độ khác nhau. 4 Hệ thống có một số tiện ích để hỗ trợ đào tạo người sử dụng cho giai đoạn chuyển tiếp từ hệ thống cũ sang hệ thống mới. 5 Gồm các yêu cầu trong trường hợp “Giá trị xếp hạng” = 4 và yêu cầu hỗ trợ của hệ thống về đào tạo cho nhiều đối tượng người sử dụng với các nội dung đào tạo khác nhau.
A18: II | B18: Hệ số phức tạp về kỹ thuật - công nghệ (TCF) | E18: =0.6+(0.01*E4) -> 0.875

Sheet PLVII.EFW
A1: PHỤ LỤC VII: BẢNG TÍNH TOÁN HỆ SỐ TÁC ĐỘNG MÔI TRƯỜNG VÀ NHÓM LÀM VIỆC, HỆ SỐ PHỨC TẠP VỀ MÔI TRƯỜNG, XÁC ĐỊNH ĐỘ ỔN ĐỊNH KINH NGHIỆM VÀ NỘI SUY THỜI GIAN LAO ĐỘNG
A3: TT | B3: Các hệ số tác động môi trường | C3: Trọng số | D3: Giá trị xếp hạng | E3: Kết quả | F3: Đánh giá độ ổn định kinh nghiệm
A4: I | B4: Hệ số tác động môi trường và nhóm làm việc (EFW) | D4: =SUM(D5:D12) -> 30 | E4: =SUM(E5:E12) -> 26
A5: 1 | B5: Có áp dụng quy trình phát triển phần mềm | C5: 1.5 | D5: 5 | E5: =C5*D5 -> 7.5 | F5: =IF(E5>3,1,IF(E5>2,0.6,IF(E5>1,0.1,IF(E5>0,0.05,0)))) -> 1
A6: 2 | B6: Kinh nghiệm phát triển ứng dụng tương tự | C6: 0.5 | D6: 5 | E6: =C6*D6 -> 2.5 | F6: =IF(E6>3,1,IF(E6>2,0.6,IF(E6>1,0.1,IF(E6>0,0.05,0)))) -> 0.6
A7: 3 | B7: Kinh nghiệm về hướng đối tượng | C7: 1 | D7: 5 | E7: =C7*D7 -> 5 | F7: =IF(E7>3,1,IF(E7>2,0.6,IF(E7>1,0.1,IF(E7>0,0.05,0)))) -> 1
A8: 4 | B8: Kinh nghiệm của trưởng nhóm lập trình | C8: 0.5 | D8: 4 | E8: =C8*D8 -> 2 | F8: =IF(E8>3,1,IF(E8>2,0.6,IF(E8>1,0.1,IF(E8>0,0.05,0)))) -> 0.1
A9: 5 | B9: Tính chủ động | C9: 1 | D9: 4 | E9: =C9*D9 -> 4 | F9: =IF(E9>3,1,IF(E9>2,0.6,IF(E9>1,0.1,IF(E9>0,0.05,0)))) -> 1
A10: 6 | B10: Độ ổn định của các yêu cầu | C10: 2 | D10: 4 | E10: =C10*D10 -> 8 | F10: =IF(E10>3,1,IF(E10>2,0.6,IF(E10>1,0.1,IF(E10>0,0.05,0)))) -> 1
A11: 7 | B11: Sử dụng các nhân viên làm bán thời gian | C11: -1 | D11: 0 | E11: =C11*D11 -> 0 | F11: =IF(E11>3,1,IF(E11>2,0.6,IF(E11>1,0.1,IF(E11>0,0.05,0)))) -> 0
A12: 8 | B12: Kinh nghiệm sử dụng ngôn ngữ lập trình | C12: -1 | D12: 3 | E12: =C12*D12 -> -3 | F12: =IF(E12>3,1,IF(E12>2,0.6,IF(E12>1,0.1,IF(E12>0,0.05,0)))) -> 0
A13: II | B13: Hệ số phức tạp về môi trường (EF) | E13: =ROUND(1.4+(-0.03*E4),4) -> 0.62
A14: III | B14: Độ ổn định kinh nghiệm (ES) | F14: =SUM(F5:F13) -> 4.7
A15: IV | B15: Nội suy thời gian lao động (P) | F15: =IF(F14>=3,26-(F14-3)*6/2.2,IF(F14>=1,40-(F14-1)*7,48 -F14*8)) -> 21.363636

Sheet KN Thành Viên
A1: BẢNG 4: BẢNG DỰ KIẾN TRÌNH ĐỘ VÀ KINH NGHIỆM CẦN CÓ CỦA THÀNH VIÊN NHÓM DỰ ÁN
A3: STT | B3: Các hệ số | C3: Điểm đánh giá
C4: Nhóm 3 | J4: Nhóm 2 | L4: Nhóm 1
C5: NV1 | D5: NV2 | E5: NV3 | F5: NV4 | G5: NV5 | H5: NV6 | I5: NV7 | J5: NV8 | K5: NV9 | L5: NV10
A6: 1 | B6: Kĩ năng lập trình
A7: Lập trinh Web
B8: HTML | C8: 3 | D8: 3 | E8: 3 | F8: 3 | G8: 3 | H8: 3 | I8: 3 | J8: 3.5 | K8: 3.5 | L8: 4
B9: Css | C9: 3 | D9: 3 | E9: 3 | F9: 3 | G9: 3 | H9: 3 | I9: 3 | J9: 3.5 | K9: 3.5 | L9: 4
B10: Javascript | C10: 3 | D10: 3 | E10: 3 | F10: 3 | G10: 3 | H10: 3 | I10: 3 | J10: 3.5 | K10: 3.5 | L10: 4
A11: Lập trinh Microsoft
B12: Microsoft.NET | C12: 3 | D12: 3 | E12: 3.5 | F12: 3.5 | G12: 4 | H12: 3 | I12: 3 | J12: 3.5 | K12: 3.5 | L12: 4
B13: C# | C13: 3 | D13: 3 | E13: 3.5 | F13: 3.5 | G13: 4 | H13: 3 | I13: 3 | J13: 3.5 | K13: 3.5 | L13: 4
A14: 2 | B14: Kiến thức về phần mềm
A15: Phần mềm CSDL
B16: SQL Server | C16: 2 | D16: 2.5 | E16: 2.5 | F16: 3.5 | G16: 3.5 | H16: 2.5 | I16: 2.5 | J16: 3.5 | K16: 3.5 | L16: 4.5
B17: Oracle | C17: 2 | D17: 2 | E17: 2.5 | F17: 2.5 | G17: 2 | H17: 2 | I17: 2 | J17: 3 | K17: 3.5 | L17: 4
A18: Phần mềm Microsoft
B19: Frontpage | C19: 2 | D19: 2.5 | E19: 2.5 | F19: 3 | G19: 3 | H19: 2.5 | I19: 2.5 | J19: 3.5 | K19: 3.5 | L19: 4
B20: MS Word | C20: 3 | D20: 3 | E20: 4 | F20: 3 | G20: 4 | H20: 3 | I20: 3 | J20: 4 | K20: 4 | L20: 4
B21: MS Excel | C21: 2 | D21: 2 | E21: 2 | F21: 3 | G21: 3 | H21: 2 | I21: 2 | J21: 3 | K21: 3 | L21: 4
B22: MS Access | C22: 2 | D22: 2 | E22: 1.5 | F22: 2 | G22: 2 | H22: 2 | I22: 2 | J22: 3 | K22: 3.5 | L22: 4.5
B23: Visio | C23: 2 | D23: 2 | E23: 2 | F23: 2 | G23: 2 | H23: 2.5 | I23: 2 | J23: 3 | K23: 3 | L23: 4
B24: MS Project | C24: 2.5 | D24: 2 | E24: 2 | F24: 2.5 | G24: 2.5 | H24: 2 | I24: 2 | J24: 3 | K24: 3 | L24: 4.5
A25: Phần mềm hệ thống, kiên thức hệ thống
B26: Win XP/2000, 7 | C26: 2 | D26: 2 | E26: 2 | F26: 3 | G26: 3 | H26: 2 | I26: 2 | J26: 3 | K26: 3 | L26: 4
B27: Win 2003, 2008 Server | C27: 3 | D27: 3 | E27: 3 | F27: 3.5 | G27: 3.5 | H27: 3 | I27: 3 | J27: 3 | K27: 3 | L27: 4.5
B28: LAN | C28: 2.5 | D28: 2 | E28: 2 | F28: 3 | G28: 3.5 | H28: 2 | I28: 2 | J28: 3 | K28: 3 | L28: 4.5
B29: WAN | C29: 2.5 | D29: 2.5 | E29: 2 | F29: 2.5 | G29: 3 | H29: 2.5 | I29: 2.5 | J29: 3.5 | K29: 3.5 | L29: 4
B30: Internet | C30: 3 | D30: 3 | E30: 3 | F30: 3 | G30: 3 | H30: 3 | I30: 3 | J30: 3 | K30: 3 | L30: 4
B31: Intranet | C31: 2 | D31: 2 | E31: 2.5 | F31: 3 | G31: 3 | H31: 2 | I31: 2 | J31: 3 | K31: 3.5 | L31: 4
A32: 3 | B32: Hiểu biết về quy trình và kinh nghiệm thực tế (ghi rõ loại)
B33: Có áp dụng quy trình phát triển phần mềm theo mẫu RUP và có hiểu biết về RUP hoặc quy trình phát triển phần mềm tương đương | C33: 4 | D33: 4 | E33: 4 | F33: 4 | G33: 4 | H33: 4 | I33: 4 | J33: 4 | K33: 4 | L33: 4
B34: Có kinh nghiệm về ứng dụng tương tự | C34: 3 | D34: 3 | E34: 4 | F34: 4 | G34: 4 | H34: 4 | I34: 4 | J34: 4 | K34: 4 | L34: 4
B35: Có kinh nghiệm về hướng đối tượng | C35: 3 | D35: 3 | E35: 4 | F35: 4 | G35: 4 | H35: 4 | I35: 4 | J35: 4 | K35: 4 | L35: 4
B36: Có khả năng lãnh đạo Nhóm | C36: 2 | D36: 2 | E36: 2 | F36: 2.5 | G36: 2.5 | H36: 2.5 | I36: 2.5 | J36: 3.5 | K36: 3.5 | L36: 4
B37: Có tính cách năng động | C37: 2 | D37: 2 | E37: 3 | F37: 3 | G37: 3 | H37: 3 | I37: 3 | J37: 3 | K37: 3 | L37: 3

Sheet Lương-H
B1: BẢNG 6: MỨC LƯƠNG LAO ĐỘNG BÌNH QUÂN
B2: (Đơn vị tính: đồng)
B3: STT | C3: Nhân viên | D3: Tỷ lệ | E3: Mức lương (giờ/người) | F3: Ghi chú
B4: 1 | C4: Nhóm 1 | D4: 0.2 | E4: =bangluong!E16 -> 71095.5 | F4: Mức lương trả cho nhân viên bậc 3
B5: 2 | C5: Nhóm 2 | D5: 0.2 | E5: =bangluong!D16 -> 63649.688 | F5: Mức lương trả cho nhân viên bậc 2
B6: 3 | C6: Nhóm 3 | D6: 0.6 | E6: =bangluong!C16 -> 56203.875 | F6: Mức lương trả cho nhân viên bậc 1
B7: Mức lương lao động bình quân (H) | E7: =D4*E4+D5*E5+D6*E6 -> 60671.362

Sheet bangluong
A2: BẢNG LƯƠNG NHÂN CÔNG KỸ SƯ CNTT
K3: Đơn vị tính: đồng
A4: TT | B4: Tiêu chí xác định | K4: Ghi chú
A5: 1 | B5: Cấp bậc kỹ sư CNTT | C5: KS-B1 | D5: KS-B2 | E5: KS-B3 | F5: KS-B4 | G5: KS-B5 | H5: KS-B6 | I5: KS-B7 | J5: KS-B8
A6: 2 | B6: Hệ số lương (Hcb) | C6: 2.34 | D6: 2.65 | E6: 2.96 | F6: 3.27 | G6: 3.58 | H6: 3.89 | I6: 4.2 | J6: 4.51 | K6: Quyết định 129/QĐ-BTTTT ngày 3/2/2021 của Bộ TTTT
A7: 3 | B7: Hệ số phụ cấp (Hpc) | C7: =$C$18 -> 0 | D7: =$C$18 -> 0 | E7: =$C$18 -> 0 | F7: =$C$18 -> 0 | G7: =$C$18 -> 0 | H7: =$C$18 -> 0 | I7: =$C$18 -> 0 | J7: =$C$18 -> 0 | K7: Theo quy định của pháp luật lao động và các văn bản có liên quan
A8: 4 | B8: Mức lương cơ sở (MLcs) | C8: =$C$34 -> 2340000 | D8: =$C$34 -> 2340000 | E8: =$C$34 -> 2340000 | F8: =$C$34 -> 2340000 | G8: =$C$34 -> 2340000 | H8: =$C$34 -> 2340000 | I8: =$C$34 -> 2340000 | J8: =$C$34 -> 2340000 | K8: Nghị định số 73/2024/NĐ-CP ngày 01/7/2024 của Chính phủ
A9: 5 | B9: Mức lương cơ bản (MLcb) | C9: =(C6+C7)*C8 -> 5475600 | D9: =(D6+D7)*D8 -> 6201000 | E9: =(E6+E7)*E8 -> 6926400 | F9: =(F6+F7)*F8 -> 7651800 | G9: =(G6+G7)*G8 -> 8377200 | H9: =(H6+H7)*H8 -> 9102600 | I9: =(I6+I7)*I8 -> 9828000 | J9: =(J6+J7)*J8 -> 10553400
A10: 6 | B10: Điều chỉnh tăng thêm tiền lương (Hdc) | C10: 0.9 | D10: 0.9 | E10: 0.9 | F10: 0.9 | G10: 0.9 | H10: 0.9 | I10: 0.9 | J10: 0.9 | K10: Quyết định 129/QĐ-BTTTT ngày 3/2/2021 của Bộ TTTT
A11: 7 | B11: Lương cơ bản (Hcb+Hcp) * MLcs * (1+Hdc) | C11: =(C6+C7)*C8*(1+C10) -> 10403640 | D11: =(D6+D7)*D8*(1+D10) -> 11781900 | E11: =(E6+E7)*E8*(1+E10) -> 13160160 | F11: =(F6+F7)*F8*(1+F10) -> 14538420 | G11: =(G6+G7)*G8*(1+G10) -> 15916680 | H11: =(H6+H7)*H8*(1+H10) -> 17294940 | I11: =(I6+I7)*I8*(1+I10) -> 18673200 | J11: =(J6+J7)*J8*(1+J10) -> 20051460
A12: 8 | B12: Tiền lương tháng đóng BHXH bắt buộc | C12: =IF($C$32<C9,C9,($C$32)) -> 5475600 | D12: =IF($C$32<D9,D9,($C$32)) -> 6201000 | E12: =IF($C$32<E9,E9,($C$32)) -> 6926400 | F12: =IF($C$32<F9,F9,($C$32)) -> 7651800 | G12: =IF($C$32<G9,G9,($C$32)) -> 8377200 | H12: =IF($C$32<H9,H9,($C$32)) -> 9102600 | I12: =IF($C$32<I9,I9,($C$32)) -> 9828000 | J12: =IF($C$32<J9,J9,($C$32)) -> 10553400
A13: 9 | B13: Chi phí khác tính trong chi phí tiền lương thuộc trách nhiệm đóng của người sử dụng lao động | C13: =C12*SUM($C$23:$C$26) -> 1286766 | D13: =D12*SUM($C$23:$C$26) -> 1457235 | E13: =E12*SUM($C$23:$C$26) -> 1627704 | F13: =F12*SUM($C$23:$C$26) -> 1798173 | G13: =G12*SUM($C$23:$C$26) -> 1968642 | H13: =H12*SUM($C$23:$C$26) -> 2139111 | I13: =I12*SUM($C$23:$C$26) -> 2309580 | J13: =J12*SUM($C$23:$C$26) -> 2480049
A14: 10 | B14: Mức lương lao động/Tháng (Hcb+Hcp) * MLcs * (1+Hdc) + BHlđ | C14: =C11+C13 -> 11690406 | D14: =D11+D13 -> 13239135 | E14: =E11+E13 -> 14787864 | F14: =F11+F13 -> 16336593 | G14: =G11+G13 -> 17885322 | H14: =H11+H13 -> 19434051 | I14: =I11+I13 -> 20982780 | J14: =J11+J13 -> 22531509
A15: 11 | B15: Mức lương lao động/Ngày | C15: =C14/$C$28 -> 449631 | D15: =D14/$C$28 -> 509197.5 | E15: =E14/$C$28 -> 568764 | F15: =F14/$C$28 -> 628330.5 | G15: =G14/$C$28 -> 687897 | H15: =H14/$C$28 -> 747463.5 | I15: =I14/$C$28 -> 807030 | J15: =J14/$C$28 -> 866596.5 | K15: Thời gian lao động để tính mức lương lao động bình quân tháng là 26 ngày.
A16: 12 | B16: Mức lương lao động/Giờ | C16: =C15/$C$29 -> 56203.875 | D16: =D15/$C$29 -> 63649.688 | E16: =E15/$C$29 -> 71095.5 | F16: =F15/$C$29 -> 78541.312 | G16: =G15/$C$29 -> 85987.125 | H16: =H15/$C$29 -> 93432.938 | I16: =I15/$C$29 -> 100878.75 | J16: =J15/$C$29 -> 108324.56 | K16: Thời gian lao động 08 giờ/ngày
B18: Hệ số phụ cấp (Hpc) | C18: 0
B20: Vùng | C20: I | D20: II | E20: III | F20: IV
B21: Hệ số điều chỉnh tăng thêm tiền lương (Hdc) | C21: 1.2 | D21: 0.9 | E21: 0.7 | F21: 0.5
B23: Bảo hiểm xã hội | C23: 0.175
B24: Bảo hiểm y tế | C24: 0.03
B25: Bảo hiểm thất nghiệp | C25: 0.01
B26: Kinh phí công đoàn | C26: 0.02
B28: Mức lương lao động/Ngày | C28: 26
B29: Mức lương lao động/Giờ | C29: 8
B31: Vùng | C31: I | D31: II | E31: III | F31: IV
B32: Mức lương tối thiểu vùng áp dụng đối với người lao động làm việc theo hợp đồng lao động (Từ ngày 01/7/2024) | C32: 4960000 | D32: 4410000 | E32: 3860000 | F32: 3450000
B34: Mức lương cơ sở (Từ ngày 01/7/2024) | C34: 2340000

Sheet 2.1.Đào tạo HDSD
A1: BẢNG DỰ TOÁN: CHI PHÍ ĐÀO TẠO HƯỚNG DẪN SỬ DỤNG
A3: TT | B3: Nội dung | C3: ĐVT | D3: Số lượng | E3: Đơn giá | F3: Thành tiền | G3: Ghi chú
A5: I | B5: Đào tạo hướng dẫn sử dụng | G5: Đối tượng: Chuyên viên, lãnh đạo các phòng ban trực thuộc. Tổng số nhân sự: 40 người Số lớp: 02 lớp Số lượng: 20 người/1 lớp (02 lớp). Thời gian: 02 buổi/lớp.
A6: 1 | B6: Chi phí cho giảng viên | F6: =SUM(F7:F8) -> 3500000
B7: Thù lao cho Giảng viên (01 người x 02 lớp x 02 buổi) | C7: buổi | D7: 4 | E7: 800000 | F7: =D7*E7 -> 3200000 | G7: Theo nghị quyết số 15/2023/NQ-HĐND ngày 11/10/2023
B8: Phụ cấp tiền ăn cho giảng viên và trợ giảng (01 người x 02 ngày) | C8: ngày | D8: 2 | E8: 150000 | F8: =D8*E8 -> 300000 | G8: Nghị quyết số 15/2017/NQ-HĐND điều 3, khoản 4
A9: 2 | B9: Chi phí khác (nước uống, VPP…) | F9: =SUM(F10:F11) -> 3260000
B10: Chi phí nước uống (40 học viên x 02 buổi,01 giảng viên, 01 trợ giảng x2 buổi) | C10: buổi | D10: 84 | E10: 15000 | F10: =D10*E10 -> 1260000 | G10: Nghị quyết số 15/2017/NQ-HĐND điều 3, khoản 3
B11: Chi văn phòng phẩm cho học viên | C11: người | D11: 40 | E11: 50000 | F11: =D11*E11 -> 2000000 | G11: Chi theo thực tế
A12: 3 | B12: Chi phí tài liệu | C12: 60 | F12: =F13 -> 2400000
B13: In tài liệu đào tạo | C13: Bộ | D13: 40 | E13: 60000 | F13: =E13*D13 -> 2400000 | G13: Chi theo thực tế
B14: TỔNG CỘNG | F14: =SUM(F6,F9,F12) -> 9160000

Sheet 2.2.Đào tạo QTHT
A2: BẢNG DỰ TOÁN: CHI PHÍ TẬP HUẤN VẬN HÀNH QUẢN TRỊ HỆ THỐNG
A4: TT | B4: Nội dung | C4: ĐVT | D4: Số lượng | F4: Đơn giá | G4: Thành tiền | H4: Ghi chú
D5: Ngày | E5: Người
A6: I | B6: Đào tạo vận hành quản trị hệ thống Đối tượng: Cán bộ vận hành hệ thống(Dự kiến 10 người) Số lượng: 1 lớp. Thời gian: 02 buổi/lớp. | F6: 02 buổi đào tạo trong vòng 01 ngày, mỗi buổi 4 tiếng
A7: 1 | B7: Chi phí cho giảng viên | G7: =SUM(G8:G9) -> 1750000
B8: Thù lao cho Giảng viên (1 người) | C8: buổi | D8: 2 | E8: 1 | F8: 800000 | G8: =D8*E8*F8 -> 1600000 | H8: Theo nghị quyết số 15/2023/NQ-HĐND ngày 11/10/2023
B9: Phụ cấp tiền ăn cho giảng viên (1 người) | C9: ngày | D9: 1 | E9: 1 | F9: 150000 | G9: =D9*E9*F9 -> 150000 | H9: Nghị quyết số 15/2017/NQ-HĐND điều 3, khoản 4
A10: 2 | B10: Chi phí khác (nước uống, VPP…) | G10: =SUM(G11:G12) -> 830000
B11: Chi phí nước uống (10 học viên + 1 giáo viên) | C11: buổi | D11: 2 | E11: 11 | F11: 15000 | G11: =D11*E11*F11 -> 330000 | H11: Nghị quyết số 15/2017/NQ-HĐND điều 3, khoản 3
B12: Chi văn phòng phẩm (10 học viên) | C12: lớp | D12: 1 | E12: 10 | F12: 50000 | G12: =D12*E12*F12 -> 500000 | H12: Chi theo thực tế
A13: 3 | B13: Chi phí tài liệu | G13: =G14 -> 500000
B14: In tài liệu đào tạo | C14: Bộ | D14: 10 | F14: 50000 | G14: =F14*D14 -> 500000 | H14: Chi theo thực tế
B15: TỔNG CỘNG | G15: =SUM(G7,,G10,G13) -> 3080000
