Workbook
Name MiscellaneousWork: #N/A
Name MiscellaneousWork_18: #REF!
Name Mita: #REF!
Name mk: #REF!
Name mkcnGPS15: #REF!
Name mkcnTRC15: #REF!
Name mkcnVRM: #REF!
Name mkeobh165: #REF!
Name mkeobh215: #REF!
Name mkeobh28: #REF!
Name mkeobh40: #REF!
Name mkeobh50: #REF!
Name mkeobh55: #REF!
Name mkeobh60: #REF!
Name mkeobh80: #REF!
Name mkeobx108: #REF!
Name mkeobx130: #REF!
Name mkeobx45: #REF!
Name mkeobx54: #REF!
Name mkeobx60: #REF!
Name mkeobx75: #REF!
Name mkhoanbttay24: #REF!
Name mkhoanbttay30: #REF!
Name mkhoanbttay38: #REF!
Name mkhoanbttay40: #REF!
Name Mkhoancamtay: #REF!
Name mkhoandatay30: #REF!
Name mkhoandatay42: #REF!
Name mkhoandung4.5: #REF!
Name mkhoansattay13: #REF!
Name mkhoanxoayth110: #REF!
Name mkhoanxoayth95: #REF!
Name mkichck18: #REF!
Name mkichck250: #REF!
Name mkichday60: #REF!
Name mkichnang100: #REF!
Name mkichnang250: #REF!
Name mkichnang500: #REF!
Name mknn: [10]ms22!$K$6
Name Mkt: #REF!
Name mktum: #REF!
Name ML: #REF!
Name ml_: #REF!
Name ml_1: {"Thuxm2.xls","Sheet1"}
Name ml_10: {"Thuxm2.xls","Sheet1"}
Name ml_10_1: {"Thuxm2.xls","Sheet1"}
Name ml_11: {"Thuxm2.xls","Sheet1"}
Name ml_11_1: {"Thuxm2.xls","Sheet1"}
Name ml_3: {"Thuxm2.xls","Sheet1"}
Name ml_3_1: {"Thuxm2.xls","Sheet1"}
Name ml_7: {"Thuxm2.xls","Sheet1"}
Name ml_7_1: {"Thuxm2.xls","Sheet1"}
Name MLATTS: #REF!
Name MLCALLS: #REF!
Name MLCALLS2: #REF!
Name MLM: #REF!
Name MLN: #REF!
Name MLS_con_POTS_menos_1: #REF!
Name MLS_cover_B: #REF!
Name mls_ext1: #REF!

Sheet CPQL1
A1: BẢNG TÍNH CHI PHÍ TƯ VẤN
A2: Công việc: Quản lý hạng mục
A3: I. Bảng dự toán giá trị công việc "Quản lý hạng mục" (Căn cứ theo Quyết định 2378/QĐ-BTTTT ngày 30/12/2016 và Quyết định 1688/QĐ-BTTTT ngày 11/10/2019):
A4: STT | B4: CHI PHÍ | C4: DIỄN GIẢI | D4: ĐƠN GIÁ | E4: SỐ NGÀY | F4: GIÁ TRỊ | G4: GHI CHÚ
A5: 1 | B5: Chi phí chuyên gia | C5: (Lcg + Pc) | F5: =SUM(F7:F12) -> 73830645 | G5: Ccg
A6: 1.1 | B6: Chi phí chuyên gia thuê khoán | G6: Lcg
B7: Thành viên 1 Quản lý dự án | C7: Đơn giá ngày công x Số ngày | D7: =G37 -> 289808.39 | E7: 48 | F7: =D7*E7 -> 13910803 | G7: - Tổ chức quản lý chất lượng, khối lượng và tiến độ thực hiện dự án - Tư vấn giúp chủ đầu tư hệ thống hóa và kiểm soát tài liệu của dự án - Dự kiến hàng tháng tổ chức thực hiện định kỳ tối thiểu 4 lần/tháng (12*4)
B8: Thành viên 2 Quản lý dự án | C8: Đơn giá ngày công x Số ngày | D8: =D7 -> 289808.39 | E8: 48 | F8: =D8*E8 -> 13910803 | G8: - Kiểm tra, giám sát việc chuyển giao công nghệ của các nhà thầu - Dự kiến hàng tháng tổ chức thực hiện định kỳ tối thiểu 4 lần/tháng (12*4)
B9: Thành viên 3 Quản lý dự án | C9: Đơn giá ngày công x Số ngày | D9: =$G$35 -> 232368.89 | E9: 48 | F9: =D9*E9 -> 11153707 | G9: - Báo cáo các khiếm khuyết, các công việc trễ tiến độ thực hiện của các nhà thầu khác và yêu cầu các nhà thầu này có biện pháp khắc phục nhằm hoàn thành đúng tiến độ đã cam kết với Chủ đầu tư - Kiểm tra, báo cáo, tổng hợp các thay đổi hoặc phát sinh thiết kế trong quá trình thực hiện kế hoạch thuê dịch vụ - Dự kiến hàng tháng tổ chức thực hiện định kỳ tối thiểu 4 lần/tháng (12*4) | K9: =12*5 -> 60
B10: Thành viên 4 Quản lý dự án | C10: Đơn giá ngày công x Số ngày | D10: =$G$35 -> 232368.89 | E10: 48 | F10: =D10*E10 -> 11153707 | G10: -Theo dõi, đánh giá và báo cáo mức độ hoàn thành tiến độ của các nhà thầu - Dự kiến hàng tháng tổ chức thực hiện định kỳ tối thiểu 4 lần/tháng (12*4) | J10: 32
B11: Thành viên 5 Quản lý dự án | C11: Đơn giá ngày công x Số ngày | D11: =$G$35 -> 232368.89 | E11: 36 | F11: =D11*E11 -> 8365279.9 | G11: - Quản lý việc thực hiện tất cả các Hợp đồng triển khai của các nhà thầu khác đã ký kết với Chủ đầu tư
B12: Thành viên 6 Quản lý dự án | C12: Đơn giá ngày công x Số ngày | D12: =$G$35 -> 232368.89 | E12: 66 | F12: =D12*E12 -> 15336346 | G12: - Tổ chức nghiệm thu, bàn giao các công việc của gói thầu. Dự kiến hàng tháng tổ chức thực hiện định kỳ tối thiểu 4 lần/tháng (12*3) - Tổ chức nghiệm thu, thanh toán, quyết toán Hợp đồng đợt 1 và đợt 2 (30 ngày) | H12: 48
A13: 1.2 | B13: Phụ cấp kiêm nhiệm chủ đầu tư | C13: Trong quy mô dự án này không đề xuất kinh phí (phụ cấp kiêm nhiệm quản lý dự án theo quy định tại điểm b khoản 3 Điều 11 Thông tư số 72/2017/TT-BTC ngày 17/7/2017 đã hết hiệu lực). Chủ đầu tư tự phân bổ nhân sự thực hiện | F13: 0 | G13: Pc
A14: 2 | B14: Chi phí quản lý | C14: 55% x Ccg | F14: =F5*55% -> 40606855 | G14: Cql
A15: 3 | B15: Chi phí khác | F15: =F16+F17+F18+F19+F20+F21 -> 23436698 | G15: Ck
B16: - Chi phí vật liệu, văn phòng phẩm | C16: Thanh toán theo thực tế | F16: 4692000 | G16: Thanh toán 1 lần/tổng số hóa đơn
B17: - Chi phí chuyển phát nhanh | C17: Thanh toán theo thực tế | F17: 3690000 | G17: Thanh toán 1 lần/tổng số hóa đơn
B18: - Chi phí thanh toán tiền điện thoại | C18: Thanh toán theo thực tế | F18: 2568000 | G18: Thanh toán khoán trọn gói 6 nhân sự/250.000 đồng | I18: =250*6 -> 1500
B19: - Chi phí thanh toán tiền điện | C19: Thanh toán theo thực tế | F19: 3617485 | G19: Thanh toán 1 lần/tổng số hóa đơn
B20: - Chi phí thanh toán tiền nước Lavie | C20: Thanh toán theo thực tế | F20: 3896000 | G20: Thanh toán 1 lần/tổng số hóa đơn | J20: =F21+778 -> 4973990.5
B21: - Chi phí thanh toán tiền bảo trì, sửa chữa máy lạnh | C21: Thanh toán theo thực tế | F21: 4973212.5 | G21: Thanh toán 1 lần/tổng số hóa đơn
A22: 4 | B22: Thu nhập chịu thuế tính trước | C22: 6% (Ccg + Cql + Ck) | F22: =(F5+F14+F15)*6% -> 8272451.8 | G22: TN | L22: Chi phí QLHM đã trình
A23: 5 | B23: Thuế giá trị gia tăng | C23: 10% (Ccg+Cql+Ck+TN) | F23: =(F5+F14+F15+F22)*10% -> 14614665 | G23: VAT
B24: Tổng cộng | F24: =F5+F14+F15+F22+F23 -> 1.6076131e+08
B25: Làm tròn | F25: =ROUNDDOWN(F24,-3) -> 160761000
F28: =F5+F14+F15+F22 -> 1.4614665e+08
A30: Bậc | B30: Hệ số | C30: Lương cơ bản | D30: Người lao động đã qua học nghề (NLĐHN): 7% | E30: BHYT | F30: Tổng | G30: CP 1 ngày công | H30: CP 1 giờ công
E31: BHTN
E32: BHTN
E33: BHXH
A34: 1 | B34: 2.34 | C34: =$C$45*B34 -> 3486600 | D34: =7%*C34 -> 244062 | E34: =21.5%*C34 -> 749619 | F34: =SUM(C34:E34) -> 4480281 | G34: =F34/22 -> 203649.14 | H34: =G34/8 -> 25456.142
A35: 2 | B35: 2.67 | C35: =$C$45*B35 -> 3978300 | D35: =7%*C35 -> 278481 | E35: =21.5%*C35 -> 855334.5 | F35: =SUM(C35:E35) -> 5112115.5 | G35: =F35/22 -> 232368.89 | H35: =G35/8 -> 29046.111
A36: 3 | B36: 3 | C36: =$C$45*B36 -> 4470000 | D36: =7%*C36 -> 312900 | E36: =21.5%*C36 -> 961050 | F36: =SUM(C36:E36) -> 5743950 | G36: =F36/22 -> 261088.64 | H36: =G36/8 -> 32636.08
A37: 4 | B37: 3.33 | C37: =$C$45*B37 -> 4961700 | D37: =7%*C37 -> 347319 | E37: =21.5%*C37 -> 1066765.5 | F37: =SUM(C37:E37) -> 6375784.5 | G37: =F37/22 -> 289808.39 | H37: =G37/8 -> 36226.048
A38: 5 | B38: 3.66 | C38: =$C$45*B38 -> 5453400 | D38: =7%*C38 -> 381738 | E38: =21.5%*C38 -> 1172481 | F38: =SUM(C38:E38) -> 7007619 | G38: =F38/22 -> 318528.14 | H38: =G38/8 -> 39816.017
A39: 6 | B39: 3.99 | C39: =$C$45*B39 -> 5945100 | D39: =7%*C39 -> 416157 | E39: =21.5%*C39 -> 1278196.5 | F39: =SUM(C39:E39) -> 7639453.5 | G39: =F39/22 -> 347247.89 | H39: =G39/8 -> 43405.986
A40: 7 | B40: 4.32 | C40: =$C$45*B40 -> 6436800 | D40: =7%*C40 -> 450576 | E40: =21.5%*C40 -> 1383912 | F40: =SUM(C40:E40) -> 8271288 | G40: =F40/22 -> 375967.64 | H40: =G40/8 -> 46995.955
A41: 8 | B41: 4.65 | C41: =$C$45*B41 -> 6928500 | D41: =7%*C41 -> 484995 | E41: =21.5%*C41 -> 1489627.5 | F41: =SUM(C41:E41) -> 8903122.5 | G41: =F41/22 -> 404687.39 | H41: =G41/8 -> 50585.923
A42: 9 | B42: 4.98 | C42: =$C$45*B42 -> 7420200 | D42: =7%*C42 -> 519414 | E42: =21.5%*C42 -> 1595343 | F42: =SUM(C42:E42) -> 9534957 | G42: =F42/22 -> 433407.14 | H42: =G42/8 -> 54175.892
A45: Lương cơ bản | C45: 1490000
...

Sheet -Triển khai-
A1: BẢNG TÍNH CHI PHÍ TRIỂN KHAI
A3: I. Bảng dự toán giá trị công việc "Triển khai, hỗ trợ,quản trị, vận hành" (Căn cứ Phụ lục 05, Thông tư 04/2020/TT-BTTTT ngày 24/02/2020)
A5: STT | B5: CHI PHÍ | C5: DIỄN GIẢI | D5: ĐƠN GIÁ | E5: SỐ NGÀY | F5: GIÁ TRỊ | G5: GHI CHÚ
A6: 1 | B6: Chi phí chuyên gia trực tiếp | F6: =SUM(F8:F33) -> 92424209 | G6: Ccg
A7: A | B7: Chuẩn bị
A8: 1 | B8: Kế hoạch triển khai (Lập, review, thống nhất các kế hoạch khung, đào tạo, vận hành thử nghiệm, vận hành chính thức,…) | C8: Đơn giá ngày công x Số ngày | D8: 258168.18 | E8: 14 | F8: =D8*E8 -> 3614354.5
A9: 2 | B9: Kick off dự án giữa đội dự án đơn vị triển khai và đội dự án khách hàng | C9: Đơn giá ngày công x Số ngày | D9: 258168.18 | E9: 14 | F9: =D9*E9 -> 3614354.5
A10: B | B10: Cài đặt, thiết lập hệ thống
A11: 1 | B11: Kiểm tra hạ tầng (PC, Server, LAN, WAN,…) | C11: Đơn giá ngày công x Số ngày | D11: 258168.18 | E11: 6 | F11: =D11*E11 -> 1549009.1
A12: 2 | B12: Cài đặt hệ thống (server, PC,…) | C12: Đơn giá ngày công x Số ngày | D12: 258168.18 | E12: 11 | F12: =D12*E12 -> 2839850
A13: 3 | B13: Cấu hình hệ thống phần mềm (LDAP, người dùng, phân quyền, danh mục,...) | C13: Đơn giá ngày công x Số ngày | D13: 258168.18 | E13: 5 | F13: =D13*E13 -> 1290840.9
A14: C | B14: Vận hành
A15: 1 | B15: Hỗ trợ vận hành thử nghiệm các phân hệ | C15: Đơn giá ngày công x Số ngày | D15: 258168.18 | E15: 30 | F15: =D15*E15 -> 7745045.5
A16: 2 | B16: Thu thập ý kiến đóng góp trong quá trình vận hành của NSD (ý kiến đóng góp NSD được tổng hợp theo quy trình) | C16: Đơn giá ngày công x Số ngày | D16: 258168.18 | E16: 12 | F16: =D16*E16 -> 3098018.2
A17: 3 | B17: Tiến hành phân tích đánh giá (góp ý đơn vị trong quá trình đào tạo và vận hành) | C17: Đơn giá ngày công x Số ngày | D17: 258168.18 | E17: 12 | F17: =D17*E17 -> 3098018.2
A18: 4 | B18: Điều chỉnh tài liệu phân tích | C18: Đơn giá ngày công x Số ngày | D18: 258168.18 | E18: 12 | F18: =D18*E18 -> 3098018.2
A19: 5 | B19: Thống nhất kết quả phân tích, đánh giá, và xác định yêu cầu điều chỉnh trong quá trình đào tạo triển khai của đơn vị | C19: Đơn giá ngày công x Số ngày | D19: 258168.18 | E19: 12 | F19: =D19*E19 -> 3098018.2
A20: 6 | B20: Tiến hành thiết kế các hiệu chỉnh phần mềm theo kết quả thống nhất | C20: Đơn giá ngày công x Số ngày | D20: 258168.18 | E20: 12 | F20: =D20*E20 -> 3098018.2
A21: 7 | B21: Điều chỉnh tài liệu thiết kế | C21: Đơn giá ngày công x Số ngày | D21: 258168.18 | E21: 12 | F21: =D21*E21 -> 3098018.2
A22: 8 | B22: Thực hiện hiệu chỉnh phần mềm | C22: Đơn giá ngày công x Số ngày | D22: 258168.18 | E22: 25 | F22: =D22*E22 -> 6454204.5
A23: 9 | B23: Báo cáo kết quả điều chỉnh phần mềm, thống nhất nội dung phần mềm hoàn chỉnh trước khi tiến hành triển khai chính thức | C23: Đơn giá ngày công x Số ngày | D23: 258168.18 | E23: 5 | F23: =D23*E23 -> 1290840.9
A24: 10 | B24: Hỗ trợ vận hành thử nghiệm tại đơn vị sau khi hoàn thiện hiệu chỉnh phần mềm theo góp ý (hỗ trợ theo phòng ban, theo cá nhân phòng ban, theo đối tượng NSD) | C24: Đơn giá ngày công x Số ngày | D24: 258168.18 | E24: 24 | F24: =D24*E24 -> 6196036.4
A25: 11 | B25: Báo cáo kết quả vận hành thử nghiệm | C25: Đơn giá ngày công x Số ngày | D25: 258168.18 | E25: 10 | F25: =D25*E25 -> 2581681.8
A26: 12 | B26: Hỗ trợ vận hành chính thức tại đơn vị (hỗ trợ theo phòng ban, theo cá nhân phòng ban, theo đối tượng NSD) | C26: Đơn giá ngày công x Số ngày | D26: 258168.18 | E26: 10 | F26: =D26*E26 -> 2581681.8
A27: 13 | B27: Báo cáo kết quả vận hành chính thức | C27: Đơn giá ngày công x Số ngày | D27: 258168.18 | E27: 10 | F27: =D27*E27 -> 2581681.8
A28: D | B28: Chuyển giao công nghệ cho chủ đầu tư
A29: 1 | B29: Tiếp nhận Chuyển giao mã nguồn sản phẩm | C29: Đơn giá ngày công x Số ngày | D29: 258168.18 | E29: 50 | F29: =D29*E29 -> 12908409
A30: 2 | B30: Hướng dẫn cài đặt, cấu hình, hiệu chỉnh, quản trị phần mềm | C30: Đơn giá ngày công x Số ngày | D30: 258168.18 | E30: 50 | F30: =D30*E30 -> 12908409
A31: E | B31: Nghiệm thu dự án
A32: 1 | B32: Tiến hành thủ tục nghiệm thu dự án | C32: Đơn giá ngày công x Số ngày | D32: 258168.18 | E32: 10 | F32: =D32*E32 -> 2581681.8
A33: 2 | B33: Họp nghiệm thu dự án | C33: Đơn giá ngày công x Số ngày | D33: 258168.18 | E33: 12 | F33: =D33*E33 -> 3098018.2
A34: 2 | B34: Chi phí quản lý | C34: 65% x Ccg | F34: =F6*65% -> 60075736 | G34: Cql
A35: 3 | B35: Chi phí khác | F35: 0 | G35: Ck
A36: 4 | B36: Thu nhập chịu thuế tính trước | C36: 6% (Ccg + Cql + Ck) | F36: =(F6+F34+F35)*6% -> 9149996.7 | G36: TN
A37: 5 | B37: Thuế giá trị gia tăng | C37: 10% (Ccg+Cql+Ck+TN) | F37: =(F6+F34+F35+F36)*10% -> 16164994 | G37: VAT
B38: Tổng cộng | F38: =F6+F34+F35+F36+F37 -> 1.7781494e+08

Sheet  Đào tạo tại chỗ
A1: BẢNG TÍNH CHI PHÍ ĐÀO TẠO
A3: II. Bảng dự toán giá trị công việc "Đào tạo hướng dẫn sử dụng tại chỗ trong quá trình vận hành hệ thống tại các đơn vị, phòng ban" (Căn cứ Phụ lục 05, Thông tư 04/2020/TT-BTTTT ngày 24/02/2020)
A5: STT | B5: CHI PHÍ | C5: DIỄN GIẢI | D5: ĐƠN GIÁ | E5: SỐ NGÀY | F5: GIÁ TRỊ | G5: GHI CHÚ
A6: 1 | B6: Chi phí chuyên gia trực tiếp | F6: =SUM(F7:F9) -> #REF! | G6: Ccg
A7: 1.1 | B7: Hướng dẫn sử dụng tại chỗ | C7: Đơn giá ngày công x Số ngày | D7: =#REF! -> #REF! | E7: 14 | F7: =D7*E7 -> #REF!
A8: 1.2 | B8: Thu thập ý kiến đóng góp trong quá trình đào tạo hướng dẫn sử dụng tại chỗ của NSD (ý kiến đóng góp NSD được tổng hợp theo quy trình) | C8: Đơn giá ngày công x Số ngày | D8: =#REF! -> #REF! | E8: 5 | F8: =D8*E8 -> #REF!
A9: 1.3 | B9: Thiết lập cơ chế vận hành hệ thống toàn đơn vị (dự thảo, review, thống nhất, ban hành) | C9: Đơn giá ngày công x Số ngày | D9: =#REF! -> #REF! | E9: 5 | F9: =D9*E9 -> #REF!
A10: 2 | B10: Chi phí quản lý | C10: 55% x Ccg | F10: =F6*55% -> #REF! | G10: Cql
A11: 3 | B11: Chi phí khác | F11: 0 | G11: Ck
A12: 4 | B12: Thu nhập chịu thuế tính trước | C12: 6% (Ccg + Cql + Ck) | F12: =(F6+F10+F11)*6% -> #REF! | G12: TN
A13: 5 | B13: Thuế giá trị gia tăng | C13: 10% (Ccg+Cql+Ck+TN) | F13: =(F6+F10+F11+F12)*10% -> #REF! | G13: VAT
B14: Tổng cộng | F14: =F6+F10+F11+F12+F13 -> #REF!

Sheet Tong hop TMDT
A1: STT | B1: Nội dung chi phí | C1: Giá trị trước thuế (VND) | D1: Thuế GTGT (VND) | E1: Giá trị sau thuế (VND)
A2: 1 | B2: Chi phí thiết bị | C2: =TMĐT!D4 -> 5.2556069e+09 | D2: =TMĐT!E4 -> 0 | E2: =TMĐT!F4 -> 5.2556069e+09
A3: 2 | B3: Chi phí quản lý dự án | C3: =TMĐT!D8 -> 120000000 | D3: =TMĐT!E8 -> 9600000 | E3: =TMĐT!F8 -> 129600000
A4: 3 | B4: Chi phí tư vấn đầu tư | C4: =TMĐT!D10 -> 2.4074947e+08 | D4: =TMĐT!E10 -> 19259958 | E4: =TMĐT!F10 -> 2.6000943e+08
A5: 4 | B5: Chi phí khác | C5: =TMĐT!D15 -> 3.1049168e+08 | D5: =TMĐT!E15 -> 0 | E5: =TMĐT!F15 -> 3.1049168e+08
A6: 5 | B6: Chi phí dự phòng | C6: =TMĐT!D18 -> 44292012 | D6: =TMĐT!E18 -> 0 | E6: =TMĐT!F18 -> 44292012
B7: TỔNG DỰ TOÁN | C7: =SUM(C2:C6) -> 5.97114e+09 | D7: =SUM(D2:D6) -> 28859958 | E7: =SUM(E2:E6) -> 6000000000

Sheet TMĐT
C1: TMĐT | D1: 6000000000
A3: Stt | B3: Nội dung | C3: Diễn giải | D3: Chi phí trước thuế | E3: Thuế GTGT | F3: Chi phí sau thuế | G3: Căn cứ pháp lý
A4: I | B4: CHI PHÍ THIẾT BỊ (Gtb) | D4: =SUM(D5:D7) -> 5.2556069e+09 | E4: =SUM(E5:E6) -> 0 | F4: =SUM(F5:F7) -> 5.2556069e+09
A5: 1 | B5: Nâng cấp, triển khai phần mềm | C5: Theo báo giá thực tế | D5: 4.7319833e+09 | E5: 0 | F5: =E5+D5 -> 4.7319833e+09 | G5: điểm a, Khoản 4, Điều 16 của Nghị định số 45/2026/NĐ-CP | J5: =D5*8% -> 3.7855867e+08
A6: 2 | B6: Chi phí thiết lập trang thành phần | C6: Theo báo giá thực tế | D6: 3.5742354e+08 | E6: 0 | F6: =D6+E6 -> 3.5742354e+08 | G6: điểm a, Khoản 4, Điều 16 của Nghị định số 45/2026/NĐ-CP
A7: 3 | B7: Bản quyền nền tảng AI (phần mềm thương mại) | C7: Theo báo giá thực tế | D7: 166200000 | E7: 0 | F7: =D7+E7 -> 166200000 | G7: điểm a, Khoản 4, Điều 16 của Nghị định số 45/2026/NĐ-CP
A8: II | B8: CHI PHÍ QUẢN LÝ DỰ ÁN (Gql) | D8: =D9 -> 120000000 | E8: =E9 -> 9600000 | F8: =F9 -> 129600000
A9: 1 | B9: Chi phí quản lý dự án | C9: Theo báo giá thực tế | D9: 120000000 | E9: =D9*8% -> 9600000 | F9: =E9+D9 -> 129600000 | G9: điểm a, Khoản 5 Điều 16, Nghị định số 45/2026/NĐ-CP
A10: III | B10: CHI PHÍ TƯ VẤN ĐẦU TƯ (Gtv) | D10: =SUM(D11:D14) -> 2.4074947e+08 | E10: =SUM(E11:E14) -> 19259958 | F10: =SUM(F11:F14) -> 2.6000943e+08
A11: 1 | B11: Chi phí lập báo cáo kinh tế - kỹ thuật | C11: Đã ký hợp đồng tư vấn | D11: 1.7592593e+08 | E11: =D11*8% -> 14074074 | F11: =E11+D11 -> 1.9e+08 | G11: Hợp đồng số 1504/VPUBND-MP ngày 15 tháng 04 năm 2026
A12: 2 | B12: Chi phí thẩm tra báo cáo kinh tế - kỹ thuật | C12: Đã ký hợp đồng tư vấn | D12: 14823548 | E12: =D12*8% -> 1185883.8 | F12: =E12+D12 -> 16009432 | G12: Hợp đồng số 162026/VPUBND-TTCĐSKH ngày 01 tháng 06 năm 2026
A13: 3 | B13: Chi phí lập E-HSMT và đánh giá E-HSDT | C13: Theo báo giá thực tế | D13: 30000000 | E13: =D13*8% -> 2400000 | F13: =E13+D13 -> 32400000 | G13: điểm a, khoản 5 Điều 16, Nghị định số 45/2026/NĐ-CP
A14: 4 | B14: Chi phí thẩm định E-HSMT và kết quả lựa chọn nhà thầu | C14: Theo báo giá thực tế | D14: 20000000 | E14: =D14*8% -> 1600000 | F14: =E14+D14 -> 21600000 | G14: điểm a, khoản 5 Điều 16, Nghị định số 45/2026/NĐ-CP
A15: IV | B15: CHI PHÍ KHÁC CÓ LIÊN QUAN (Gk) | D15: =SUM(D16:D17) -> 3.1049168e+08 | E15: =SUM(E16:E17) -> 0 | F15: =SUM(F16:F17) -> 3.1049168e+08
A16: 1 | B16: Chi phí kiểm thử phần mềm | C16: Theo báo giá thực tế | D16: 288278390 | E16: 0 | F16: =E16+D16 -> 288278390 | G16: điểm a, Khoản 4, Điều 16 của Nghị định số 45/2026/NĐ-CP
A17: 2 | B17: Chi phí thẩm tra phê duyệt quyết toán | C17: Gtqt*0,53743%*70% | D17: =D21*0.53743%*70% -> 22213295 | F17: =E17+D17 -> 22213295 | G17: điểm c, d, e, Khoản 1, Điều 45 Nghị định 254/2025/NĐ-CP
A18: V | B18: CHI PHÍ DỰ PHÒNG (Gdp) | C18: <5% | D18: 44292012 | E18: 0 | F18: =D18 -> 44292012 | G18: Phụ lục 03, Thông tư 18/TT-BTTTT
B19: TỔNG CỘNG | C19: I + II + III + IV + V | D19: =SUM(D4,D8,D10,D15,D18) -> 5.97114e+09 | E19: =SUM(E4,E8,E10,E15,E18) -> 28859958 | F19: =SUM(F4,F8,F10,F15,F18) -> 6000000000
C21: GTQT | D21: =D16++D10+D8+D4 -> 5.9046347e+09 | E21: 6000000000
E22: =E21-F19 -> 0
E23: =D18/F19 -> 0.007382002

Sheet Phan bo von
A1: STT | B1: Nội dung | C1: Kế hoạch phân bổ vốn
C2: Năm 2026
A3: I | B3: CHI PHÍ THIẾT BỊ (Gtb) | C3: =SUM(C4:C4) -> 5.2556069e+09
A4: 1 | B4: Nâng cấp, triển khai phần mềm | C4: =TMĐT!F4 -> 5.2556069e+09
A5: II | B5: CHI PHÍ QUẢN LÝ DỰ ÁN (Gql) | C5: =C6 -> 129600000
A6: 1 | B6: Chi phí quản lý dự án và giám sát, đánh giá đầu tư | C6: =TMĐT!F9 -> 129600000
A7: III | B7: CHI PHÍ TƯ VẤN ĐẦU TƯ (Gtv) | C7: =SUM(C8:C11) -> 2.6000943e+08
A8: 1 | B8: Chi phí lập báo cáo kinh tế - kỹ thuật | C8: =TMĐT!F11 -> 1.9e+08
A9: 2 | B9: Chi phí thẩm tra báo cáo kinh tế - kỹ thuật | C9: =TMĐT!F12 -> 16009432
A10: 3 | B10: Chi phí lập E-HSMT và đánh giá E-HSDT | C10: =TMĐT!F13 -> 32400000
A11: 4 | B11: Chi phí thẩm định E-HSMT và kết quả lựa chọn nhà thầu | C11: =TMĐT!F14 -> 21600000
A12: IV | B12: CHI PHÍ KHÁC CÓ LIÊN QUAN (Gk) | C12: =SUM(C13:C15) -> #REF!
A13: 1 | B13: Chi phí kiểm thử phần mềm | C13: =TMĐT!F16 -> 288278390
A14: 2 | B14: Chi phí thuê dịch vụ AI | C14: =TMĐT!#REF! -> #REF!
A15: 3 | B15: Chi phí thẩm tra phê duyệt quyết toán | C15: =TMĐT!F17 -> 22213295
A16: V | B16: CHI PHÍ DỰ PHÒNG (Gdp) | C16: =TMĐT!F18 -> 44292012
B17: Tổng cộng | C17: =SUM(C3,C5,C7,C12,C16) -> #REF!

Sheet Chi phí AI
A1: DỰ TOÁN CHI PHÍ DỊCH VỤ AI (Phạm vi triển khai cho 01 trang thông tin điện tử tỉnh Khánh Hòa)
A2: TT | B2: Tính năng tích hợp | C2: Dịch vụ AI | D2: Đơn vị tính | E2: Thời gian sử dụng | F2: Số lượng | G2: Đơn giá (VND) | H2: Thành tiền / tháng (VND) | I2: Thành tiền/ năm (VND)
C3: Dịch vụ GenAI | H3: =SUM(H4:H9) -> 12400000 | I3: =H3*12 -> 148800000
A4: 1 | B4: Hỏi đáp ngôn ngữ tự nhiên; Tìm kiếm và tổng hợp thông tin | C4: Dịch vụ ChatBot GenAI | D4: request | E4: 1 tháng | F4: 20000 | G4: 400 | H4: =F4*G4 -> 8000000 | I4: =H4*12 -> 96000000
A5: 2 | B5: Hỏi đáp bằng giọng nói | C5: Dịch vụ VoiceBot GenAI | D5: request | F5: 2000 | G5: 700 | H5: =F5*G5 -> 1400000 | I5: =H5*12 -> 16800000
A6: 3 | B6: Kiểm tra chính tả và ngữ pháp | C6: Dịch vụ GenAI - Input tối đa 8000 từ (~10.000 token) | D6: request | F6: 5000 | G6: 600 | H6: =F6*G6 -> 3000000 | I6: =H6*12 -> 36000000
A7: 4 | B7: Tóm tắt nội dung bài viết
A8: 5 | B8: Kiểm tra từ ngữ nhạy cảm, nội dung tiêu cực
A9: 6 | B9: Gợi ý từ khóa và thẻ (tag) khi soạn thảo
C10: Dịch vụ AI xử lý giọng nói | H10: =SUM(H11:H12) -> 950000 | I10: =H10*12 -> 11400000
A11: 7 | B11: Chuyển đổi dữ liệu từ file ghi âm audio sang văn bản | C11: Speech to Text | D11: phút | E11: 1 tháng | F11: 500 | G11: 400 | H11: =F11*G11 -> 200000 | I11: =H11*12 -> 2400000
A12: 8 | B12: Hỗ trợ đọc bài viết | C12: Text to Speech | D12: ký tự | F12: 2500000 | G12: 0.3 | H12: =F12*G12 -> 750000 | I12: =H12*12 -> 9000000
C13: Dịch vụ AI xử lý văn bản | H13: =SUM(H14) -> 500000 | I13: =H13*12 -> 6000000
A14: 9 | B14: Chuyển đổi dữ liệu từ PDF sang văn bản; Chuyển đổi tài liệu thành tri thức | C14: Dịch vụ OCR | D14: trang | E14: 1 tháng | F14: 2500 | G14: 200 | H14: =F14*G14 -> 500000 | I14: =H14*12 -> 6000000
C15: TỔNG CỘNG | H15: =SUM(H3,H10,H13) -> 13850000 | I15: =H15*12 -> 166200000
B16: - Giá chưa bao gồm VAT 8%
