Workbook
Name \0: '[1]PNT-QUOT-#3'!#REF!
Name \0: '[1]PNT-QUOT-#3'!#REF!
Name \0: '[1]PNT-QUOT-#3'!#REF!
Name \d: #REF!
Name \d: #REF!
Name \d: #REF!
Name \e: #REF!
Name \e: #REF!
Name \e: #REF!
Name \f: #REF!
Name \f: #REF!
Name \f: #REF!
Name \g: #REF!
Name \g: #REF!
Name \g: #REF!
Name \h: #REF!
Name \h: #REF!
Name \h: #REF!
Name \i: #REF!
Name \i: #REF!
Name \i: #REF!
Name \j: #REF!
Name \j: #REF!
Name \j: #REF!
Name \k: #REF!
Name \k: #REF!
Name \k: #REF!
Name \l: #REF!
Name \l: #REF!
Name \l: #REF!
Name \m: #REF!
Name \m: #REF!
Name \m: #REF!
Name \n: #REF!
Name \n: #REF!
Name \n: #REF!
Name \o: #REF!
Name \o: #REF!
Name \o: #REF!
Name \z: '[1]COAT&WRAP-QIOT-#3'!#REF!
Name \z: '[1]COAT&WRAP-QIOT-#3'!#REF!
Name \z: '[1]COAT&WRAP-QIOT-#3'!#REF!
Name ____atn1: #REF!
Name ____atn1: #REF!
Name ____atn1: #REF!
Name ____atn10: #REF!
Name ____atn10: #REF!
Name ____atn10: #REF!
Name ____atn3: #REF!
Name ____atn3: #REF!
Name ____atn3: #REF!
Name ____atn4: #REF!
Name ____atn4: #REF!
Name ____atn4: #REF!
Name ____atn5: #REF!
Name ____atn5: #REF!
Name ____atn5: #REF!
Name ____atn6: #REF!
Name ____atn6: #REF!
Name ____atn6: #REF!

Sheet Khối lượng tài liệu
A1: STT | B1: Tên Phông | C1: Số mét | D1: Số hộp | E1: Số HS | F1: Thời gian TL | G1: Số trang | H1: Số trường hồ sơ | I1: Số trường văn bản
A2: 1 | B2: UBND tỉnh Bắc Ninh 1997 - 2007 | C2: 59 | D2: 516 | E2: 4091 | F2: 1997-2007 | G2: =C2*4000 -> 236000 | H2: =E2*9 -> 36819 | I2: =ROUND(G2/8*18,0) -> 531000
A3: 2 | B3: Đoàn ĐBQH - HĐND tỉnh | C3: 2 | D3: 16 | E3: 81 | F3: 1997-2007 | G3: =C3*4000 -> 8000 | H3: =E3*9 -> 729 | I3: =ROUND(G3/8*18,0) -> 18000
A4: 3 | B4: Sở Nội vụ | C4: 53.5 | D4: 428 | E4: 4370 | F4: 1993-2007 | G4: =C4*4000 -> 214000 | H4: =E4*9 -> 39330 | I4: =ROUND(G4/8*18,0) -> 481500
A5: 4 | B5: Sở Khoa học và Công nghệ | C5: 1 | D5: 7 | E5: 96 | F5: 1997-2003 | G5: =C5*4000 -> 4000 | H5: =E5*9 -> 864 | I5: =ROUND(G5/8*18,0) -> 9000
A6: 5 | B6: Sở Kế hoạch và Đầu tư | C6: 148 | D6: 1183 | E6: 4130 | F6: 1997-2005 | G6: =C6*4000 -> 592000 | H6: =E6*9 -> 37170 | I6: =ROUND(G6/8*18,0) -> 1332000
A7: 6 | B7: Sở Thể dục thể thao | C7: 1.5 | D7: 12 | E7: 87 | F7: 1997-2005 | G7: =C7*4000 -> 6000 | H7: =E7*9 -> 783 | I7: =ROUND(G7/8*18,0) -> 13500
A8: 7 | B8: Sở Văn hóa thông tin | C8: 2.1 | D8: 17 | E8: 126 | F8: 1997-2005 | G8: =C8*4000 -> 8400 | H8: =E8*9 -> 1134 | I8: =ROUND(G8/8*18,0) -> 18900
A9: 8 | B9: Sở Giao thông, Vận tải | C9: 21.6 | D9: 190 | E9: 1022 | F9: 1997-2004 | G9: =C9*4000 -> 86400 | H9: =E9*9 -> 9198 | I9: =ROUND(G9/8*18,0) -> 194400
A10: 9 | B10: Sở Tư pháp | C10: 21.1 | D10: 190 | E10: 4511 | F10: 1997-2006 | G10: 81520 | H10: 40599 | I10: 189900
A11: 10 | B11: Sở Công thương | C11: 16 | D11: 132 | E11: 1044 | F11: 1997-2010 | G11: =C11*4000 -> 64000 | H11: =E11*9 -> 9396 | I11: =ROUND(G11/8*18,0) -> 144000
A12: 11 | B12: Điện lực Bắc Ninh | C12: 0.2 | D12: 2 | E12: 18 | F12: 1997-2003 | G12: =C12*4000 -> 800 | H12: =E12*9 -> 162 | I12: =ROUND(G12/8*18,0) -> 1800
A13: 12 | B13: Viện Kiểm sát nhân dân tỉnh | C13: 0.2 | D13: 2 | E13: 10 | F13: 1997-2004 | G13: =C13*4000 -> 800 | H13: =E13*9 -> 90 | I13: =ROUND(G13/8*18,0) -> 1800
A14: 13 | B14: Sở Nông nghiệp và PTNT (Chi cục bảo vệ Thực vật) | C14: 1 | D14: 9 | E14: 45 | F14: 1997-2006 | G14: =C14*4000 -> 4000 | H14: =E14*9 -> 405 | I14: =ROUND(G14/8*18,0) -> 9000
A15: 14 | B15: Ngân hàng Nhà nước chi nhánh Bắc Ninh | C15: 3.5 | D15: 32 | E15: 318 | F15: 1999-2005 | G15: =C15*4000 -> 14000 | H15: =E15*9 -> 2862 | I15: =ROUND(G15/8*18,0) -> 31500
A16: 15 | B16: Bảo hiểm Xã hội tỉnh | C16: 5 | D16: 39 | E16: 216 | F16: 1997-2004 | G16: =C16*4000 -> 20000 | H16: =E16*9 -> 1944 | I16: =ROUND(G16/8*18,0) -> 45000
B17: Tổng cộng | C17: =SUM(C2:C16) -> 335.7 | D17: =SUM(D2:D16) -> 2775 | E17: =SUM(E2:E16) -> 20165 | G17: =SUM(G2:G16) -> 1339920 | H17: =SUM(H2:H16) -> 181485 | I17: =SUM(I2:I16) -> 3021300 | J17: =H17+I17 -> 3202785
A18: 16 | B18: Hội đồng Thi đua - Khen thưởng tỉnh | C18: 30.5 | D18: 284 | E18: 1454 | F18: 1947-2006 | G18: =C18*4000 -> 122000 | H18: =E18*9 -> 13086 | I18: =ROUND(G18/8*18,0) -> 274500
A19: 17 | B19: Cục Thuế tỉnh | C19: 2 | D19: 14 | E19: 133 | F19: 1997-2005 | G19: =C19*4000 -> 8000 | H19: =E19*9 -> 1197 | I19: =ROUND(G19/8*18,0) -> 18000
A20: 18 | B20: Hội Người mù | C20: 1 | D20: 7 | E20: 17 | F20: 1997-2003 | G20: =C20*4000 -> 4000 | H20: =E20*9 -> 153 | I20: =ROUND(G20/8*18,0) -> 9000
A21: 19 | B21: BCĐ Phòng chống tham nhũng | C21: 0.3 | D21: 3 | E21: 16 | F21: 2008-2013 | G21: =C21*4000 -> 1200 | H21: =E21*9 -> 144 | I21: =ROUND(G21/8*18,0) -> 2700
A22: 20 | B22: Ban Quản lý các KCN | C22: 146 | D22: 1165 | E22: 2915 | F22: 1998-2012 | G22: =C22*4000 -> 584000 | H22: =E22*9 -> 26235 | I22: =ROUND(G22/8*18,0) -> 1314000
A23: TỔNG CỘNG | C23: =SUM(C2:C20) -> 704.9 | D23: =SUM(D2:D20) -> 5855 | E23: =SUM(E2:E20) -> 41934 | G23: =SUM(G17:G22) -> 2059120 | H23: =SUM(H17:H22) -> 222300 | I23: =SUM(I17:I22) -> 4639500 | J23: =H23+I23 -> 4861800
H24: =G23*2850 -> 5868492000 | I24: =I23+H23 -> 4861800
H25: =(H23+I23)*350 -> 1701630000
G26: Phần mềm | H26: 800000000
G27: Thiết bị | H27: 850000000
H28: =SUM(H24:H27) -> 9220122000
E30: =0.405%*6000000000 -> 24300000
I32: =#REF! -> #REF!

Sheet TDT
A1: TỔNG MỨC ĐẦU TƯ DỰ ÁN | H1: Loại dự án | I1: Đề cương | J1: =IF(I1="Thiết kế 2 bước","1",IF(I1="Thiết kế 1 bước","2",IF(I1="Đề cương","3",IF(I1="Thuê dịch vụ vốn đầu tư","4","5")))) -> 3
G2: Đơn vị tính: đồng
A3: TT | B3: Nội dung chi phí | C3: Giá trị trước thuế VAT | D3: Thuế VAT | E3: Giá trị sau thuế VAT | F3: Giá trị sau VAT (LÀM TRÒN) | G3: Ghi chú
A4: I | B4: Chi phí thiết bị | C4: =SUBTOTAL(9,C5:C7) -> #REF! | D4: =SUBTOTAL(9,D5:D7) -> 0 | E4: =SUBTOTAL(9,E5:E7) -> #REF! | F4: =F5 -> #REF!
B5: Hạng mục phần mềm nội bộ, CSDL, phần cứng | C5: =SUBTOTAL(9,C6:C7) -> #REF! | D5: =SUBTOTAL(9,D6:D7) -> 0 | E5: =SUBTOTAL(9,E6:E7) -> #REF! | F5: =F6+F7+F8 -> #REF!
A6: 1 | B6: Chi phí xây dựng phần mềm nội bộ | C6: =#REF! -> #REF! | D6: 0 | E6: =C6+D6 -> #REF! | F6: =ROUND(E6,-3) -> #REF! | G6: Bảng tổng hợp chi phí xây dựng phần mềm nội bộ
A7: 2 | B7: Chi phí số hóa, tạo lập CSDL | D7: =C7*0.1 -> 0 | E7: =C7+D7 -> 0 | F7: =ROUND(E7,-3) -> 0
A8: 3 | B8: Chi phí hạ tầng phần cứng | D8: =C8*0.1 -> 0 | E8: =C8+D8 -> 0 | F8: =ROUND(E8,-3) -> 0
A9: II | B9: =IF(OR(J1="1",J1="2",J1="4"),"Chi phí tư vấn đầu tư","Chi phí tư vấn") -> Chi phí tư vấn | C9: =SUBTOTAL(9,C10:C13) -> #REF! | D9: =SUBTOTAL(9,D10:D13) -> #REF! | E9: =SUBTOTAL(9,E10:E14) -> #REF! | F9: =ROUND(E9,-3) -> #REF!
A10: 1 | B10: =IF(J1="1","Chi phí lập báo cáo nghiên cứu khả thi",IF(J1="2","Chi phí lập báo cáo kinh tế kỹ thuật",IF(J1="3","Chi phí lập đề cương dự toán chi tiết",IF(J1="4","Chi phí lập báo cáo nghiên cứu khả thi thuê dịch vụ CNTT","Chi phí lập kế hoạch thuê dịch vụ")))) -> Chi phí lập đề cương dự toán chi tiết | C10: ='Ty le tv'!B21 -> #REF! | D10: =C10/10 -> #REF! | E10: =D10+C10 -> #REF! | F10: =ROUND(E10,-3) -> #REF! | G10: QĐ 1688/QĐ-BTTTT
A11: 2 | B11: =IF(J1="1","Chi phí thẩm tra tính hiệu quả và tính khả thi của dự án",IF(J1="2","Chi phí thẩm tra báo cáo kinh tế kỹ thuật",IF(J1="3","Chi phí thẩm tra đề cương và dự toán chi tiết",IF(J1="4","Chi phí thẩm tra dự án thuê dịch vụ CNTT","Chi phí thẩm tra kế hoạch thuê dịch vụ CNTT")))) -> Chi phí thẩm tra đề cương và dự toán chi tiết | C11: ='Ty le tv'!B30 -> #REF! | D11: =C11/10 -> #REF! | E11: =D11+C11 -> #REF! | F11: =ROUND(E11,-3) -> #REF!
A12: 3 | B12: Chi phí lập hồ sơ mời thầu, đánh giá hồ sơ dự thầu | C12: ='Ty le tv'!B41 -> #REF! | D12: =C12/10 -> #REF! | E12: =D12+C12 -> #REF! | F12: =ROUND(E12,-3) -> #REF!
A13: 4 | B13: Chi phí thẩm định hồ sơ mời thầu, thẩm định kết quả lựa chọn nhà thầu | C13: ='Ty le tv'!B47+'Ty le tv'!B48 -> #REF! | D13: =C13*0.1 -> #REF! | E13: =C13+D13 -> #REF! | F13: =ROUND(E13,-3) -> #REF! | G13: NĐ 63/2014/NĐ-CP
A14: 5 | B14: Chi phí giám sát thi công phần mềm, CSDL | C14: ='Ty le tv'!B46 -> #REF! | D14: =C14*0.1 -> #REF! | E14: =C14+D14 -> #REF! | F14: =ROUND(E14,-3) -> #REF! | G14: QĐ 1688/QĐ-BTTTT
A15: III | B15: Chi phí khác | C15: =SUBTOTAL(9,C16:C17) -> #REF! | D15: =SUBTOTAL(9,D16:D17) -> #REF! | E15: =SUBTOTAL(9,E16:E17) -> #REF! | F15: =ROUND(E15,-3) -> #REF!
A16: 1 | B16: Thẩm định giá = 0,55% *Gtb | C16: =E4*0.55% -> #REF! | D16: =C16*0.1 -> #REF! | E16: =D16+C16 -> #REF! | F16: =ROUND(E16,-3) -> #REF! | G16: Báo giá của đơn vị thẩm định giá
A17: 2 | B17: Chi phí kiểm thử | C17: ='CP Kiểm thử'!D8 -> #REF! | D17: =C17*0.1 -> #REF! | E17: =D17+C17 -> #REF! | F17: =ROUND(E17,-3) -> #REF! | G17: Công văn số 3787/BTTTT-THH
B18: Tổng cộng (I+II+III) | C18: =SUBTOTAL(9,C4:C17) -> #REF! | D18: =SUBTOTAL(9,D4:D17) -> #REF! | E18: =SUBTOTAL(9,E4:E17) -> #REF! | F18: =F4+F9+F15 -> #REF!

Sheet Ty le tv
A1: Tổng giá trị đề nghị quyết toán | B1: Gxl+Gtb+Gqlda+Gtv+VAT | D1: =TDT!E4+TDT!E9 -> #REF!
A2: Giá trị gói thầu xây lắp | B2: Gxl+VAT | D2: 0
A3: Giá trị gói thầu xây lắp+thiết bị | B3: Gxl+Gtb+VAT | D3: =TDT!E4 -> #REF!
A4: Giá trị hạng mục xây lắp trước thuế | B4: Gxl | D4: 0
A5: Giá trị hạng mục hạ tầng kỹ thuật CNTT trước thuế | B5: Gpc | D5: 0
A6: Giá trị hạng mục phần mềm nội bộ, CSDL trước thuế | B6: Gpm+Gsh+Gđt | D6: =TDT!C5 -> #REF!
A7: Giá trị phần mềm nội bộ (+đào tạo) trước thuế | B7: Gpm+Gđt | D7: =TDT!C6 -> #REF!
A9: DIỄN GIẢI CÁCH TÍNH CHI PHÍ TƯ VẤN | K9: (Quyết định số 1688/QĐ-BTTTT ngày 11/10/2019)
B11: Giá trị trước thuế | C11: Hệ số | D11: Nt (giá trị cần tính %) | E11: Na (%) | F11: Nb (%) | G11: Ga | H11: Gb | I11: Gt | K11: LOẠI DỰ ÁN | L11: Chi phí xây lắp và thiết bị (Chưa có thuế GTGT) (tỷ đồng)
A12: Chi phí quản lý dự án | B12: =SUM(B13:B14)*C12 -> #REF! | C12: =C54*C55*C56 -> 1 | J12: 1 | K12: Định mức chi phí quản lý dự án | L12: 7000000000 | M12: 15000000000 | N12: 20000000000 | O12: 30000000000 | P12: 50000000000 | Q12: 100000000000 | R12: 150000000000 | S12: 200000000000 | T12: 500000000000 | U12: 1000000000000
A13: + Hạ tầng kỹ thuật | B13: =D13*I13/100 -> 0 | D13: =F13-(F13-E13)*(I13-H13)/(G13-H13) -> 2.644 | E13: =IF(G13=0,L13,HLOOKUP(G13,dinhmuc,$J13,TRUE)) -> 2.644 | F13: =IF(H13=0,M13,HLOOKUP(H13,dinhmuc,$J13,TRUE)) -> 2.644 | G13: =IF(I13<$L$12,0,INDEX(budget,MATCH(I13,budget,1))) -> 0 | H13: =IF(I13<$L$12,$L$12,INDEX(budget,MATCH(I13,budget,1)+1)) -> 7000000000 | I13: =$D$5 -> 0 | J13: 2 | K13: Dự án hạ tầng kỹ thuật công nghệ thông tin | L13: 2.644 | M13: 2.184 | N13: 1.913 | O13: 1.747 | P13: 1.324 | Q13: 1.045 | R13: 1.007 | S13: 0.975 | T13: 0.841 | U13: 0.696
A14: + Phần mềm, CSDL | B14: =D14*I14/100 -> #REF! | D14: =F14-(F14-E14)*(I14-H14)/(G14-H14) -> #REF! | E14: =IF(G14=0,L14,HLOOKUP(G14,dinhmuc,$J14,TRUE)) -> #REF! | F14: =IF(H14=0,M14,HLOOKUP(H14,dinhmuc,$J14,TRUE)) -> #REF! | G14: =IF(I14<$L$12,0,INDEX(budget,MATCH(I14,budget,1))) -> #REF! | H14: =IF(I14<$L$12,$L$12,INDEX(budget,MATCH(I14,budget,1)+1)) -> #REF! | I14: =$D$6 -> #REF! | J14: 3 | K14: Dự án phần mềm nội bộ, cơ sở dữ liệu | L14: 2.809 | M14: 2.133 | N14: 1.964 | O14: 1.782 | P14: 1.71 | Q14: 1.346 | R14: 1.287 | S14: 1.248
A15: Chi phí quản lý dự án trường hợp báo cáo kinh tế kỹ thuật, đề cương dự toán chi tiết | B15: =SUM(B16:B17)*C15 -> #REF! | C15: =C54*C55*C56 -> 1 | J15: 4 | K15: Định mức chi phí quản lý dự án trường hợp báo cáo kinh tế kỹ thuật, đề cương dự toán chi tiết
A16: + Hạ tầng kỹ thuật | B16: =D16*I16/100*C16 -> 0 | C16: 0.84 | D16: =F16-(F16-E16)*(I16-H16)/(G16-H16) -> 2.644 | E16: =IF(G16=0,L16,HLOOKUP(G16,dinhmuc,$J16,TRUE)) -> 2.644 | F16: =IF(H16=0,M16,HLOOKUP(H16,dinhmuc,$J16,TRUE)) -> 2.644 | G16: =IF(I16<$L$12,0,INDEX(budget,MATCH(I16,budget,1))) -> 0 | H16: =IF(I16<$L$12,$L$12,INDEX(budget,MATCH(I16,budget,1)+1)) -> 7000000000 | I16: =$D$5 -> 0 | J16: 5 | K16: Dự án hạ tầng kỹ thuật công nghệ thông tin | L16: 2.644 | M16: 2.184
A17: + Phần mềm, CSDL | B17: =D17*I17/100 -> #REF! | D17: =F17-(F17-E17)*(I17-H17)/(G17-H17) -> #REF! | E17: =IF(G17=0,L17,HLOOKUP(G17,dinhmuc,$J17,TRUE)) -> #REF! | F17: =IF(H17=0,M17,HLOOKUP(H17,dinhmuc,$J17,TRUE)) -> #REF! | G17: =IF(I17<$L$12,0,INDEX(budget,MATCH(I17,budget,1))) -> #REF! | H17: =IF(I17<$L$12,$L$12,INDEX(budget,MATCH(I17,budget,1)+1)) -> #REF! | I17: =$D$6 -> #REF! | J17: 6 | K17: Dự án phần mềm nội bộ, cơ sở dữ liệu | L17: 1.855 | M17: 1.532
A18: Chi phí lập báo cáo nghiên cứu khả thi | B18: =IF(SUM(B19:B20)*C18<10000000,10000000,SUM(B19:B20)*C18) -> #REF! | C18: =C59*C60*C61*C62 -> 1 | J18: 7 | K18: Định mức chi phí lập báo cáo nghiên cứu khả thi
A19: + Hạ tầng kỹ thuật | B19: =D19*I19/100 -> 0 | D19: =F19-(F19-E19)*(I19-H19)/(G19-H19) -> 0.992 | E19: =IF(G19=0,L19,HLOOKUP(G19,dinhmuc,$J19,TRUE)) -> 0.992 | F19: =IF(H19=0,M19,HLOOKUP(H19,dinhmuc,$J19,TRUE)) -> 0.992 | G19: =IF(I19<$L$12,0,INDEX(budget,MATCH(I19,budget,1))) -> 0 | H19: =IF(I19<$L$12,$L$12,INDEX(budget,MATCH(I19,budget,1)+1)) -> 7000000000 | I19: =$D$5 -> 0 | J19: 8 | K19: Dự án hạ tầng kỹ thuật công nghệ thông tin | L19: 0.992 | M19: 0.739 | N19: 0.652 | O19: 0.533 | P19: 0.42 | Q19: 0.31 | R19: 0.253 | S19: 0.205 | T19: 0.164 | U19: 0.144
A20: + Phần mềm, CSDL | B20: =D20*I20/100 -> #REF! | D20: =F20-(F20-E20)*(I20-H20)/(G20-H20) -> #REF! | E20: =IF(G20=0,L20,HLOOKUP(G20,dinhmuc,$J20,TRUE)) -> #REF! | F20: =IF(H20=0,M20,HLOOKUP(H20,dinhmuc,$J20,TRUE)) -> #REF! | G20: =IF(I20<$L$12,0,INDEX(budget,MATCH(I20,budget,1))) -> #REF! | H20: =IF(I20<$L$12,$L$12,INDEX(budget,MATCH(I20,budget,1)+1)) -> #REF! | I20: =$D$6 -> #REF! | J20: 9 | K20: Dự án phần mềm nội bộ, cơ sở dữ liệu | L20: 0.992 | M20: 0.906 | N20: 0.812 | O20: 0.763 | P20: 0.648 | Q20: 0.485 | R20: 0.437 | S20: 0.381
A21: Chi phí lập báo cáo kinh tế kỹ thuật, đề cương dự toán chi tiết | B21: =IF(SUM(B22:B23)*C21<10000000,10000000,SUM(B22:B23)*C21) -> #REF! | C21: =C59*C60*C61*C62 -> 1 | J21: 10 | K21: Định mức chi phí lập báo cáo kinh tế kỹ thuật
A22: + Hạ tầng kỹ thuật | B22: =D22*I22/100*1.65 -> 0 | C22: 1.65 | D22: =F22-(F22-E22)*(I22-H22)/(G22-H22) -> 0.992 | E22: =IF(G22=0,L22,HLOOKUP(G22,dinhmuc,$J22,TRUE)) -> 0.992 | F22: =IF(H22=0,M22,HLOOKUP(H22,dinhmuc,$J22,TRUE)) -> 0.992 | G22: =IF(I22<$L$12,0,INDEX(budget,MATCH(I22,budget,1))) -> 0 | H22: =IF(I22<$L$12,$L$12,INDEX(budget,MATCH(I22,budget,1)+1)) -> 7000000000 | I22: =$D$5 -> 0 | J22: 11 | K22: Dự án hạ tầng kỹ thuật công nghệ thông tin | L22: 0.992 | M22: 0.739
A23: + Phần mềm, CSDL | B23: =D23*I23/100 -> #REF! | D23: =F23-(F23-E23)*(I23-H23)/(G23-H23) -> #REF! | E23: =IF(G23=0,L23,HLOOKUP(G23,dinhmuc,$J23,TRUE)) -> #REF! | F23: =IF(H23=0,M23,HLOOKUP(H23,dinhmuc,$J23,TRUE)) -> #REF! | G23: =IF(I23<$L$12,0,INDEX(budget,MATCH(I23,budget,1))) -> #REF! | H23: =IF(I23<$L$12,$L$12,INDEX(budget,MATCH(I23,budget,1)+1)) -> #REF! | I23: =$D$6 -> #REF! | J23: 12 | K23: Dự án phần mềm nội bộ, cơ sở dữ liệu | L23: 3.64 | M23: 3.24
A24: Chi phí lập thiết kế thi công và tổng dự toán | B24: =SUM(B25:B26)*C24 -> #REF! | C24: =C65*C66*C67*C68*C69*C70*C71 -> 1 | J24: 13 | K24: Định mức chi phí lập thiết kế thi công và dự toán
A25: + Hạ tầng kỹ thuật | B25: =D25*I25/100 -> 0 | D25: =F25-(F25-E25)*(I25-H25)/(G25-H25) -> 1.499 | E25: =IF(G25=0,L25,HLOOKUP(G25,dinhmuc,$J25,TRUE)) -> 1.499 | F25: =IF(H25=0,M25,HLOOKUP(H25,dinhmuc,$J25,TRUE)) -> 1.499 | G25: =IF(I25<$L$12,0,INDEX(budget,MATCH(I25,budget,1))) -> 0 | H25: =IF(I25<$L$12,$L$12,INDEX(budget,MATCH(I25,budget,1)+1)) -> 7000000000 | I25: =$D$5 -> 0 | J25: 14 | K25: Dự án hạ tầng kỹ thuật công nghệ thông tin | L25: 1.499 | M25: 1.198 | N25: 0.991 | O25: 0.82 | P25: 0.646 | Q25: 0.522 | R25: 0.461 | S25: 0.411 | T25: 0.321 | U25: 0.24
A26: + Phần mềm, CSDL | B26: =D26*I26/100 -> #REF! | D26: =F26-(F26-E26)*(I26-H26)/(G26-H26) -> #REF! | E26: =IF(G26=0,L26,HLOOKUP(G26,dinhmuc,$J26,TRUE)) -> #REF! | F26: =IF(H26=0,M26,HLOOKUP(H26,dinhmuc,$J26,TRUE)) -> #REF! | G26: =IF(I26<$L$12,0,INDEX(budget,MATCH(I26,budget,1))) -> #REF! | H26: =IF(I26<$L$12,$L$12,INDEX(budget,MATCH(I26,budget,1)+1)) -> #REF! | I26: =$D$7 -> #REF! | J26: 15 | K26: Dự án phần mềm nội bộ, cơ sở dữ liệu | L26: 3.376 | M26: 3.155 | N26: 3.023 | O26: 2.847 | P26: 2.506 | Q26: 2.211 | R26: 2.091 | S26: 1.975
A27: Chi phí thẩm tra tính hiệu quả và tính khả thi của dự án đầu tư | B27: =IF(SUM(B28:B29)<2000000,2000000,SUM(B28:B29)) -> #REF! | J27: 16 | K27: Định mức chi phí thẩm tra tính hiệu quả và tính khả thi của dự án đầu tư
A28: + Hạ tầng kỹ thuật | B28: =D28*I28/100 -> 0 | D28: =F28-(F28-E28)*(I28-H28)/(G28-H28) -> 0.105 | E28: =IF(G28=0,L28,HLOOKUP(G28,dinhmuc,$J28,TRUE)) -> 0.105 | F28: =IF(H28=0,M28,HLOOKUP(H28,dinhmuc,$J28,TRUE)) -> 0.105 | G28: =IF(I28<$L$12,0,INDEX(budget,MATCH(I28,budget,1))) -> 0 | H28: =IF(I28<$L$12,$L$12,INDEX(budget,MATCH(I28,budget,1)+1)) -> 7000000000 | I28: =$D$5 -> 0 | J28: 17 | K28: Dự án hạ tầng kỹ thuật công nghệ thông tin | L28: 0.105 | M28: 0.074 | N28: 0.066 | O28: 0.059 | P28: 0.047 | Q28: 0.035 | R28: 0.03 | S28: 0.026 | T28: 0.0152 | U28: 0.0142
A29: + Phần mềm, CSDL | B29: =D29*I29/100 -> #REF! | D29: =F29-(F29-E29)*(I29-H29)/(G29-H29) -> #REF! | E29: =IF(G29=0,L29,HLOOKUP(G29,dinhmuc,$J29,TRUE)) -> #REF! | F29: =IF(H29=0,M29,HLOOKUP(H29,dinhmuc,$J29,TRUE)) -> #REF! | G29: =IF(I29<$L$12,0,INDEX(budget,MATCH(I29,budget,1))) -> #REF! | H29: =IF(I29<$L$12,$L$12,INDEX(budget,MATCH(I29,budget,1)+1)) -> #REF! | I29: =$D$6 -> #REF! | J29: 18 | K29: Dự án phần mềm nội bộ, cơ sở dữ liệu | L29: 0.126 | M29: 0.088 | N29: 0.085 | O29: 0.077 | P29: 0.065 | Q29: 0.051 | R29: 0.042 | S29: 0.036
A30: Chi phí thẩm tra báo cáo kinh tế kỹ thuật, đề cương dự toán chi tiết | B30: =IF(SUM(B31:B32)<2000000,2000000,SUM(B31:B32)) -> #REF! | J30: 19
A31: + Hạ tầng kỹ thuật | B31: =B34*70%+B37*70%+B28*40% -> 0 | J31: 20
A32: + Phần mềm, CSDL | B32: =B35*70%+B38*70%+B29*40% -> #REF! | J32: 21
A33: Chi phí thẩm tra thiết kế thi công | B33: =IF(SUM(B34:B35)<2000000,2000000,SUM(B34:B35)) -> #REF! | J33: 22 | K33: Định mức chi phí thẩm tra thiết kế thi công (chi phí tối thiểu không dưới 2 triệu)
A34: + Hạ tầng kỹ thuật | B34: =D34*I34/100 -> 0 | D34: =F34-(F34-E34)*(I34-H34)/(G34-H34) -> 0.087 | E34: =IF(G34=0,L34,HLOOKUP(G34,dinhmuc,$J34,TRUE)) -> 0.087 | F34: =IF(H34=0,M34,HLOOKUP(H34,dinhmuc,$J34,TRUE)) -> 0.087 | G34: =IF(I34<$L$12,0,INDEX(budget,MATCH(I34,budget,1))) -> 0 | H34: =IF(I34<$L$12,$L$12,INDEX(budget,MATCH(I34,budget,1)+1)) -> 7000000000 | I34: =$D$5 -> 0 | J34: 23 | K34: Dự án hạ tầng kỹ thuật công nghệ thông tin | L34: 0.087 | M34: 0.061 | N34: 0.054 | O34: 0.043 | P34: 0.03 | Q34: 0.022 | R34: 0.019 | S34: 0.016 | T34: 0.011 | U34: 0.008
A35: + Phần mềm, CSDL | B35: =D35*I35/100 -> #REF! | D35: =F35-(F35-E35)*(I35-H35)/(G35-H35) -> #REF! | E35: =IF(G35=0,L35,HLOOKUP(G35,dinhmuc,$J35,TRUE)) -> #REF! | F35: =IF(H35=0,M35,HLOOKUP(H35,dinhmuc,$J35,TRUE)) -> #REF! | G35: =IF(I35<$L$12,0,INDEX(budget,MATCH(I35,budget,1))) -> #REF! | H35: =IF(I35<$L$12,$L$12,INDEX(budget,MATCH(I35,budget,1)+1)) -> #REF! | I35: =$D$7 -> #REF! | J35: 24 | K35: Dự án phần mềm nội bộ, cơ sở dữ liệu | L35: 0.095 | M35: 0.066 | N35: 0.059 | O35: 0.047 | P35: 0.032 | Q35: 0.024 | R35: 0.02 | S35: 0.017
A36: Chi phí thẩm tra dự toán | B36: =IF(SUM(B37:B38)<2000000,2000000,SUM(B37:B38)) -> #REF! | J36: 25 | K36: Định mức chi phí thẩm tra dự toán (chi phí tối thiểu không dưới 2 triệu)
A37: + Hạ tầng kỹ thuật | B37: =D37*I37/100 -> 0 | D37: =F37-(F37-E37)*(I37-H37)/(G37-H37) -> 0.078 | E37: =IF(G37=0,L37,HLOOKUP(G37,dinhmuc,$J37,TRUE)) -> 0.078 | F37: =IF(H37=0,M37,HLOOKUP(H37,dinhmuc,$J37,TRUE)) -> 0.078 | G37: =IF(I37<$L$12,0,INDEX(budget,MATCH(I37,budget,1))) -> 0 | H37: =IF(I37<$L$12,$L$12,INDEX(budget,MATCH(I37,budget,1)+1)) -> 7000000000 | I37: =$D$5 -> 0 | J37: 26 | K37: Dự án hạ tầng kỹ thuật công nghệ thông tin | L37: 0.078 | M37: 0.05 | N37: 0.044 | O37: 0.034 | P37: 0.026 | Q37: 0.018 | R37: 0.015 | S37: 0.013 | T37: 0.01 | U37: 0.007
A38: + Phần mềm, CSDL | B38: =D38*I38/100 -> #REF! | D38: =F38-(F38-E38)*(I38-H38)/(G38-H38) -> #REF! | E38: =IF(G38=0,L38,HLOOKUP(G38,dinhmuc,$J38,TRUE)) -> #REF! | F38: =IF(H38=0,M38,HLOOKUP(H38,dinhmuc,$J38,TRUE)) -> #REF! | G38: =IF(I38<$L$12,0,INDEX(budget,MATCH(I38,budget,1))) -> #REF! | H38: =IF(I38<$L$12,$L$12,INDEX(budget,MATCH(I38,budget,1)+1)) -> #REF! | I38: =$D$7 -> #REF! | J38: 27 | K38: Dự án phần mềm nội bộ, cơ sở dữ liệu | L38: 0.085 | M38: 0.054 | N38: 0.048 | O38: 0.037 | P38: 0.028 | Q38: 0.019 | R38: 0.016 | S38: 0.014
A39: Chi phí lập hồ sơ mời thầu, đánh giá hồ sơ dự thầu xây lắp | B39: =IF(B40<5000000,5000000,B40) -> 5000000 | J39: 28 | K39: Định mức chi phí lập hồ sơ mời thầu, đánh giá hồ sơ dự thầu xây lắp
A40: + Hạ tầng kỹ thuật | B40: =D40*I40/100 -> 0 | D40: =F40-(F40-E40)*(I40-H40)/(G40-H40) -> 0.362 | E40: =IF(G40=0,L40,HLOOKUP(G40,dinhmuc,$J40,TRUE)) -> 0.362 | F40: =IF(H40=0,M40,HLOOKUP(H40,dinhmuc,$J40,TRUE)) -> 0.362 | G40: =IF(I40<$L$12,0,INDEX(budget,MATCH(I40,budget,1))) -> 0 | H40: =IF(I40<$L$12,$L$12,INDEX(budget,MATCH(I40,budget,1)+1)) -> 7000000000 | I40: =D4 -> 0 | J40: 29 | K40: Dự án hạ tầng kỹ thuật công nghệ thông tin | L40: 0.362 | M40: 0.339 | N40: 0.305 | O40: 0.255 | P40: 0.164 | Q40: 0.099 | R40: 0.079 | S40: 0.063 | T40: 0.047 | U40: 0.028
A41: Chi phí lập hồ sơ mời thầu, đánh giá hồ sơ dự thầu mua sắm thiết bị | B41: =IF(SUM(B42:B43)<5000000,5000000,SUM(B42:B43)) -> #REF! | J41: 30 | K41: Định mức chi phí lập hồ sơ mời thầu, đánh giá hồ sơ dự thầu mua sắm thiết bị
A42: + Hạ tầng kỹ thuật | B42: =D42*I42/100 -> 0 | D42: =F42-(F42-E42)*(I42-H42)/(G42-H42) -> 0.283 | E42: =IF(G42=0,L42,HLOOKUP(G42,dinhmuc,$J42,TRUE)) -> 0.283 | F42: =IF(H42=0,M42,HLOOKUP(H42,dinhmuc,$J42,TRUE)) -> 0.283 | G42: =IF(I42<$L$12,0,INDEX(budget,MATCH(I42,budget,1))) -> 0 | H42: =IF(I42<$L$12,$L$12,INDEX(budget,MATCH(I42,budget,1)+1)) -> 7000000000 | I42: =$D$5 -> 0 | J42: 31 | K42: Dự án hạ tầng kỹ thuật công nghệ thông tin | L42: 0.283 | M42: 0.228 | N42: 0.206 | O42: 0.172 | P42: 0.12 | Q42: 0.078 | R42: 0.072 | S42: 0.064 | T42: 0.053 | U42: 0.041
...

Sheet CP Kiểm thử
A1: CHI PHÍ KIỂM THỬ
A3: TT | B3: Khoản mục chi phí | C3: Cách tính | D3: Giá trị | E3: Ký hiệu
A4: 1 | B4: Giá trị kiểm thử | C4: G = E*H | D4: =#REF!*#REF! -> #REF! | E4: G
A5: 2 | B5: Chi phí chung | C5: G x 65% | D5: =D4*65% -> #REF! | E5: C
A6: 3 | B6: Thu nhập chịu thuế tính trước | C6: (G +C) x 6 % | D6: =(D4+D5)*6% -> #REF! | E6: TL
A7: 4 | B7: Chi phí kiểm thử | C7: G + C + TL | D7: =SUM(D4:D6) -> #REF! | E7: Gkt
B8: TỔNG CỘNG | C8: Gkt | D8: =ROUND(D7,-3) -> #REF!

Sheet UC Detail
A1: STT | B1: Tên Use-case | C1: Tên tác nhân chính | D1: Tên tác nhân phụ | E1: Mô tả trường sử dụng
A2: I | B2: Quản trị hệ thống
A3: =IF(AND(B3<>"",C3<>""),MAX($A$1:A2)+1,"") -> 1 | B3: Quản lý "Đối tượng khen thưởng" | C3: Quản trị hệ thống cấp cao
A4: =IF(AND(B4<>"",C4<>""),MAX($A1:A$5)+1,"") | E4: Quản trị hệ thống cấp cao có thể thực hiện tìm kiếm trong danh sách "Đối tượng khen thưởng" đã lưu trong hệ thống bằng cách nhập điều kiện và thực hiện tìm kiếm. Hệ thống trả kết quả tìm kiếm theo điều kiện đã nhập
A5: =IF(AND(B5<>"",C5<>""),MAX($A2:A$5)+1,"") | E5: Quản trị hệ thống cấp cao có thể thực hiện khoá "Đối tượng khen thưởng" bằng cách nhấn khoá. Hệ thống khoá và thông báo khoá thành công
A6: =IF(AND(B6<>"",C6<>""),MAX($A3:A$5)+1,"") | E6: Quản trị hệ thống cấp cao có thể thực hiện mở khoá "Đối tượng khen thưởng" bằng cách nhấn mở khoá. Hệ thống mở khoá và thông báo mở khoá thành công
A7: =IF(AND(B7<>"",C7<>""),MAX($A$5:A5)+1,"") | E7: Quản trị hệ thống cấp cao có thể thực hiện xuất một bản ghi hoặc nhiều bản ghi dữ liệu "Đối tượng khen thưởng" ra file excel. Hệ thống thực hiện kiểm tra và xuất dữ liệu theo điều kiện thực hiện ra file excel.
E8: Quản trị hệ thống cấp cao có thể thực hiện xem phân trang thông tin "Đối tượng khen thưởng" bằng cách nhấn vào phân trang. Hệ thống xử lý chuyển đến trang đã chọn
E9: Quản trị hệ thống cấp cao có thể thực hiện thêm mới đối tượng khen thưởng trong "Đối tượng khen thưởng". Hệ thống kiểm tra và lưu thông tin.
E10: Quản trị hệ thống cấp cao có thể thực hiện sửa thông tin đối tượng khen thưởng trong "Đối tượng khen thưởng". Hệ thống kiểm tra và lưu thông tin.
E11: Quản trị hệ thống cấp cao có thể thực hiện xoá đối tượng khen thưởng trong "Đối tượng khen thưởng". Hệ thống kiểm tra và xoá đối tượng khen thưởng.
A12: =IF(AND(B12<>"",C12<>""),MAX($A$1:A10)+1,"") -> 2 | B12: Quản lý cơ quan, đơn vị | C12: Quản trị hệ thống cấp cao
A13: =IF(AND(B13<>"",C13<>""),MAX($A$1:A11)+1,"") | E13: Quản trị hệ thống cấp cao có thể thực hiện tìm kiếm trong danh sách cơ quan, đơn vị đã lưu trong hệ thống bằng cách nhập điều kiện và thực hiện tìm kiếm. Hệ thống trả kết quả tìm kiếm theo điều kiện đã nhập
A14: =IF(AND(B14<>"",C14<>""),MAX($A$1:A12)+1,"") | E14: Quản trị hệ thống cấp cao có thể thực hiện khoá cơ quan, đơn vị bằng cách nhấn khoá. Hệ thống khoá và thông báo khoá thành công
A15: =IF(AND(B15<>"",C15<>""),MAX($A$1:A13)+1,"") | E15: Quản trị hệ thống cấp cao có thể thực hiện mở khoá cơ quan, đơn vị bằng cách nhấn mở khoá. Hệ thống mở khoá và thông báo mở khoá thành công
A16: =IF(AND(B16<>"",C16<>""),MAX($A$1:A14)+1,"") | E16: Quản trị hệ thống cấp cao có thể thực hiện xuất một bản ghi hoặc nhiều bản ghi dữ liệu cơ quan, đơn vị ra file excel. Hệ thống thực hiện kiểm tra và xuất dữ liệu theo điều kiện thực hiện ra file excel
A17: =IF(AND(B17<>"",C17<>""),MAX($A$1:A15)+1,"") | E17: Quản trị hệ thống cấp cao có thể thực hiện xem phân trang thông tin cơ quan, đơn vị bằng cách nhấn vào phân trang. Hệ thống xử lý chuyển đến trang đã chọn
A18: =IF(AND(B18<>"",C18<>""),MAX($A$1:A16)+1,"") | E18: Quản trị hệ thống cấp cao có thể thực hiện thêm mới cơ quan, đơn vị. Hệ thống kiểm tra và lưu thông tin.
A19: =IF(AND(B19<>"",C19<>""),MAX($A$1:A17)+1,"") | E19: Quản trị hệ thống cấp cao có thể thực hiện sửa thông tin cơ quan, đơn vị. Hệ thống kiểm tra và lưu thông tin.
A20: =IF(AND(B20<>"",C20<>""),MAX($A$1:A18)+1,"") | E20: Quản trị hệ thống cấp cao có thể thực hiện xoá cơ quan, đơn vị. Hệ thống kiểm tra và xoá cơ quan, đơn vị.
A21: =IF(AND(B21<>"",C21<>""),MAX($A$1:A19)+1,"") -> 3 | B21: Quản lý "Tính chất tặng" | C21: Quản trị hệ thống cấp cao
A22: =IF(AND(B22<>"",C22<>""),MAX($A$1:A20)+1,"") | E22: Quản trị hệ thống cấp cao có thể thực hiện tìm kiếm trong danh sách "Tính chất tặng" đã lưu trong hệ thống bằng cách nhập điều kiện và thực hiện tìm kiếm. Hệ thống trả kết quả tìm kiếm theo điều kiện đã nhập
A23: =IF(AND(B23<>"",C23<>""),MAX($A$1:A21)+1,"") | E23: Quản trị hệ thống cấp cao có thể thực hiện khoá "Tính chất tặng" bằng cách nhấn khoá. Hệ thống khoá và thông báo khoá thành công
A24: =IF(AND(B24<>"",C24<>""),MAX($A$1:A22)+1,"") | E24: Quản trị hệ thống cấp cao có thể thực hiện mở khoá "Tính chất tặng" bằng cách nhấn mở khoá. Hệ thống mở khoá và thông báo mở khoá thành công
A25: =IF(AND(B25<>"",C25<>""),MAX($A$1:A23)+1,"") | E25: Quản trị hệ thống cấp cao có thể thực hiện xuất một bản ghi hoặc nhiều bản ghi dữ liệu "Tính chất tặng" ra file excel. Hệ thống thực hiện kiểm tra và xuất dữ liệu theo điều kiện thực hiện ra file excel
A26: =IF(AND(B26<>"",C26<>""),MAX($A$1:A24)+1,"") | E26: Quản trị hệ thống cấp cao có thể thực hiện xem phân trang "Tính chất tặng" bằng cách nhấn vào phân trang. Hệ thống xử lý chuyển đến trang đã chọn
A27: =IF(AND(B27<>"",C27<>""),MAX($A$1:A25)+1,"") | E27: Quản trị hệ thống cấp cao có thể thực hiện thêm mới tính chất tặng trong "Tính chất tặng". Hệ thống kiểm tra và lưu thông tin.
A28: =IF(AND(B28<>"",C28<>""),MAX($A$1:A26)+1,"") | E28: Quản trị hệ thống cấp cao có thể thực hiện sửa thông tin tính chất tặng trong "Tính chất tặng". Hệ thống kiểm tra và lưu thông tin.
A29: =IF(AND(B29<>"",C29<>""),MAX($A$1:A27)+1,"") | E29: Quản trị hệ thống cấp cao có thể thực hiện xoá tính chất tặng trong "Tính chất tặng". Hệ thống kiểm tra và xoá Tính chất tặng.
A30: =IF(AND(B30<>"",C30<>""),MAX($A$1:A28)+1,"") -> 4 | B30: Quản lý "Hình thức khen thưởng" | C30: Quản trị hệ thống cấp cao
A31: =IF(AND(B31<>"",C31<>""),MAX($A$1:A29)+1,"") | E31: Quản trị hệ thống cấp cao có thể thực hiện tìm kiếm trong danh sách "Hình thức khen thưởng" đã lưu trong hệ thống bằng cách nhập điều kiện và thực hiện tìm kiếm. Hệ thống trả kết quả tìm kiếm theo điều kiện đã nhập
A32: =IF(AND(B32<>"",C32<>""),MAX($A$1:A30)+1,"") | E32: Quản trị hệ thống cấp cao có thể thực hiện khoá "Hình thức khen thưởng" bằng cách nhấn khoá. Hệ thống khoá và thông báo khoá thành công
A33: =IF(AND(B33<>"",C33<>""),MAX($A$1:A31)+1,"") | E33: Quản trị hệ thống cấp cao có thể thực hiện mở khoá "Hình thức khen thưởng" bằng cách nhấn mở khoá. Hệ thống mở khoá và thông báo mở khoá thành công
A34: =IF(AND(B34<>"",C34<>""),MAX($A$1:A32)+1,"") | E34: Quản trị hệ thống cấp cao có thể thực hiện xuất một bản ghi hoặc nhiều bản ghi dữ liệu "Hình thức khen thưởng" ra file excel. Hệ thống thực hiện kiểm tra và xuất dữ liệu theo điều kiện thực hiện ra file excel
A35: =IF(AND(B35<>"",C35<>""),MAX($A$1:A33)+1,"") | E35: Quản trị hệ thống có thể thực hiện xem phân trang "Hình thức khen thưởng" bằng cách nhấn vào phân trang. Hệ thống xử lý chuyển đến trang đã chọn
A36: =IF(AND(B36<>"",C36<>""),MAX($A$1:A35)+1,"") -> 5 | B36: Quản lý "Phương thức khen thưởng" | C36: Quản trị hệ thống cấp cao
A37: =IF(AND(B37<>"",C37<>""),MAX($A$1:A35)+1,"") | E37: Quản trị hệ thống cấp cao có thể thực hiện tìm kiếm trong danh sách "Phương thức khen thưởng" đã lưu trong hệ thống bằng cách nhập điều kiện và thực hiện tìm kiếm. Hệ thống trả kết quả tìm kiếm theo điều kiện đã nhập
A38: =IF(AND(B38<>"",C38<>""),MAX($A$1:A36)+1,"") | E38: Quản trị hệ thống cấp cao có thể thực hiện khoá "Phương thức khen thưởng" bằng cách nhấn khoá. Hệ thống khoá và thông báo khoá thành công
A39: =IF(AND(B39<>"",C39<>""),MAX($A$1:A37)+1,"") | E39: Quản trị hệ thống cấp cao có thể thực hiện mở khoá "Phương thức khen thưởng" bằng cách nhấn mở khoá. Hệ thống mở khoá và thông báo mở khoá thành công
A40: =IF(AND(B40<>"",C40<>""),MAX($A$1:A38)+1,"") | E40: Quản trị hệ thống cấp cao có thể thực hiện xuất một bản ghi hoặc nhiều bản ghi dữ liệu "Phương thức khen thưởng" ra file excel. Hệ thống thực hiện kiểm tra và xuất dữ liệu theo điều kiện thực hiện ra file excel
...

Sheet CPSH
A1: KHÁI TOÁN CHI PHÍ SỐ HOÁ
A2: STT | B2: Tên công việc/ Thành phần hao phí | C2: Đơn vị | D2: Khối lượng | E2: Đơn giá | F2: Thành tiền (đ) | G2: VBPL | H2: Ghi chú | I2: Dung lượng lưu trữ
A3: I | B3: THU THẬP BẢN GỐC | F3: =F4 -> 1.8060154e+08
A4: 1 | B4: Quét tài liệu | C4: Trang | F4: =F5 -> 1.8060154e+08
B5: - Khổ giấy A4 | C5: Trang A4 | D5: 86709.415 | E5: 2082.8366 | F5: =D5*E5 -> 1.8060154e+08
A6: II | B6: NHẬP DỮ LIỆU | F6: =SUM(F7:F8) -> 95821035
A7: 1 | B7: Xây dựng tài liệu hướng dẫn nhập dữ liệu | C7: Tài liệu | D7: 1 | E7: 3035244.6 | F7: =D7*E7 -> 3035244.6 | G7: QĐ 1595.2011
A8: 2 | B8: Nhập dữ liệu | C8: Trường | D8: 247428.77 | E8: 375 | F8: =D8*E8 -> 92785790 | G8: 194/2012/TT-BTC
B9: TỔNG (I+II): | F9: =F3+F6 -> 2.7642258e+08
B10: TỔNG (I+II) LÀM TRÒN | F10: =ROUND(F9,-3) -> 276423000
B11: THUẾ VAT (10%): | F11: =F10*10% -> 27642300
B12: TỔNG CỘNG: | F12: =F10+F11 -> 304065300

Sheet Khối lượng dự toán
A1: Mô tả | B1: Thời hạn bảo quản | C1: Số lượng hộp | D1: Số văn bản trung bình/hồ sơ | E1: Số trang trung bình/văn bản | F1: Số Hồ sơ | G1: File (văn bản) | H1: Trang | I1: Trường tin
A2: Đã được cấp bằng | B2: Vĩnh viễn | D2: 7.0645161 | E2: 6.9032258 | F2: 1778 | G2: =F2*D2 -> 12560.71 | H2: =G2*E2 -> 86709.415 | I2: =F2*12+G2*18 -> 247428.77
A3: Không được cấp bằng | B3: 5 năm | D3: 7.0645161 | E3: 6.9032258 | F3: 0 | G3: 0 | H3: =G3*E3 -> 0 | I3: =F3*12+G3*18 -> 0
F4: =F2+F3 -> 1778 | G4: =G2+G3 -> 12560.71 | H4: =H2+H3 -> 86709.415 | I4: =I2+I3 -> 247428.77

Sheet Báo cáo khảo sát
A1: SỐ LIỆU KHẢO SÁT
A2: TT | B2: Địa điểm khảo sát | C2: Loại hồ sơ | D2: Mô tả | E2: Thời hạn bảo quản | F2: Số lượng hộp | G2: Số văn bản trung bình/hồ sơ | H2: Số trang trung bình/văn bản | I2: Số Hồ sơ | J2: File (văn bản) | K2: Trang | L2: Trường tin
I3: 1 | J3: 2 | K3: 3 | L3: 4
A4: 1 | B4: Cục Sở Hữu Trí tuệ | C4: Hồ sơ hành chính | D4: Công văn, quyết định, hồ sơ công việc | E4: Vĩnh viễn | G4: 8.5384615 | H4: 6.5714286 | I4: 0 | J4: =I4*G4 -> 0 | K4: =J4*H4 -> 0 | L4: =I4*12+J4*18 -> 0
C5: Hồ sơ sang chế và giải pháp hữu ích | D5: Đã được cấp bằng | E5: Vĩnh viễn | G5: 7.0645161 | H5: 6.9032258 | I5: 32000 | J5: =I5*G5 -> 226064.52 | K5: =J5*H5 -> 1560574.4 | L5: =I5*12+J5*18 -> 4453161.3
D6: Không được cấp bằng | E6: 5 năm | I6: 35000
C7: Hồ sơ kiểu dáng công nghiệp | D7: Đã được cấp bằng | E7: Vĩnh viễn | G7: 43.52381 | H7: 1.7619048 | I7: 30000 | J7: =I7*G7 -> 1305714.3 | K7: =J7*H7 -> 2300544.2 | L7: =I7*12+J7*18 -> 23862857
D8: Không được cấp bằng | E8: 5 năm | I8: 35000
C9: Hồ sơ nhãn hiệu | D9: Đã được cấp bằng | E9: Vĩnh viễn | I9: 500000
D10: Không được cấp bằng | E10: 5 năm | I10: 300000
C11: Hồ sơ chỉ dẫn địa lý | D11: Đã được cấp bằng | E11: Vĩnh viễn
D12: Không được cấp bằng | E12: 5 năm
C13: Hồ sơ thiết kế bố trí mạch tích hợp bán dẫn | E13: Vĩnh viễn | I13: 100
A14: Tổng Cộng | I14: =SUM(I4:I13) -> 932100 | J14: =SUM(J4:J7) -> 1531778.8 | K14: =SUM(K4:K7) -> 3861118.6 | L14: =SUM(L4:L7) -> 28316018

Sheet Hạ tầng
B1: CHI PHÍ PHỤC VỤ CÔNG TÁC THUÊ HẠ TẦNG MÁY CHỦ
A3: STT | B3: Danh mục đầu tư | C3: Ghi chú | D3: Đơn vị tính | E3: Số lượng | F3: Đơn giá | G3: Thành tiền chưa bao gồm thuế VAT | H3: Thuế VAT | I3: Tổng tiền đã bao gồm VAT
B4: Hạ tầng thiết bị | G4: =SUM(G5) -> 220800000 | H4: =SUM(H5) -> 22080000 | I4: =SUM(I5) -> 242880000
A5: 1 | B5: Chi phí 02 server | C5: 16 CPU, 64 GB Ram, 500GB HDD | D5: Tháng | E5: 12 | F5: =9200000*2 -> 18400000 | G5: =F5*E5 -> 220800000 | H5: =G5*10% -> 22080000 | I5: =G5+H5 -> 242880000

Sheet Ty le tv (so hoa)
A2: Gt = Gxl + Gtb + Gqlda + Gtv
A3: Gt = Gpc | C3: 0
A4: Gt= Gpm | C4: =#REF! -> #REF!
A6: DIỄN GIẢI CÁCH TÍNH CHI PHÍ TƯ VẤN | J6: (Quyết định số 2378/QĐ-BTTTT ngày 30/12/2016)
B8: Giá trị trước thuế | C8: Nt (giá trị cần tính %) | D8: Na (%) | E8: Nb (%) | F8: Ga | G8: Gb | H8: Gt | J8: LOẠI DỰ ÁN | K8: Chi phí xây lắp và thiết bị (Chưa có thuế GTGT) (tỷ đồng)
A9: Chi phí quản lý dự án | B9: =SUM(B10:B11) -> #REF! | I9: 1 | J9: Bảng số 1: Định mức chi phí quản lý dự án | K9: 7000000000 | L9: 15000000000 | M9: 20000000000 | N9: 30000000000 | O9: 50000000000 | P9: 100000000000 | Q9: 150000000000 | R9: 200000000000 | S9: 500000000000 | T9: 1000000000000
A10: + Hạ tầng kỹ thuật | B10: =C10*H10/100 -> 0 | C10: =E10-(E10-D10)*(H10-G10)/(F10-G10) -> 2.644 | D10: =IF(F10=0,K10,HLOOKUP(F10,dinhmuc,$I10,TRUE)) -> 2.644 | E10: =IF(G10=0,L10,HLOOKUP(G10,dinhmuc,$I10,TRUE)) -> 2.644 | F10: =IF(H10<$K$9,0,INDEX(budget,MATCH(H10,budget,1))) -> 0 | G10: =IF(H10<$K$9,$K$9,INDEX(budget,MATCH(H10,budget,1)+1)) -> 7000000000 | H10: =C3 -> 0 | I10: 2 | J10: Dự án hạ tầng kỹ thuật công nghệ thông tin | K10: 2.644 | L10: 2.184 | M10: 1.913 | N10: 1.747 | O10: 1.324 | P10: 1.045 | Q10: 1.007 | R10: 0.975 | S10: 0.841 | T10: 0.696
A11: + Phần mềm, CSDL | B11: =C11*H11/100 -> #REF! | C11: =E11-(E11-D11)*(H11-G11)/(F11-G11) -> #REF! | D11: =IF(F11=0,K11,HLOOKUP(F11,dinhmuc,$I11,TRUE)) -> #REF! | E11: =IF(G11=0,L11,HLOOKUP(G11,dinhmuc,$I11,TRUE)) -> #REF! | F11: =IF(H11<$K$9,0,INDEX(budget,MATCH(H11,budget,1))) -> #REF! | G11: =IF(H11<$K$9,$K$9,INDEX(budget,MATCH(H11,budget,1)+1)) -> #REF! | H11: =C4 -> #REF! | I11: 3 | J11: Dự án phần mềm nội bộ, cơ sở dữ liệu | K11: 2.809 | L11: 2.133 | M11: 1.964 | N11: 1.782 | O11: 1.71 | P11: 1.346 | Q11: 1.287 | R11: 1.248
A12: Chi phí lập dự án đầu tư | B12: =SUM(B13:B14) -> #REF! | I12: 4 | J12: Bảng số 2: Định mức chi phí lập dự án đầu tư
A13: + Hạ tầng kỹ thuật | B13: =C13*H13/100 -> 0 | C13: =E13-(E13-D13)*(H13-G13)/(F13-G13) -> 0.992 | D13: =IF(F13=0,K13,HLOOKUP(F13,dinhmuc,$I13,TRUE)) -> 0.992 | E13: =IF(G13=0,L13,HLOOKUP(G13,dinhmuc,$I13,TRUE)) -> 2.644 | F13: =IF(H13<$K$9,0,INDEX(budget,MATCH(H13,budget,1))) -> 0 | G13: =IF(H13<$K$9,$K$9,INDEX(budget,MATCH(H13,budget,1)+1)) -> 7000000000 | H13: =C3 -> 0 | I13: 5 | J13: Dự án hạ tầng kỹ thuật công nghệ thông tin | K13: 0.992 | L13: 0.739 | M13: 0.652 | N13: 0.533 | O13: 0.42 | P13: 0.31 | Q13: 0.253 | R13: 0.205 | S13: 0.164 | T13: 0.144
A14: + Phần mềm, CSDL | B14: =C14*H14/100 -> #REF! | C14: =E14-(E14-D14)*(H14-G14)/(F14-G14) -> #REF! | D14: =IF(F14=0,K14,HLOOKUP(F14,dinhmuc,$I14,TRUE)) -> #REF! | E14: =IF(G14=0,L14,HLOOKUP(G14,dinhmuc,$I14,TRUE)) -> #REF! | F14: =IF(H14<$K$9,0,INDEX(budget,MATCH(H14,budget,1))) -> #REF! | G14: =IF(H14<$K$9,$K$9,INDEX(budget,MATCH(H14,budget,1)+1)) -> #REF! | H14: =C4 -> #REF! | I14: 6 | J14: Dự án phần mềm nội bộ, cơ sở dữ liệu | K14: 0.992 | L14: 0.906 | M14: 0.812 | N14: 0.763 | O14: 0.648 | P14: 0.485 | Q14: 0.437 | R14: 0.381
A15: Chi phí lập thiết kế thi công và dự toán | B15: =SUM(B16:B17) -> #REF! | I15: 7 | J15: Bảng số 3: Định mức chi phí lập thiết kế thi công và dự toán
A16: + Hạ tầng kỹ thuật | B16: 0 | C16: =E16-(E16-D16)*(H16-G16)/(F16-G16) -> 1.499 | D16: =IF(F16=0,K16,HLOOKUP(F16,dinhmuc,$I16,TRUE)) -> 1.499 | E16: =IF(G16=0,L16,HLOOKUP(G16,dinhmuc,$I16,TRUE)) -> 0.992 | F16: =IF(H16<$K$9,0,INDEX(budget,MATCH(H16,budget,1))) -> 0 | G16: =IF(H16<$K$9,$K$9,INDEX(budget,MATCH(H16,budget,1)+1)) -> 7000000000 | H16: =C3 -> 0 | I16: 8 | J16: Dự án hạ tầng kỹ thuật công nghệ thông tin | K16: 1.499 | L16: 1.198 | M16: 0.991 | N16: 0.82 | O16: 0.646 | P16: 0.522 | Q16: 0.461 | R16: 0.411 | S16: 0.321 | T16: 0.24
A17: + Phần mềm, CSDL | B17: =IF(C17*H17/100<2000000,2000000,C17*H17/100) -> #REF! | C17: =E17-(E17-D17)*(H17-G17)/(F17-G17) -> #REF! | D17: =IF(F17=0,K17,HLOOKUP(F17,dinhmuc,$I17,TRUE)) -> #REF! | E17: =IF(G17=0,L17,HLOOKUP(G17,dinhmuc,$I17,TRUE)) -> #REF! | F17: =IF(H17<$K$9,0,INDEX(budget,MATCH(H17,budget,1))) -> #REF! | G17: =IF(H17<$K$9,$K$9,INDEX(budget,MATCH(H17,budget,1)+1)) -> #REF! | H17: =C4 -> #REF! | I17: 9 | J17: Dự án phần mềm nội bộ, cơ sở dữ liệu | K17: 3.376 | L17: 3.155 | M17: 3.023 | N17: 2.847 | O17: 2.506 | P17: 2.211 | Q17: 2.091 | R17: 1.975
A18: Chi phí thẩm tra tính hiệu quả và tính khả thi của dự án đầu tư | B18: =SUM(B19:B20) -> #REF! | I18: 10 | J18: Bảng số 4: Định mức chi phí thẩm tra tính hiệu quả và tính khả thi của dự án đầu tư
A19: + Hạ tầng kỹ thuật | B19: 0 | C19: =E19-(E19-D19)*(H19-G19)/(F19-G19) -> 0.105 | D19: =IF(F19=0,K19,HLOOKUP(F19,dinhmuc,$I19,TRUE)) -> 0.105 | E19: =IF(G19=0,L19,HLOOKUP(G19,dinhmuc,$I19,TRUE)) -> 0.992 | F19: =IF(H19<$K$9,0,INDEX(budget,MATCH(H19,budget,1))) -> 0 | G19: =IF(H19<$K$9,$K$9,INDEX(budget,MATCH(H19,budget,1)+1)) -> 7000000000 | H19: =C3 -> 0 | I19: 11 | J19: Dự án hạ tầng kỹ thuật công nghệ thông tin | K19: 0.105 | L19: 0.074 | M19: 0.066 | N19: 0.059 | O19: 0.047 | P19: 0.035 | Q19: 0.03 | R19: 0.026 | S19: 0.0152 | T19: 0.0142
A20: + Phần mềm, CSDL | B20: =IF(C20*H20/100<2000000,2000000,C20*H20/100) -> #REF! | C20: =E20-(E20-D20)*(H20-G20)/(F20-G20) -> #REF! | D20: =IF(F20=0,K20,HLOOKUP(F20,dinhmuc,$I20,TRUE)) -> #REF! | E20: =IF(G20=0,L20,HLOOKUP(G20,dinhmuc,$I20,TRUE)) -> #REF! | F20: =IF(H20<$K$9,0,INDEX(budget,MATCH(H20,budget,1))) -> #REF! | G20: =IF(H20<$K$9,$K$9,INDEX(budget,MATCH(H20,budget,1)+1)) -> #REF! | H20: =C4 -> #REF! | I20: 12 | J20: Dự án phần mềm nội bộ, cơ sở dữ liệu | K20: 0.126 | L20: 0.088 | M20: 0.085 | N20: 0.077 | O20: 0.065 | P20: 0.051 | Q20: 0.042 | R20: 0.036
A21: Chi phí thẩm tra thiết kế thi công | B21: =SUM(B22:B23) -> #REF! | I21: 13 | J21: Bảng số 5: Định mức chi phí thẩm tra thiết kế thi công (chi phí tối thiểu không dưới 2 triệu)
A22: + Hạ tầng kỹ thuật | B22: 0 | C22: =E22-(E22-D22)*(H22-G22)/(F22-G22) -> 0.087 | D22: =IF(F22=0,K22,HLOOKUP(F22,dinhmuc,$I22,TRUE)) -> 0.087 | E22: =IF(G22=0,L22,HLOOKUP(G22,dinhmuc,$I22,TRUE)) -> 1.499 | F22: =IF(H22<$K$9,0,INDEX(budget,MATCH(H22,budget,1))) -> 0 | G22: =IF(H22<$K$9,$K$9,INDEX(budget,MATCH(H22,budget,1)+1)) -> 7000000000 | H22: =C3 -> 0 | I22: 14 | J22: Dự án hạ tầng kỹ thuật công nghệ thông tin | K22: 0.087 | L22: 0.061 | M22: 0.054 | N22: 0.043 | O22: 0.03 | P22: 0.022 | Q22: 0.019 | R22: 0.016 | S22: 0.011 | T22: 0.008
A23: + Phần mềm, CSDL | B23: =IF(C23*H23/100<2000000,2000000,C23*H23/100) -> #REF! | C23: =E23-(E23-D23)*(H23-G23)/(F23-G23) -> #REF! | D23: =IF(F23=0,K23,HLOOKUP(F23,dinhmuc,$I23,TRUE)) -> #REF! | E23: =IF(G23=0,L23,HLOOKUP(G23,dinhmuc,$I23,TRUE)) -> #REF! | F23: =IF(H23<$K$9,0,INDEX(budget,MATCH(H23,budget,1))) -> #REF! | G23: =IF(H23<$K$9,$K$9,INDEX(budget,MATCH(H23,budget,1)+1)) -> #REF! | H23: =H11 -> #REF! | I23: 15 | J23: Dự án phần mềm nội bộ, cơ sở dữ liệu | K23: 0.095 | L23: 0.066 | M23: 0.059 | N23: 0.047 | O23: 0.032 | P23: 0.024 | Q23: 0.02 | R23: 0.017
A24: Chi phí thẩm tra dự toán | B24: =SUM(B25:B26) -> #REF! | I24: 16 | J24: Bảng số 6: Định mức chi phí thẩm tra dự toán (chi phí tối thiểu không dưới 2 triệu)
A25: + Hạ tầng kỹ thuật | B25: 0 | C25: =E25-(E25-D25)*(H25-G25)/(F25-G25) -> 0.078 | D25: =IF(F25=0,K25,HLOOKUP(F25,dinhmuc,$I25,TRUE)) -> 0.078 | E25: =IF(G25=0,L25,HLOOKUP(G25,dinhmuc,$I25,TRUE)) -> 0.105 | F25: =IF(H25<$K$9,0,INDEX(budget,MATCH(H25,budget,1))) -> 0 | G25: =IF(H25<$K$9,$K$9,INDEX(budget,MATCH(H25,budget,1)+1)) -> 7000000000 | H25: =C3 -> 0 | I25: 17 | J25: Dự án hạ tầng kỹ thuật công nghệ thông tin | K25: 0.078 | L25: 0.05 | M25: 0.044 | N25: 0.034 | O25: 0.026 | P25: 0.018 | Q25: 0.015 | R25: 0.013 | S25: 0.01 | T25: 0.007
A26: + Phần mềm, CSDL | B26: =IF(C26*H26/100<2000000,2000000,C26*H26/100) -> #REF! | C26: =E26-(E26-D26)*(H26-G26)/(F26-G26) -> #REF! | D26: =IF(F26=0,K26,HLOOKUP(F26,dinhmuc,$I26,TRUE)) -> #REF! | E26: =IF(G26=0,L26,HLOOKUP(G26,dinhmuc,$I26,TRUE)) -> #REF! | F26: =IF(H26<$K$9,0,INDEX(budget,MATCH(H26,budget,1))) -> #REF! | G26: =IF(H26<$K$9,$K$9,INDEX(budget,MATCH(H26,budget,1)+1)) -> #REF! | H26: =H11 -> #REF! | I26: 18 | J26: Dự án phần mềm nội bộ, cơ sở dữ liệu | K26: 0.085 | L26: 0.054 | M26: 0.048 | N26: 0.037 | O26: 0.028 | P26: 0.019 | Q26: 0.016 | R26: 0.014
A27: Chi phí lập hồ sơ mời thầu, đánh giá hồ sơ dự thầu xây lắp | B27: =B28 -> 0 | I27: 19 | J27: Bảng số 7: Định mức chi phí lập hồ sơ mời thầu, đánh giá hồ sơ dự thầu xây lắp
A28: + Hạ tầng kỹ thuật | B28: =C28*H28/100 -> 0 | C28: =E28-(E28-D28)*(H28-G28)/(F28-G28) -> 0.362 | D28: =IF(F28=0,K28,HLOOKUP(F28,dinhmuc,$I28,TRUE)) -> 0.362 | E28: =IF(G28=0,L28,HLOOKUP(G28,dinhmuc,$I28,TRUE)) -> 0 | F28: =IF(H28<$K$9,0,INDEX(budget,MATCH(H28,budget,1))) -> 0 | G28: =IF(H28<$K$9,$K$9,INDEX(budget,MATCH(H28,budget,1)+1)) -> 7000000000 | H28: 0 | I28: 20 | J28: Dự án hạ tầng kỹ thuật công nghệ thông tin | K28: 0.362 | L28: 0.339 | M28: 0.305 | N28: 0.255 | O28: 0.164 | P28: 0.099 | Q28: 0.079 | R28: 0.063 | S28: 0.047 | T28: 0.028
A29: Chi phí lập hồ sơ mời thầu, đánh giá hồ sơ dự thầu mua sắm thiết bị | B29: =SUM(B30:B31) -> #REF! | I29: 21 | J29: Bảng số 8: Định mức chi phí lập hồ sơ mời thầu, đánh giá hồ sơ dự thầu mua sắm thiết bị
A30: + Hạ tầng kỹ thuật | B30: =C30*H30/100 -> 0 | C30: =E30-(E30-D30)*(H30-G30)/(F30-G30) -> 0.283 | D30: =IF(F30=0,K30,HLOOKUP(F30,dinhmuc,$I30,TRUE)) -> 0.283 | E30: =IF(G30=0,L30,HLOOKUP(G30,dinhmuc,$I30,TRUE)) -> 0 | F30: =IF(H30<$K$9,0,INDEX(budget,MATCH(H30,budget,1))) -> 0 | G30: =IF(H30<$K$9,$K$9,INDEX(budget,MATCH(H30,budget,1)+1)) -> 7000000000 | H30: =C3 -> 0 | I30: 22 | J30: Dự án hạ tầng kỹ thuật công nghệ thông tin | K30: 0.283 | L30: 0.228 | M30: 0.206 | N30: 0.172 | O30: 0.12 | P30: 0.078 | Q30: 0.072 | R30: 0.064 | S30: 0.053 | T30: 0.041
A31: + Phần mềm, CSDL | B31: =C31*H31/100 -> #REF! | C31: =E31-(E31-D31)*(H31-G31)/(F31-G31) -> #REF! | D31: =IF(F31=0,K31,HLOOKUP(F31,dinhmuc,$I31,TRUE)) -> #REF! | E31: =IF(G31=0,L31,HLOOKUP(G31,dinhmuc,$I31,TRUE)) -> #REF! | F31: =IF(H31<$K$9,0,INDEX(budget,MATCH(H31,budget,1))) -> #REF! | G31: =IF(H31<$K$9,$K$9,INDEX(budget,MATCH(H31,budget,1)+1)) -> #REF! | H31: =H11 -> #REF! | I31: 23 | J31: Dự án phần mềm nội bộ, cơ sở dữ liệu | K31: 0.405 | L31: 0.336 | M31: 0.311 | N31: 0.265 | O31: 0.182 | P31: 0.119 | Q31: 0.109 | R31: 0.102
A32: Chi phí giám sát thi công lắp đặt phần cứng, cài đặt phần mềm | B32: =SUM(B33:B34) -> #REF! | I32: 24 | J32: Bảng số 9: Định mức chi phí giám sát thi công lắp đặt phần cứng, cài đặt phần mềm
A33: + Hạ tầng kỹ thuật | B33: =C33*H33/100 -> 0 | C33: =E33-(E33-D33)*(H33-G33)/(F33-G33) -> 0.718 | D33: =IF(F33=0,K33,HLOOKUP(F33,dinhmuc,$I33,TRUE)) -> 0.718 | E33: =IF(G33=0,L33,HLOOKUP(G33,dinhmuc,$I33,TRUE)) -> 0 | F33: =IF(H33<$K$9,0,INDEX(budget,MATCH(H33,budget,1))) -> 0 | G33: =IF(H33<$K$9,$K$9,INDEX(budget,MATCH(H33,budget,1)+1)) -> 7000000000 | H33: =C3 -> 0 | I33: 25 | J33: Dự án hạ tầng kỹ thuật công nghệ thông tin | K33: 0.718 | L33: 0.602 | M33: 0.583 | N33: 0.5233 | O33: 0.468 | P33: 0.311 | Q33: 0.278 | R33: 0.25 | S33: 0.217 | T33: 0.143
A34: + Phần mềm, CSDL | B34: =C34*H34/100 -> #REF! | C34: =E34-(E34-D34)*(H34-G34)/(F34-G34) -> #REF! | D34: =IF(F34=0,K34,HLOOKUP(F34,dinhmuc,$I34,TRUE)) -> #REF! | E34: =IF(G34=0,L34,HLOOKUP(G34,dinhmuc,$I34,TRUE)) -> #REF! | F34: =IF(H34<$K$9,0,INDEX(budget,MATCH(H34,budget,1))) -> #REF! | G34: =IF(H34<$K$9,$K$9,INDEX(budget,MATCH(H34,budget,1)+1)) -> #REF! | H34: =H11 -> #REF! | I34: 26 | J34: Dự án phần mềm nội bộ, cơ sở dữ liệu | K34: 2.063 | L34: 1.931 | M34: 1.833 | N34: 1.736 | O34: 1.595 | P34: 1.22 | Q34: 1.091 | R34: 0.956
A35: Chi phí thẩm định hồ sơ mời thầu | B35: =H35*C35/100 -> #REF! | C35: 0.05 | H35: =#REF! -> #REF! | J35: Điều 21 (TT09/2016/TT-BC) Chi phí thẩm tra, phê duyệt quyết toán, chi phí kiểm toán độc lập ngày 18/01/2016
A36: Chi phí thẩm định kết quả lựa chọn nhà thầu | B36: =H36*C36/100 -> #REF! | C36: 0.05 | H36: =H35 -> #REF! | I36: 1 | J36: Tổng mức đầu tư (tỷ đồng) | K36: 5000000000 | L36: 10000000000 | M36: 50000000000 | N36: 100000000000 | O36: 500000000000 | P36: 1000000000000 | Q36: 10000000000000 | S36: 10000000000000
A37: Chi phí thẩm tra, phê duyệt quyết toán | B37: =H37*C37/100*70% -> 22428000 | C37: =E37-(E37-D37)*(H37-G37)/(F37-G37) -> 0.534 | D37: =IF(F37=0,K37,HLOOKUP(F37,pdqt,$I37,TRUE)) -> 0.57 | E37: =IF(G37=0,L37,HLOOKUP(G37,pdqt,$I37,TRUE)) -> 0.39 | F37: =IF(H37<$K$36,0,INDEX(budget2,MATCH(H37,budget2,1))) -> 5000000000 | G37: =IF(H37<$K$36,$K$36,INDEX(budget2,MATCH(H37,budget2,1)+1)) -> 10000000000 | H37: 6000000000 | I37: 2 | J37: Thẩm tra, phê duyệt (%) | K37: 0.95 | L37: 0.65 | M37: 0.475 | N37: 0.375 | O37: 0.225 | P37: 0.15 | Q37: 0.08 | S37: 0.032
A38: Kiểm toán | B38: =H38*C38/100*70% -> 37674000 | C38: =E38-(E38-D38)*(H38-G38)/(F38-G38) -> 0.897 | D38: =IF(F38=0,K38,HLOOKUP(F38,pdqt,$I38,TRUE)) -> 0.96 | E38: =IF(G38=0,L38,HLOOKUP(G38,pdqt,$I38,TRUE)) -> 0.645 | F38: =IF(H38<$K$36,0,INDEX(budget2,MATCH(H38,budget2,1))) -> 5000000000 | G38: =IF(H38<$K$36,$K$36,INDEX(budget2,MATCH(H38,budget2,1)+1)) -> 10000000000 | H38: =H37 -> 6000000000 | I38: 3 | J38: Kiểm toán (%) | K38: 1.6 | L38: 1.075 | M38: 0.75 | N38: 0.575 | O38: 0.325 | P38: 0.215 | Q38: 0.115 | S38: 0.046
